2025-06-28 11:16:22,360 | INFO     | django.utils.autoreload | run_with_reloader    | Line 667  | Watching for file changes with StatReloader
2025-06-28 11:17:32,233 | DEBUG    | google.cloud.storage._opentelemetry_tracing | <module>             | Line 42   | This service is instrumented using OpenTelemetry. OpenTelemetry or one of its components could not be imported; please add compatible versions of opentelemetry-api and opentelemetry-instrumentation packages in order to get Storage Tracing data.
2025-06-28 11:18:08,063 | INFO     | authentication.views | post                 | Line 96   | Login attempt received.
2025-06-28 11:18:21,507 | INFO     | authentication.views | post                 | Line 113  | Login successful for user: abc
2025-06-28 11:19:08,784 | WARNING  |  django.request | log_response         | Line 253  | Unauthorized: /IDA/upload/
2025-06-28 11:19:25,383 | INFO     | ImageApp1.views | post                 | Line 306  | Upload request received
2025-06-28 11:20:30,275 | ERROR    | ImageApp1.views | post                 | Line 547  | 500
Traceback (most recent call last):
  File "D:\IDP_Project\ImageExtraction\ImageApp1\views.py", line 413, in post
    parsed_json = json.loads(result)
                  ^^^^^^^^^^^^^^^^^^
  File "C:\Users\pooja.akolkar\AppData\Local\anaconda3\Lib\json\__init__.py", line 346, in loads
    return _default_decoder.decode(s)
           ^^^^^^^^^^^^^^^^^^^^^^^^^^
  File "C:\Users\pooja.akolkar\AppData\Local\anaconda3\Lib\json\decoder.py", line 337, in decode
    obj, end = self.raw_decode(s, idx=_w(s, 0).end())
               ^^^^^^^^^^^^^^^^^^^^^^^^^^^^^^^^^^^^^^
  File "C:\Users\pooja.akolkar\AppData\Local\anaconda3\Lib\json\decoder.py", line 355, in raw_decode
    raise JSONDecodeError("Expecting value", s, err.value) from None
json.decoder.JSONDecodeError: Expecting value: line 1 column 1 (char 0)
2025-06-28 11:20:30,288 | ERROR    | ImageApp1.views | post                 | Line 548  | Error while processing document.
Traceback (most recent call last):
  File "D:\IDP_Project\ImageExtraction\ImageApp1\views.py", line 413, in post
    parsed_json = json.loads(result)
                  ^^^^^^^^^^^^^^^^^^
  File "C:\Users\pooja.akolkar\AppData\Local\anaconda3\Lib\json\__init__.py", line 346, in loads
    return _default_decoder.decode(s)
           ^^^^^^^^^^^^^^^^^^^^^^^^^^
  File "C:\Users\pooja.akolkar\AppData\Local\anaconda3\Lib\json\decoder.py", line 337, in decode
    obj, end = self.raw_decode(s, idx=_w(s, 0).end())
               ^^^^^^^^^^^^^^^^^^^^^^^^^^^^^^^^^^^^^^
  File "C:\Users\pooja.akolkar\AppData\Local\anaconda3\Lib\json\decoder.py", line 355, in raw_decode
    raise JSONDecodeError("Expecting value", s, err.value) from None
json.decoder.JSONDecodeError: Expecting value: line 1 column 1 (char 0)
2025-06-28 11:20:30,295 | ERROR    | ImageApp1.views | log_exception        | Line 71   | Exception occurred in D:\IDP_Project\ImageExtraction\ImageApp1\views.py, line 413: parsed_json = json.loads(result)
2025-06-28 11:20:30,296 | ERROR    | ImageApp1.views | log_exception        | Line 71   | Exception occurred in C:\Users\pooja.akolkar\AppData\Local\anaconda3\Lib\json\__init__.py, line 346: return _default_decoder.decode(s)
2025-06-28 11:20:30,296 | ERROR    | ImageApp1.views | log_exception        | Line 71   | Exception occurred in C:\Users\pooja.akolkar\AppData\Local\anaconda3\Lib\json\decoder.py, line 337: obj, end = self.raw_decode(s, idx=_w(s, 0).end())
2025-06-28 11:20:30,298 | ERROR    | ImageApp1.views | log_exception        | Line 71   | Exception occurred in C:\Users\pooja.akolkar\AppData\Local\anaconda3\Lib\json\decoder.py, line 355: raise JSONDecodeError("Expecting value", s, err.value) from None
2025-06-28 11:20:30,299 | ERROR    |  django.request | log_response         | Line 253  | Internal Server Error: /IDA/upload/
2025-06-28 11:24:08,250 | INFO     | django.utils.autoreload | trigger_reload       | Line 265  | D:\IDP_Project\ImageExtraction\ImageApp1\views.py changed, reloading.
2025-06-28 11:24:11,034 | INFO     | django.utils.autoreload | run_with_reloader    | Line 667  | Watching for file changes with StatReloader
2025-06-28 11:24:19,528 | DEBUG    | google.cloud.storage._opentelemetry_tracing | <module>             | Line 42   | This service is instrumented using OpenTelemetry. OpenTelemetry or one of its components could not be imported; please add compatible versions of opentelemetry-api and opentelemetry-instrumentation packages in order to get Storage Tracing data.
2025-06-28 11:25:10,673 | INFO     | django.utils.autoreload | trigger_reload       | Line 265  | D:\IDP_Project\ImageExtraction\ImageApp1\views.py changed, reloading.
2025-06-28 11:25:12,966 | INFO     | django.utils.autoreload | run_with_reloader    | Line 667  | Watching for file changes with StatReloader
2025-06-28 11:25:19,290 | DEBUG    | google.cloud.storage._opentelemetry_tracing | <module>             | Line 42   | This service is instrumented using OpenTelemetry. OpenTelemetry or one of its components could not be imported; please add compatible versions of opentelemetry-api and opentelemetry-instrumentation packages in order to get Storage Tracing data.
2025-06-28 11:25:27,807 | INFO     | ImageApp1.views | post                 | Line 306  | Upload request received
2025-06-28 11:26:31,457 | ERROR    | ImageApp1.views | post                 | Line 428  | JSON decoding error: Expecting value: line 1 column 1 (char 0)
Traceback (most recent call last):
  File "D:\IDP_Project\ImageExtraction\ImageApp1\views.py", line 422, in post
    parsed_json = json.loads(result)
                  ^^^^^^^^^^^^^^^^^^
  File "C:\Users\pooja.akolkar\AppData\Local\anaconda3\Lib\json\__init__.py", line 346, in loads
    return _default_decoder.decode(s)
           ^^^^^^^^^^^^^^^^^^^^^^^^^^
  File "C:\Users\pooja.akolkar\AppData\Local\anaconda3\Lib\json\decoder.py", line 337, in decode
    obj, end = self.raw_decode(s, idx=_w(s, 0).end())
               ^^^^^^^^^^^^^^^^^^^^^^^^^^^^^^^^^^^^^^
  File "C:\Users\pooja.akolkar\AppData\Local\anaconda3\Lib\json\decoder.py", line 355, in raw_decode
    raise JSONDecodeError("Expecting value", s, err.value) from None
json.decoder.JSONDecodeError: Expecting value: line 1 column 1 (char 0)
2025-06-28 11:26:31,463 | WARNING  |  django.request | log_response         | Line 253  | Bad Request: /IDA/upload/
2025-06-28 11:33:57,376 | INFO     | django.utils.autoreload | trigger_reload       | Line 265  | D:\IDP_Project\ImageExtraction\ImageApp1\views.py changed, reloading.
2025-06-28 11:34:00,099 | INFO     | django.utils.autoreload | run_with_reloader    | Line 667  | Watching for file changes with StatReloader
2025-06-28 11:34:24,188 | INFO     | django.utils.autoreload | trigger_reload       | Line 265  | D:\IDP_Project\ImageExtraction\ImageApp1\views.py changed, reloading.
2025-06-28 11:34:25,583 | INFO     | django.utils.autoreload | run_with_reloader    | Line 667  | Watching for file changes with StatReloader
2025-06-28 11:35:28,621 | INFO     | django.utils.autoreload | trigger_reload       | Line 265  | D:\IDP_Project\ImageExtraction\ImageApp1\views.py changed, reloading.
2025-06-28 11:35:30,147 | INFO     | django.utils.autoreload | run_with_reloader    | Line 667  | Watching for file changes with StatReloader
2025-06-28 11:35:54,901 | INFO     | django.utils.autoreload | run_with_reloader    | Line 667  | Watching for file changes with StatReloader
2025-06-28 11:36:33,648 | INFO     | django.utils.autoreload | trigger_reload       | Line 265  | D:\IDP_Project\ImageExtraction\ImageApp1\views.py changed, reloading.
2025-06-28 11:36:35,082 | INFO     | django.utils.autoreload | run_with_reloader    | Line 667  | Watching for file changes with StatReloader
2025-06-28 11:36:41,121 | DEBUG    | google.cloud.storage._opentelemetry_tracing | <module>             | Line 42   | This service is instrumented using OpenTelemetry. OpenTelemetry or one of its components could not be imported; please add compatible versions of opentelemetry-api and opentelemetry-instrumentation packages in order to get Storage Tracing data.
2025-06-28 11:37:11,279 | INFO     | django.utils.autoreload | trigger_reload       | Line 265  | D:\IDP_Project\ImageExtraction\ImageApp1\views.py changed, reloading.
2025-06-28 11:37:13,252 | INFO     | django.utils.autoreload | run_with_reloader    | Line 667  | Watching for file changes with StatReloader
2025-06-28 11:37:18,893 | DEBUG    | google.cloud.storage._opentelemetry_tracing | <module>             | Line 42   | This service is instrumented using OpenTelemetry. OpenTelemetry or one of its components could not be imported; please add compatible versions of opentelemetry-api and opentelemetry-instrumentation packages in order to get Storage Tracing data.
2025-06-28 11:37:23,402 | INFO     | ImageApp1.views | post                 | Line 321  | Upload request received
2025-06-28 11:38:43,646 | ERROR    | ImageApp1.views | post                 | Line 442  | JSON decoding error: Expecting value: line 1 column 1 (char 0)
Traceback (most recent call last):
  File "D:\IDP_Project\ImageExtraction\ImageApp1\views.py", line 436, in post
    parsed_json = json.loads(result)
                  ^^^^^^^^^^^^^^^^^^
  File "C:\Users\pooja.akolkar\AppData\Local\anaconda3\Lib\json\__init__.py", line 346, in loads
    return _default_decoder.decode(s)
           ^^^^^^^^^^^^^^^^^^^^^^^^^^
  File "C:\Users\pooja.akolkar\AppData\Local\anaconda3\Lib\json\decoder.py", line 337, in decode
    obj, end = self.raw_decode(s, idx=_w(s, 0).end())
               ^^^^^^^^^^^^^^^^^^^^^^^^^^^^^^^^^^^^^^
  File "C:\Users\pooja.akolkar\AppData\Local\anaconda3\Lib\json\decoder.py", line 355, in raw_decode
    raise JSONDecodeError("Expecting value", s, err.value) from None
json.decoder.JSONDecodeError: Expecting value: line 1 column 1 (char 0)
2025-06-28 11:38:43,655 | WARNING  |  django.request | log_response         | Line 253  | Bad Request: /IDA/upload/
2025-06-28 11:41:30,449 | INFO     | django.utils.autoreload | trigger_reload       | Line 265  | D:\IDP_Project\ImageExtraction\ImageApp1\views.py changed, reloading.
2025-06-28 11:41:32,598 | INFO     | django.utils.autoreload | run_with_reloader    | Line 667  | Watching for file changes with StatReloader
2025-06-28 11:41:39,298 | DEBUG    | google.cloud.storage._opentelemetry_tracing | <module>             | Line 42   | This service is instrumented using OpenTelemetry. OpenTelemetry or one of its components could not be imported; please add compatible versions of opentelemetry-api and opentelemetry-instrumentation packages in order to get Storage Tracing data.
2025-06-28 11:42:21,997 | INFO     | django.utils.autoreload | trigger_reload       | Line 265  | D:\IDP_Project\ImageExtraction\ImageApp1\views.py changed, reloading.
2025-06-28 11:42:24,143 | INFO     | django.utils.autoreload | run_with_reloader    | Line 667  | Watching for file changes with StatReloader
2025-06-28 11:42:30,362 | DEBUG    | google.cloud.storage._opentelemetry_tracing | <module>             | Line 42   | This service is instrumented using OpenTelemetry. OpenTelemetry or one of its components could not be imported; please add compatible versions of opentelemetry-api and opentelemetry-instrumentation packages in order to get Storage Tracing data.
2025-06-28 11:42:37,115 | INFO     | django.utils.autoreload | trigger_reload       | Line 265  | D:\IDP_Project\ImageExtraction\ImageApp1\views.py changed, reloading.
2025-06-28 11:42:39,989 | INFO     | django.utils.autoreload | run_with_reloader    | Line 667  | Watching for file changes with StatReloader
2025-06-28 11:42:46,644 | DEBUG    | google.cloud.storage._opentelemetry_tracing | <module>             | Line 42   | This service is instrumented using OpenTelemetry. OpenTelemetry or one of its components could not be imported; please add compatible versions of opentelemetry-api and opentelemetry-instrumentation packages in order to get Storage Tracing data.
2025-06-28 11:42:54,683 | INFO     | ImageApp1.views | post                 | Line 321  | Upload request received
2025-06-28 11:46:11,971 | ERROR    | ImageApp1.views | post                 | Line 580  | 500
Traceback (most recent call last):
  File "C:\Users\pooja.akolkar\AppData\Local\anaconda3\Lib\site-packages\django\db\models\fields\__init__.py", line 2128, in get_prep_value
    return int(value)
           ^^^^^^^^^^
ValueError: invalid literal for int() with base 10: ''

The above exception was the direct cause of the following exception:

Traceback (most recent call last):
  File "D:\IDP_Project\ImageExtraction\ImageApp1\views.py", line 560, in post
    doc = Document.objects.create(
          ^^^^^^^^^^^^^^^^^^^^^^^^
  File "C:\Users\pooja.akolkar\AppData\Local\anaconda3\Lib\site-packages\django\db\models\manager.py", line 87, in manager_method
    return getattr(self.get_queryset(), name)(*args, **kwargs)
           ^^^^^^^^^^^^^^^^^^^^^^^^^^^^^^^^^^^^^^^^^^^^^^^^^^^
  File "C:\Users\pooja.akolkar\AppData\Local\anaconda3\Lib\site-packages\django\db\models\query.py", line 663, in create
    obj.save(force_insert=True, using=self.db)
  File "C:\Users\pooja.akolkar\AppData\Local\anaconda3\Lib\site-packages\django\db\models\base.py", line 902, in save
    self.save_base(
  File "C:\Users\pooja.akolkar\AppData\Local\anaconda3\Lib\site-packages\django\db\models\base.py", line 1008, in save_base
    updated = self._save_table(
              ^^^^^^^^^^^^^^^^^
  File "C:\Users\pooja.akolkar\AppData\Local\anaconda3\Lib\site-packages\django\db\models\base.py", line 1169, in _save_table
    results = self._do_insert(
              ^^^^^^^^^^^^^^^^
  File "C:\Users\pooja.akolkar\AppData\Local\anaconda3\Lib\site-packages\django\db\models\base.py", line 1210, in _do_insert
    return manager._insert(
           ^^^^^^^^^^^^^^^^
  File "C:\Users\pooja.akolkar\AppData\Local\anaconda3\Lib\site-packages\django\db\models\manager.py", line 87, in manager_method
    return getattr(self.get_queryset(), name)(*args, **kwargs)
           ^^^^^^^^^^^^^^^^^^^^^^^^^^^^^^^^^^^^^^^^^^^^^^^^^^^
  File "C:\Users\pooja.akolkar\AppData\Local\anaconda3\Lib\site-packages\django\db\models\query.py", line 1868, in _insert
    return query.get_compiler(using=using).execute_sql(returning_fields)
           ^^^^^^^^^^^^^^^^^^^^^^^^^^^^^^^^^^^^^^^^^^^^^^^^^^^^^^^^^^^^^
  File "C:\Users\pooja.akolkar\AppData\Local\anaconda3\Lib\site-packages\django\db\models\sql\compiler.py", line 1881, in execute_sql
    for sql, params in self.as_sql():
                       ^^^^^^^^^^^^^
  File "C:\Users\pooja.akolkar\AppData\Local\anaconda3\Lib\site-packages\django\db\models\sql\compiler.py", line 1806, in as_sql
    self.prepare_value(field, self.pre_save_val(field, obj))
  File "C:\Users\pooja.akolkar\AppData\Local\anaconda3\Lib\site-packages\django\db\models\sql\compiler.py", line 1741, in prepare_value
    return field.get_db_prep_save(value, connection=self.connection)
           ^^^^^^^^^^^^^^^^^^^^^^^^^^^^^^^^^^^^^^^^^^^^^^^^^^^^^^^^^
  File "C:\Users\pooja.akolkar\AppData\Local\anaconda3\Lib\site-packages\django\db\models\fields\__init__.py", line 1012, in get_db_prep_save
    return self.get_db_prep_value(value, connection=connection, prepared=False)
           ^^^^^^^^^^^^^^^^^^^^^^^^^^^^^^^^^^^^^^^^^^^^^^^^^^^^^^^^^^^^^^^^^^^^
  File "C:\Users\pooja.akolkar\AppData\Local\anaconda3\Lib\site-packages\django\db\models\fields\__init__.py", line 2135, in get_db_prep_value
    value = super().get_db_prep_value(value, connection, prepared)
            ^^^^^^^^^^^^^^^^^^^^^^^^^^^^^^^^^^^^^^^^^^^^^^^^^^^^^^
  File "C:\Users\pooja.akolkar\AppData\Local\anaconda3\Lib\site-packages\django\db\models\fields\__init__.py", line 1005, in get_db_prep_value
    value = self.get_prep_value(value)
            ^^^^^^^^^^^^^^^^^^^^^^^^^^
  File "C:\Users\pooja.akolkar\AppData\Local\anaconda3\Lib\site-packages\django\db\models\fields\__init__.py", line 2130, in get_prep_value
    raise e.__class__(
ValueError: Field 'input_token' expected a number but got ''.
2025-06-28 11:46:12,193 | ERROR    | ImageApp1.views | post                 | Line 581  | Error while processing document.
Traceback (most recent call last):
  File "C:\Users\pooja.akolkar\AppData\Local\anaconda3\Lib\site-packages\django\db\models\fields\__init__.py", line 2128, in get_prep_value
    return int(value)
           ^^^^^^^^^^
ValueError: invalid literal for int() with base 10: ''

The above exception was the direct cause of the following exception:

Traceback (most recent call last):
  File "D:\IDP_Project\ImageExtraction\ImageApp1\views.py", line 560, in post
    doc = Document.objects.create(
          ^^^^^^^^^^^^^^^^^^^^^^^^
  File "C:\Users\pooja.akolkar\AppData\Local\anaconda3\Lib\site-packages\django\db\models\manager.py", line 87, in manager_method
    return getattr(self.get_queryset(), name)(*args, **kwargs)
           ^^^^^^^^^^^^^^^^^^^^^^^^^^^^^^^^^^^^^^^^^^^^^^^^^^^
  File "C:\Users\pooja.akolkar\AppData\Local\anaconda3\Lib\site-packages\django\db\models\query.py", line 663, in create
    obj.save(force_insert=True, using=self.db)
  File "C:\Users\pooja.akolkar\AppData\Local\anaconda3\Lib\site-packages\django\db\models\base.py", line 902, in save
    self.save_base(
  File "C:\Users\pooja.akolkar\AppData\Local\anaconda3\Lib\site-packages\django\db\models\base.py", line 1008, in save_base
    updated = self._save_table(
              ^^^^^^^^^^^^^^^^^
  File "C:\Users\pooja.akolkar\AppData\Local\anaconda3\Lib\site-packages\django\db\models\base.py", line 1169, in _save_table
    results = self._do_insert(
              ^^^^^^^^^^^^^^^^
  File "C:\Users\pooja.akolkar\AppData\Local\anaconda3\Lib\site-packages\django\db\models\base.py", line 1210, in _do_insert
    return manager._insert(
           ^^^^^^^^^^^^^^^^
  File "C:\Users\pooja.akolkar\AppData\Local\anaconda3\Lib\site-packages\django\db\models\manager.py", line 87, in manager_method
    return getattr(self.get_queryset(), name)(*args, **kwargs)
           ^^^^^^^^^^^^^^^^^^^^^^^^^^^^^^^^^^^^^^^^^^^^^^^^^^^
  File "C:\Users\pooja.akolkar\AppData\Local\anaconda3\Lib\site-packages\django\db\models\query.py", line 1868, in _insert
    return query.get_compiler(using=using).execute_sql(returning_fields)
           ^^^^^^^^^^^^^^^^^^^^^^^^^^^^^^^^^^^^^^^^^^^^^^^^^^^^^^^^^^^^^
  File "C:\Users\pooja.akolkar\AppData\Local\anaconda3\Lib\site-packages\django\db\models\sql\compiler.py", line 1881, in execute_sql
    for sql, params in self.as_sql():
                       ^^^^^^^^^^^^^
  File "C:\Users\pooja.akolkar\AppData\Local\anaconda3\Lib\site-packages\django\db\models\sql\compiler.py", line 1806, in as_sql
    self.prepare_value(field, self.pre_save_val(field, obj))
  File "C:\Users\pooja.akolkar\AppData\Local\anaconda3\Lib\site-packages\django\db\models\sql\compiler.py", line 1741, in prepare_value
    return field.get_db_prep_save(value, connection=self.connection)
           ^^^^^^^^^^^^^^^^^^^^^^^^^^^^^^^^^^^^^^^^^^^^^^^^^^^^^^^^^
  File "C:\Users\pooja.akolkar\AppData\Local\anaconda3\Lib\site-packages\django\db\models\fields\__init__.py", line 1012, in get_db_prep_save
    return self.get_db_prep_value(value, connection=connection, prepared=False)
           ^^^^^^^^^^^^^^^^^^^^^^^^^^^^^^^^^^^^^^^^^^^^^^^^^^^^^^^^^^^^^^^^^^^^
  File "C:\Users\pooja.akolkar\AppData\Local\anaconda3\Lib\site-packages\django\db\models\fields\__init__.py", line 2135, in get_db_prep_value
    value = super().get_db_prep_value(value, connection, prepared)
            ^^^^^^^^^^^^^^^^^^^^^^^^^^^^^^^^^^^^^^^^^^^^^^^^^^^^^^
  File "C:\Users\pooja.akolkar\AppData\Local\anaconda3\Lib\site-packages\django\db\models\fields\__init__.py", line 1005, in get_db_prep_value
    value = self.get_prep_value(value)
            ^^^^^^^^^^^^^^^^^^^^^^^^^^
  File "C:\Users\pooja.akolkar\AppData\Local\anaconda3\Lib\site-packages\django\db\models\fields\__init__.py", line 2130, in get_prep_value
    raise e.__class__(
ValueError: Field 'input_token' expected a number but got ''.
2025-06-28 11:46:12,202 | ERROR    | ImageApp1.views | log_exception        | Line 71   | Exception occurred in D:\IDP_Project\ImageExtraction\ImageApp1\views.py, line 560: doc = Document.objects.create(
2025-06-28 11:46:12,203 | ERROR    | ImageApp1.views | log_exception        | Line 71   | Exception occurred in C:\Users\pooja.akolkar\AppData\Local\anaconda3\Lib\site-packages\django\db\models\manager.py, line 87: return getattr(self.get_queryset(), name)(*args, **kwargs)
2025-06-28 11:46:12,204 | ERROR    | ImageApp1.views | log_exception        | Line 71   | Exception occurred in C:\Users\pooja.akolkar\AppData\Local\anaconda3\Lib\site-packages\django\db\models\query.py, line 663: obj.save(force_insert=True, using=self.db)
2025-06-28 11:46:12,204 | ERROR    | ImageApp1.views | log_exception        | Line 71   | Exception occurred in C:\Users\pooja.akolkar\AppData\Local\anaconda3\Lib\site-packages\django\db\models\base.py, line 902: self.save_base(
2025-06-28 11:46:12,205 | ERROR    | ImageApp1.views | log_exception        | Line 71   | Exception occurred in C:\Users\pooja.akolkar\AppData\Local\anaconda3\Lib\site-packages\django\db\models\base.py, line 1008: updated = self._save_table(
2025-06-28 11:46:12,205 | ERROR    | ImageApp1.views | log_exception        | Line 71   | Exception occurred in C:\Users\pooja.akolkar\AppData\Local\anaconda3\Lib\site-packages\django\db\models\base.py, line 1169: results = self._do_insert(
2025-06-28 11:46:12,206 | ERROR    | ImageApp1.views | log_exception        | Line 71   | Exception occurred in C:\Users\pooja.akolkar\AppData\Local\anaconda3\Lib\site-packages\django\db\models\base.py, line 1210: return manager._insert(
2025-06-28 11:46:12,206 | ERROR    | ImageApp1.views | log_exception        | Line 71   | Exception occurred in C:\Users\pooja.akolkar\AppData\Local\anaconda3\Lib\site-packages\django\db\models\manager.py, line 87: return getattr(self.get_queryset(), name)(*args, **kwargs)
2025-06-28 11:46:12,207 | ERROR    | ImageApp1.views | log_exception        | Line 71   | Exception occurred in C:\Users\pooja.akolkar\AppData\Local\anaconda3\Lib\site-packages\django\db\models\query.py, line 1868: return query.get_compiler(using=using).execute_sql(returning_fields)
2025-06-28 11:46:12,207 | ERROR    | ImageApp1.views | log_exception        | Line 71   | Exception occurred in C:\Users\pooja.akolkar\AppData\Local\anaconda3\Lib\site-packages\django\db\models\sql\compiler.py, line 1881: for sql, params in self.as_sql():
2025-06-28 11:46:12,208 | ERROR    | ImageApp1.views | log_exception        | Line 71   | Exception occurred in C:\Users\pooja.akolkar\AppData\Local\anaconda3\Lib\site-packages\django\db\models\sql\compiler.py, line 1806: self.prepare_value(field, self.pre_save_val(field, obj))
2025-06-28 11:46:12,209 | ERROR    | ImageApp1.views | log_exception        | Line 71   | Exception occurred in C:\Users\pooja.akolkar\AppData\Local\anaconda3\Lib\site-packages\django\db\models\sql\compiler.py, line 1741: return field.get_db_prep_save(value, connection=self.connection)
2025-06-28 11:46:12,209 | ERROR    | ImageApp1.views | log_exception        | Line 71   | Exception occurred in C:\Users\pooja.akolkar\AppData\Local\anaconda3\Lib\site-packages\django\db\models\fields\__init__.py, line 1012: return self.get_db_prep_value(value, connection=connection, prepared=False)
2025-06-28 11:46:12,210 | ERROR    | ImageApp1.views | log_exception        | Line 71   | Exception occurred in C:\Users\pooja.akolkar\AppData\Local\anaconda3\Lib\site-packages\django\db\models\fields\__init__.py, line 2135: value = super().get_db_prep_value(value, connection, prepared)
2025-06-28 11:46:12,210 | ERROR    | ImageApp1.views | log_exception        | Line 71   | Exception occurred in C:\Users\pooja.akolkar\AppData\Local\anaconda3\Lib\site-packages\django\db\models\fields\__init__.py, line 1005: value = self.get_prep_value(value)
2025-06-28 11:46:12,211 | ERROR    | ImageApp1.views | log_exception        | Line 71   | Exception occurred in C:\Users\pooja.akolkar\AppData\Local\anaconda3\Lib\site-packages\django\db\models\fields\__init__.py, line 2130: raise e.__class__(
2025-06-28 11:46:12,213 | ERROR    |  django.request | log_response         | Line 253  | Internal Server Error: /IDA/upload/
2025-06-28 11:46:47,957 | INFO     | authentication.views | post                 | Line 96   | Login attempt received.
2025-06-28 11:46:49,644 | INFO     | authentication.views | post                 | Line 113  | Login successful for user: abc
2025-06-28 11:47:39,743 | WARNING  |  django.request | log_response         | Line 253  | Unauthorized: /IDA/upload/
2025-06-28 11:48:04,158 | INFO     | ImageApp1.views | post                 | Line 321  | Upload request received
2025-06-28 11:50:37,324 | ERROR    | ImageApp1.views | post                 | Line 580  | 500
Traceback (most recent call last):
  File "C:\Users\pooja.akolkar\AppData\Local\anaconda3\Lib\site-packages\django\db\models\fields\__init__.py", line 2128, in get_prep_value
    return int(value)
           ^^^^^^^^^^
ValueError: invalid literal for int() with base 10: ''

The above exception was the direct cause of the following exception:

Traceback (most recent call last):
  File "D:\IDP_Project\ImageExtraction\ImageApp1\views.py", line 560, in post
    doc = Document.objects.create(
          ^^^^^^^^^^^^^^^^^^^^^^^^
  File "C:\Users\pooja.akolkar\AppData\Local\anaconda3\Lib\site-packages\django\db\models\manager.py", line 87, in manager_method
    return getattr(self.get_queryset(), name)(*args, **kwargs)
           ^^^^^^^^^^^^^^^^^^^^^^^^^^^^^^^^^^^^^^^^^^^^^^^^^^^
  File "C:\Users\pooja.akolkar\AppData\Local\anaconda3\Lib\site-packages\django\db\models\query.py", line 663, in create
    obj.save(force_insert=True, using=self.db)
  File "C:\Users\pooja.akolkar\AppData\Local\anaconda3\Lib\site-packages\django\db\models\base.py", line 902, in save
    self.save_base(
  File "C:\Users\pooja.akolkar\AppData\Local\anaconda3\Lib\site-packages\django\db\models\base.py", line 1008, in save_base
    updated = self._save_table(
              ^^^^^^^^^^^^^^^^^
  File "C:\Users\pooja.akolkar\AppData\Local\anaconda3\Lib\site-packages\django\db\models\base.py", line 1169, in _save_table
    results = self._do_insert(
              ^^^^^^^^^^^^^^^^
  File "C:\Users\pooja.akolkar\AppData\Local\anaconda3\Lib\site-packages\django\db\models\base.py", line 1210, in _do_insert
    return manager._insert(
           ^^^^^^^^^^^^^^^^
  File "C:\Users\pooja.akolkar\AppData\Local\anaconda3\Lib\site-packages\django\db\models\manager.py", line 87, in manager_method
    return getattr(self.get_queryset(), name)(*args, **kwargs)
           ^^^^^^^^^^^^^^^^^^^^^^^^^^^^^^^^^^^^^^^^^^^^^^^^^^^
  File "C:\Users\pooja.akolkar\AppData\Local\anaconda3\Lib\site-packages\django\db\models\query.py", line 1868, in _insert
    return query.get_compiler(using=using).execute_sql(returning_fields)
           ^^^^^^^^^^^^^^^^^^^^^^^^^^^^^^^^^^^^^^^^^^^^^^^^^^^^^^^^^^^^^
  File "C:\Users\pooja.akolkar\AppData\Local\anaconda3\Lib\site-packages\django\db\models\sql\compiler.py", line 1881, in execute_sql
    for sql, params in self.as_sql():
                       ^^^^^^^^^^^^^
  File "C:\Users\pooja.akolkar\AppData\Local\anaconda3\Lib\site-packages\django\db\models\sql\compiler.py", line 1806, in as_sql
    self.prepare_value(field, self.pre_save_val(field, obj))
  File "C:\Users\pooja.akolkar\AppData\Local\anaconda3\Lib\site-packages\django\db\models\sql\compiler.py", line 1741, in prepare_value
    return field.get_db_prep_save(value, connection=self.connection)
           ^^^^^^^^^^^^^^^^^^^^^^^^^^^^^^^^^^^^^^^^^^^^^^^^^^^^^^^^^
  File "C:\Users\pooja.akolkar\AppData\Local\anaconda3\Lib\site-packages\django\db\models\fields\__init__.py", line 1012, in get_db_prep_save
    return self.get_db_prep_value(value, connection=connection, prepared=False)
           ^^^^^^^^^^^^^^^^^^^^^^^^^^^^^^^^^^^^^^^^^^^^^^^^^^^^^^^^^^^^^^^^^^^^
  File "C:\Users\pooja.akolkar\AppData\Local\anaconda3\Lib\site-packages\django\db\models\fields\__init__.py", line 2135, in get_db_prep_value
    value = super().get_db_prep_value(value, connection, prepared)
            ^^^^^^^^^^^^^^^^^^^^^^^^^^^^^^^^^^^^^^^^^^^^^^^^^^^^^^
  File "C:\Users\pooja.akolkar\AppData\Local\anaconda3\Lib\site-packages\django\db\models\fields\__init__.py", line 1005, in get_db_prep_value
    value = self.get_prep_value(value)
            ^^^^^^^^^^^^^^^^^^^^^^^^^^
  File "C:\Users\pooja.akolkar\AppData\Local\anaconda3\Lib\site-packages\django\db\models\fields\__init__.py", line 2130, in get_prep_value
    raise e.__class__(
ValueError: Field 'input_token' expected a number but got ''.
2025-06-28 11:50:37,329 | ERROR    | ImageApp1.views | post                 | Line 581  | Error while processing document.
Traceback (most recent call last):
  File "C:\Users\pooja.akolkar\AppData\Local\anaconda3\Lib\site-packages\django\db\models\fields\__init__.py", line 2128, in get_prep_value
    return int(value)
           ^^^^^^^^^^
ValueError: invalid literal for int() with base 10: ''

The above exception was the direct cause of the following exception:

Traceback (most recent call last):
  File "D:\IDP_Project\ImageExtraction\ImageApp1\views.py", line 560, in post
    doc = Document.objects.create(
          ^^^^^^^^^^^^^^^^^^^^^^^^
  File "C:\Users\pooja.akolkar\AppData\Local\anaconda3\Lib\site-packages\django\db\models\manager.py", line 87, in manager_method
    return getattr(self.get_queryset(), name)(*args, **kwargs)
           ^^^^^^^^^^^^^^^^^^^^^^^^^^^^^^^^^^^^^^^^^^^^^^^^^^^
  File "C:\Users\pooja.akolkar\AppData\Local\anaconda3\Lib\site-packages\django\db\models\query.py", line 663, in create
    obj.save(force_insert=True, using=self.db)
  File "C:\Users\pooja.akolkar\AppData\Local\anaconda3\Lib\site-packages\django\db\models\base.py", line 902, in save
    self.save_base(
  File "C:\Users\pooja.akolkar\AppData\Local\anaconda3\Lib\site-packages\django\db\models\base.py", line 1008, in save_base
    updated = self._save_table(
              ^^^^^^^^^^^^^^^^^
  File "C:\Users\pooja.akolkar\AppData\Local\anaconda3\Lib\site-packages\django\db\models\base.py", line 1169, in _save_table
    results = self._do_insert(
              ^^^^^^^^^^^^^^^^
  File "C:\Users\pooja.akolkar\AppData\Local\anaconda3\Lib\site-packages\django\db\models\base.py", line 1210, in _do_insert
    return manager._insert(
           ^^^^^^^^^^^^^^^^
  File "C:\Users\pooja.akolkar\AppData\Local\anaconda3\Lib\site-packages\django\db\models\manager.py", line 87, in manager_method
    return getattr(self.get_queryset(), name)(*args, **kwargs)
           ^^^^^^^^^^^^^^^^^^^^^^^^^^^^^^^^^^^^^^^^^^^^^^^^^^^
  File "C:\Users\pooja.akolkar\AppData\Local\anaconda3\Lib\site-packages\django\db\models\query.py", line 1868, in _insert
    return query.get_compiler(using=using).execute_sql(returning_fields)
           ^^^^^^^^^^^^^^^^^^^^^^^^^^^^^^^^^^^^^^^^^^^^^^^^^^^^^^^^^^^^^
  File "C:\Users\pooja.akolkar\AppData\Local\anaconda3\Lib\site-packages\django\db\models\sql\compiler.py", line 1881, in execute_sql
    for sql, params in self.as_sql():
                       ^^^^^^^^^^^^^
  File "C:\Users\pooja.akolkar\AppData\Local\anaconda3\Lib\site-packages\django\db\models\sql\compiler.py", line 1806, in as_sql
    self.prepare_value(field, self.pre_save_val(field, obj))
  File "C:\Users\pooja.akolkar\AppData\Local\anaconda3\Lib\site-packages\django\db\models\sql\compiler.py", line 1741, in prepare_value
    return field.get_db_prep_save(value, connection=self.connection)
           ^^^^^^^^^^^^^^^^^^^^^^^^^^^^^^^^^^^^^^^^^^^^^^^^^^^^^^^^^
  File "C:\Users\pooja.akolkar\AppData\Local\anaconda3\Lib\site-packages\django\db\models\fields\__init__.py", line 1012, in get_db_prep_save
    return self.get_db_prep_value(value, connection=connection, prepared=False)
           ^^^^^^^^^^^^^^^^^^^^^^^^^^^^^^^^^^^^^^^^^^^^^^^^^^^^^^^^^^^^^^^^^^^^
  File "C:\Users\pooja.akolkar\AppData\Local\anaconda3\Lib\site-packages\django\db\models\fields\__init__.py", line 2135, in get_db_prep_value
    value = super().get_db_prep_value(value, connection, prepared)
            ^^^^^^^^^^^^^^^^^^^^^^^^^^^^^^^^^^^^^^^^^^^^^^^^^^^^^^
  File "C:\Users\pooja.akolkar\AppData\Local\anaconda3\Lib\site-packages\django\db\models\fields\__init__.py", line 1005, in get_db_prep_value
    value = self.get_prep_value(value)
            ^^^^^^^^^^^^^^^^^^^^^^^^^^
  File "C:\Users\pooja.akolkar\AppData\Local\anaconda3\Lib\site-packages\django\db\models\fields\__init__.py", line 2130, in get_prep_value
    raise e.__class__(
ValueError: Field 'input_token' expected a number but got ''.
2025-06-28 11:50:37,340 | ERROR    | ImageApp1.views | log_exception        | Line 71   | Exception occurred in D:\IDP_Project\ImageExtraction\ImageApp1\views.py, line 560: doc = Document.objects.create(
2025-06-28 11:50:37,340 | ERROR    | ImageApp1.views | log_exception        | Line 71   | Exception occurred in C:\Users\pooja.akolkar\AppData\Local\anaconda3\Lib\site-packages\django\db\models\manager.py, line 87: return getattr(self.get_queryset(), name)(*args, **kwargs)
2025-06-28 11:50:37,341 | ERROR    | ImageApp1.views | log_exception        | Line 71   | Exception occurred in C:\Users\pooja.akolkar\AppData\Local\anaconda3\Lib\site-packages\django\db\models\query.py, line 663: obj.save(force_insert=True, using=self.db)
2025-06-28 11:50:37,341 | ERROR    | ImageApp1.views | log_exception        | Line 71   | Exception occurred in C:\Users\pooja.akolkar\AppData\Local\anaconda3\Lib\site-packages\django\db\models\base.py, line 902: self.save_base(
2025-06-28 11:50:37,342 | ERROR    | ImageApp1.views | log_exception        | Line 71   | Exception occurred in C:\Users\pooja.akolkar\AppData\Local\anaconda3\Lib\site-packages\django\db\models\base.py, line 1008: updated = self._save_table(
2025-06-28 11:50:37,343 | ERROR    | ImageApp1.views | log_exception        | Line 71   | Exception occurred in C:\Users\pooja.akolkar\AppData\Local\anaconda3\Lib\site-packages\django\db\models\base.py, line 1169: results = self._do_insert(
2025-06-28 11:50:37,343 | ERROR    | ImageApp1.views | log_exception        | Line 71   | Exception occurred in C:\Users\pooja.akolkar\AppData\Local\anaconda3\Lib\site-packages\django\db\models\base.py, line 1210: return manager._insert(
2025-06-28 11:50:37,344 | ERROR    | ImageApp1.views | log_exception        | Line 71   | Exception occurred in C:\Users\pooja.akolkar\AppData\Local\anaconda3\Lib\site-packages\django\db\models\manager.py, line 87: return getattr(self.get_queryset(), name)(*args, **kwargs)
2025-06-28 11:50:37,345 | ERROR    | ImageApp1.views | log_exception        | Line 71   | Exception occurred in C:\Users\pooja.akolkar\AppData\Local\anaconda3\Lib\site-packages\django\db\models\query.py, line 1868: return query.get_compiler(using=using).execute_sql(returning_fields)
2025-06-28 11:50:37,346 | ERROR    | ImageApp1.views | log_exception        | Line 71   | Exception occurred in C:\Users\pooja.akolkar\AppData\Local\anaconda3\Lib\site-packages\django\db\models\sql\compiler.py, line 1881: for sql, params in self.as_sql():
2025-06-28 11:50:37,346 | ERROR    | ImageApp1.views | log_exception        | Line 71   | Exception occurred in C:\Users\pooja.akolkar\AppData\Local\anaconda3\Lib\site-packages\django\db\models\sql\compiler.py, line 1806: self.prepare_value(field, self.pre_save_val(field, obj))
2025-06-28 11:50:37,347 | ERROR    | ImageApp1.views | log_exception        | Line 71   | Exception occurred in C:\Users\pooja.akolkar\AppData\Local\anaconda3\Lib\site-packages\django\db\models\sql\compiler.py, line 1741: return field.get_db_prep_save(value, connection=self.connection)
2025-06-28 11:50:37,348 | ERROR    | ImageApp1.views | log_exception        | Line 71   | Exception occurred in C:\Users\pooja.akolkar\AppData\Local\anaconda3\Lib\site-packages\django\db\models\fields\__init__.py, line 1012: return self.get_db_prep_value(value, connection=connection, prepared=False)
2025-06-28 11:50:37,348 | ERROR    | ImageApp1.views | log_exception        | Line 71   | Exception occurred in C:\Users\pooja.akolkar\AppData\Local\anaconda3\Lib\site-packages\django\db\models\fields\__init__.py, line 2135: value = super().get_db_prep_value(value, connection, prepared)
2025-06-28 11:50:37,349 | ERROR    | ImageApp1.views | log_exception        | Line 71   | Exception occurred in C:\Users\pooja.akolkar\AppData\Local\anaconda3\Lib\site-packages\django\db\models\fields\__init__.py, line 1005: value = self.get_prep_value(value)
2025-06-28 11:50:37,350 | ERROR    | ImageApp1.views | log_exception        | Line 71   | Exception occurred in C:\Users\pooja.akolkar\AppData\Local\anaconda3\Lib\site-packages\django\db\models\fields\__init__.py, line 2130: raise e.__class__(
2025-06-28 11:50:37,352 | ERROR    |  django.request | log_response         | Line 253  | Internal Server Error: /IDA/upload/
2025-06-28 11:51:49,041 | INFO     | ImageApp1.views | post                 | Line 321  | Upload request received
2025-06-28 11:52:58,558 | ERROR    | ImageApp1.views | post                 | Line 580  | 500
Traceback (most recent call last):
  File "C:\Users\pooja.akolkar\AppData\Local\anaconda3\Lib\site-packages\django\db\models\fields\__init__.py", line 2128, in get_prep_value
    return int(value)
           ^^^^^^^^^^
ValueError: invalid literal for int() with base 10: ''

The above exception was the direct cause of the following exception:

Traceback (most recent call last):
  File "D:\IDP_Project\ImageExtraction\ImageApp1\views.py", line 560, in post
    doc = Document.objects.create(
          ^^^^^^^^^^^^^^^^^^^^^^^^
  File "C:\Users\pooja.akolkar\AppData\Local\anaconda3\Lib\site-packages\django\db\models\manager.py", line 87, in manager_method
    return getattr(self.get_queryset(), name)(*args, **kwargs)
           ^^^^^^^^^^^^^^^^^^^^^^^^^^^^^^^^^^^^^^^^^^^^^^^^^^^
  File "C:\Users\pooja.akolkar\AppData\Local\anaconda3\Lib\site-packages\django\db\models\query.py", line 663, in create
    obj.save(force_insert=True, using=self.db)
  File "C:\Users\pooja.akolkar\AppData\Local\anaconda3\Lib\site-packages\django\db\models\base.py", line 902, in save
    self.save_base(
  File "C:\Users\pooja.akolkar\AppData\Local\anaconda3\Lib\site-packages\django\db\models\base.py", line 1008, in save_base
    updated = self._save_table(
              ^^^^^^^^^^^^^^^^^
  File "C:\Users\pooja.akolkar\AppData\Local\anaconda3\Lib\site-packages\django\db\models\base.py", line 1169, in _save_table
    results = self._do_insert(
              ^^^^^^^^^^^^^^^^
  File "C:\Users\pooja.akolkar\AppData\Local\anaconda3\Lib\site-packages\django\db\models\base.py", line 1210, in _do_insert
    return manager._insert(
           ^^^^^^^^^^^^^^^^
  File "C:\Users\pooja.akolkar\AppData\Local\anaconda3\Lib\site-packages\django\db\models\manager.py", line 87, in manager_method
    return getattr(self.get_queryset(), name)(*args, **kwargs)
           ^^^^^^^^^^^^^^^^^^^^^^^^^^^^^^^^^^^^^^^^^^^^^^^^^^^
  File "C:\Users\pooja.akolkar\AppData\Local\anaconda3\Lib\site-packages\django\db\models\query.py", line 1868, in _insert
    return query.get_compiler(using=using).execute_sql(returning_fields)
           ^^^^^^^^^^^^^^^^^^^^^^^^^^^^^^^^^^^^^^^^^^^^^^^^^^^^^^^^^^^^^
  File "C:\Users\pooja.akolkar\AppData\Local\anaconda3\Lib\site-packages\django\db\models\sql\compiler.py", line 1881, in execute_sql
    for sql, params in self.as_sql():
                       ^^^^^^^^^^^^^
  File "C:\Users\pooja.akolkar\AppData\Local\anaconda3\Lib\site-packages\django\db\models\sql\compiler.py", line 1806, in as_sql
    self.prepare_value(field, self.pre_save_val(field, obj))
  File "C:\Users\pooja.akolkar\AppData\Local\anaconda3\Lib\site-packages\django\db\models\sql\compiler.py", line 1741, in prepare_value
    return field.get_db_prep_save(value, connection=self.connection)
           ^^^^^^^^^^^^^^^^^^^^^^^^^^^^^^^^^^^^^^^^^^^^^^^^^^^^^^^^^
  File "C:\Users\pooja.akolkar\AppData\Local\anaconda3\Lib\site-packages\django\db\models\fields\__init__.py", line 1012, in get_db_prep_save
    return self.get_db_prep_value(value, connection=connection, prepared=False)
           ^^^^^^^^^^^^^^^^^^^^^^^^^^^^^^^^^^^^^^^^^^^^^^^^^^^^^^^^^^^^^^^^^^^^
  File "C:\Users\pooja.akolkar\AppData\Local\anaconda3\Lib\site-packages\django\db\models\fields\__init__.py", line 2135, in get_db_prep_value
    value = super().get_db_prep_value(value, connection, prepared)
            ^^^^^^^^^^^^^^^^^^^^^^^^^^^^^^^^^^^^^^^^^^^^^^^^^^^^^^
  File "C:\Users\pooja.akolkar\AppData\Local\anaconda3\Lib\site-packages\django\db\models\fields\__init__.py", line 1005, in get_db_prep_value
    value = self.get_prep_value(value)
            ^^^^^^^^^^^^^^^^^^^^^^^^^^
  File "C:\Users\pooja.akolkar\AppData\Local\anaconda3\Lib\site-packages\django\db\models\fields\__init__.py", line 2130, in get_prep_value
    raise e.__class__(
ValueError: Field 'input_token' expected a number but got ''.
2025-06-28 11:52:58,562 | ERROR    | ImageApp1.views | post                 | Line 581  | Error while processing document.
Traceback (most recent call last):
  File "C:\Users\pooja.akolkar\AppData\Local\anaconda3\Lib\site-packages\django\db\models\fields\__init__.py", line 2128, in get_prep_value
    return int(value)
           ^^^^^^^^^^
ValueError: invalid literal for int() with base 10: ''

The above exception was the direct cause of the following exception:

Traceback (most recent call last):
  File "D:\IDP_Project\ImageExtraction\ImageApp1\views.py", line 560, in post
    doc = Document.objects.create(
          ^^^^^^^^^^^^^^^^^^^^^^^^
  File "C:\Users\pooja.akolkar\AppData\Local\anaconda3\Lib\site-packages\django\db\models\manager.py", line 87, in manager_method
    return getattr(self.get_queryset(), name)(*args, **kwargs)
           ^^^^^^^^^^^^^^^^^^^^^^^^^^^^^^^^^^^^^^^^^^^^^^^^^^^
  File "C:\Users\pooja.akolkar\AppData\Local\anaconda3\Lib\site-packages\django\db\models\query.py", line 663, in create
    obj.save(force_insert=True, using=self.db)
  File "C:\Users\pooja.akolkar\AppData\Local\anaconda3\Lib\site-packages\django\db\models\base.py", line 902, in save
    self.save_base(
  File "C:\Users\pooja.akolkar\AppData\Local\anaconda3\Lib\site-packages\django\db\models\base.py", line 1008, in save_base
    updated = self._save_table(
              ^^^^^^^^^^^^^^^^^
  File "C:\Users\pooja.akolkar\AppData\Local\anaconda3\Lib\site-packages\django\db\models\base.py", line 1169, in _save_table
    results = self._do_insert(
              ^^^^^^^^^^^^^^^^
  File "C:\Users\pooja.akolkar\AppData\Local\anaconda3\Lib\site-packages\django\db\models\base.py", line 1210, in _do_insert
    return manager._insert(
           ^^^^^^^^^^^^^^^^
  File "C:\Users\pooja.akolkar\AppData\Local\anaconda3\Lib\site-packages\django\db\models\manager.py", line 87, in manager_method
    return getattr(self.get_queryset(), name)(*args, **kwargs)
           ^^^^^^^^^^^^^^^^^^^^^^^^^^^^^^^^^^^^^^^^^^^^^^^^^^^
  File "C:\Users\pooja.akolkar\AppData\Local\anaconda3\Lib\site-packages\django\db\models\query.py", line 1868, in _insert
    return query.get_compiler(using=using).execute_sql(returning_fields)
           ^^^^^^^^^^^^^^^^^^^^^^^^^^^^^^^^^^^^^^^^^^^^^^^^^^^^^^^^^^^^^
  File "C:\Users\pooja.akolkar\AppData\Local\anaconda3\Lib\site-packages\django\db\models\sql\compiler.py", line 1881, in execute_sql
    for sql, params in self.as_sql():
                       ^^^^^^^^^^^^^
  File "C:\Users\pooja.akolkar\AppData\Local\anaconda3\Lib\site-packages\django\db\models\sql\compiler.py", line 1806, in as_sql
    self.prepare_value(field, self.pre_save_val(field, obj))
  File "C:\Users\pooja.akolkar\AppData\Local\anaconda3\Lib\site-packages\django\db\models\sql\compiler.py", line 1741, in prepare_value
    return field.get_db_prep_save(value, connection=self.connection)
           ^^^^^^^^^^^^^^^^^^^^^^^^^^^^^^^^^^^^^^^^^^^^^^^^^^^^^^^^^
  File "C:\Users\pooja.akolkar\AppData\Local\anaconda3\Lib\site-packages\django\db\models\fields\__init__.py", line 1012, in get_db_prep_save
    return self.get_db_prep_value(value, connection=connection, prepared=False)
           ^^^^^^^^^^^^^^^^^^^^^^^^^^^^^^^^^^^^^^^^^^^^^^^^^^^^^^^^^^^^^^^^^^^^
  File "C:\Users\pooja.akolkar\AppData\Local\anaconda3\Lib\site-packages\django\db\models\fields\__init__.py", line 2135, in get_db_prep_value
    value = super().get_db_prep_value(value, connection, prepared)
            ^^^^^^^^^^^^^^^^^^^^^^^^^^^^^^^^^^^^^^^^^^^^^^^^^^^^^^
  File "C:\Users\pooja.akolkar\AppData\Local\anaconda3\Lib\site-packages\django\db\models\fields\__init__.py", line 1005, in get_db_prep_value
    value = self.get_prep_value(value)
            ^^^^^^^^^^^^^^^^^^^^^^^^^^
  File "C:\Users\pooja.akolkar\AppData\Local\anaconda3\Lib\site-packages\django\db\models\fields\__init__.py", line 2130, in get_prep_value
    raise e.__class__(
ValueError: Field 'input_token' expected a number but got ''.
2025-06-28 11:52:58,570 | ERROR    | ImageApp1.views | log_exception        | Line 71   | Exception occurred in D:\IDP_Project\ImageExtraction\ImageApp1\views.py, line 560: doc = Document.objects.create(
2025-06-28 11:52:58,570 | ERROR    | ImageApp1.views | log_exception        | Line 71   | Exception occurred in C:\Users\pooja.akolkar\AppData\Local\anaconda3\Lib\site-packages\django\db\models\manager.py, line 87: return getattr(self.get_queryset(), name)(*args, **kwargs)
2025-06-28 11:52:58,571 | ERROR    | ImageApp1.views | log_exception        | Line 71   | Exception occurred in C:\Users\pooja.akolkar\AppData\Local\anaconda3\Lib\site-packages\django\db\models\query.py, line 663: obj.save(force_insert=True, using=self.db)
2025-06-28 11:52:58,571 | ERROR    | ImageApp1.views | log_exception        | Line 71   | Exception occurred in C:\Users\pooja.akolkar\AppData\Local\anaconda3\Lib\site-packages\django\db\models\base.py, line 902: self.save_base(
2025-06-28 11:52:58,572 | ERROR    | ImageApp1.views | log_exception        | Line 71   | Exception occurred in C:\Users\pooja.akolkar\AppData\Local\anaconda3\Lib\site-packages\django\db\models\base.py, line 1008: updated = self._save_table(
2025-06-28 11:52:58,572 | ERROR    | ImageApp1.views | log_exception        | Line 71   | Exception occurred in C:\Users\pooja.akolkar\AppData\Local\anaconda3\Lib\site-packages\django\db\models\base.py, line 1169: results = self._do_insert(
2025-06-28 11:52:58,573 | ERROR    | ImageApp1.views | log_exception        | Line 71   | Exception occurred in C:\Users\pooja.akolkar\AppData\Local\anaconda3\Lib\site-packages\django\db\models\base.py, line 1210: return manager._insert(
2025-06-28 11:52:58,574 | ERROR    | ImageApp1.views | log_exception        | Line 71   | Exception occurred in C:\Users\pooja.akolkar\AppData\Local\anaconda3\Lib\site-packages\django\db\models\manager.py, line 87: return getattr(self.get_queryset(), name)(*args, **kwargs)
2025-06-28 11:52:58,574 | ERROR    | ImageApp1.views | log_exception        | Line 71   | Exception occurred in C:\Users\pooja.akolkar\AppData\Local\anaconda3\Lib\site-packages\django\db\models\query.py, line 1868: return query.get_compiler(using=using).execute_sql(returning_fields)
2025-06-28 11:52:58,575 | ERROR    | ImageApp1.views | log_exception        | Line 71   | Exception occurred in C:\Users\pooja.akolkar\AppData\Local\anaconda3\Lib\site-packages\django\db\models\sql\compiler.py, line 1881: for sql, params in self.as_sql():
2025-06-28 11:52:58,575 | ERROR    | ImageApp1.views | log_exception        | Line 71   | Exception occurred in C:\Users\pooja.akolkar\AppData\Local\anaconda3\Lib\site-packages\django\db\models\sql\compiler.py, line 1806: self.prepare_value(field, self.pre_save_val(field, obj))
2025-06-28 11:52:58,576 | ERROR    | ImageApp1.views | log_exception        | Line 71   | Exception occurred in C:\Users\pooja.akolkar\AppData\Local\anaconda3\Lib\site-packages\django\db\models\sql\compiler.py, line 1741: return field.get_db_prep_save(value, connection=self.connection)
2025-06-28 11:52:58,577 | ERROR    | ImageApp1.views | log_exception        | Line 71   | Exception occurred in C:\Users\pooja.akolkar\AppData\Local\anaconda3\Lib\site-packages\django\db\models\fields\__init__.py, line 1012: return self.get_db_prep_value(value, connection=connection, prepared=False)
2025-06-28 11:52:58,578 | ERROR    | ImageApp1.views | log_exception        | Line 71   | Exception occurred in C:\Users\pooja.akolkar\AppData\Local\anaconda3\Lib\site-packages\django\db\models\fields\__init__.py, line 2135: value = super().get_db_prep_value(value, connection, prepared)
2025-06-28 11:52:58,584 | ERROR    | ImageApp1.views | log_exception        | Line 71   | Exception occurred in C:\Users\pooja.akolkar\AppData\Local\anaconda3\Lib\site-packages\django\db\models\fields\__init__.py, line 1005: value = self.get_prep_value(value)
2025-06-28 11:52:58,584 | ERROR    | ImageApp1.views | log_exception        | Line 71   | Exception occurred in C:\Users\pooja.akolkar\AppData\Local\anaconda3\Lib\site-packages\django\db\models\fields\__init__.py, line 2130: raise e.__class__(
2025-06-28 11:52:58,587 | ERROR    |  django.request | log_response         | Line 253  | Internal Server Error: /IDA/upload/
2025-06-28 11:54:31,879 | INFO     | django.utils.autoreload | trigger_reload       | Line 265  | D:\IDP_Project\ImageExtraction\ImageApp1\views.py changed, reloading.
2025-06-28 11:54:33,829 | INFO     | django.utils.autoreload | run_with_reloader    | Line 667  | Watching for file changes with StatReloader
2025-06-28 11:54:39,959 | DEBUG    | google.cloud.storage._opentelemetry_tracing | <module>             | Line 42   | This service is instrumented using OpenTelemetry. OpenTelemetry or one of its components could not be imported; please add compatible versions of opentelemetry-api and opentelemetry-instrumentation packages in order to get Storage Tracing data.
2025-06-28 11:54:47,054 | INFO     | django.utils.autoreload | trigger_reload       | Line 265  | D:\IDP_Project\ImageExtraction\ImageApp1\views.py changed, reloading.
2025-06-28 11:54:49,394 | INFO     | django.utils.autoreload | run_with_reloader    | Line 667  | Watching for file changes with StatReloader
2025-06-28 11:54:56,027 | DEBUG    | google.cloud.storage._opentelemetry_tracing | <module>             | Line 42   | This service is instrumented using OpenTelemetry. OpenTelemetry or one of its components could not be imported; please add compatible versions of opentelemetry-api and opentelemetry-instrumentation packages in order to get Storage Tracing data.
2025-06-28 11:54:58,616 | INFO     | ImageApp1.views | post                 | Line 321  | Upload request received
2025-06-28 11:55:22,471 | INFO     | ImageApp1.views | post                 | Line 461  | Usage metadata not available in the response.
2025-06-28 11:56:25,765 | ERROR    | ImageApp1.views | post                 | Line 578  | 500
Traceback (most recent call last):
  File "C:\Users\pooja.akolkar\AppData\Local\anaconda3\Lib\site-packages\django\db\models\fields\__init__.py", line 2128, in get_prep_value
    return int(value)
           ^^^^^^^^^^
ValueError: invalid literal for int() with base 10: ''

The above exception was the direct cause of the following exception:

Traceback (most recent call last):
  File "D:\IDP_Project\ImageExtraction\ImageApp1\views.py", line 558, in post
    doc = Document.objects.create(
          ^^^^^^^^^^^^^^^^^^^^^^^^
  File "C:\Users\pooja.akolkar\AppData\Local\anaconda3\Lib\site-packages\django\db\models\manager.py", line 87, in manager_method
    return getattr(self.get_queryset(), name)(*args, **kwargs)
           ^^^^^^^^^^^^^^^^^^^^^^^^^^^^^^^^^^^^^^^^^^^^^^^^^^^
  File "C:\Users\pooja.akolkar\AppData\Local\anaconda3\Lib\site-packages\django\db\models\query.py", line 663, in create
    obj.save(force_insert=True, using=self.db)
  File "C:\Users\pooja.akolkar\AppData\Local\anaconda3\Lib\site-packages\django\db\models\base.py", line 902, in save
    self.save_base(
  File "C:\Users\pooja.akolkar\AppData\Local\anaconda3\Lib\site-packages\django\db\models\base.py", line 1008, in save_base
    updated = self._save_table(
              ^^^^^^^^^^^^^^^^^
  File "C:\Users\pooja.akolkar\AppData\Local\anaconda3\Lib\site-packages\django\db\models\base.py", line 1169, in _save_table
    results = self._do_insert(
              ^^^^^^^^^^^^^^^^
  File "C:\Users\pooja.akolkar\AppData\Local\anaconda3\Lib\site-packages\django\db\models\base.py", line 1210, in _do_insert
    return manager._insert(
           ^^^^^^^^^^^^^^^^
  File "C:\Users\pooja.akolkar\AppData\Local\anaconda3\Lib\site-packages\django\db\models\manager.py", line 87, in manager_method
    return getattr(self.get_queryset(), name)(*args, **kwargs)
           ^^^^^^^^^^^^^^^^^^^^^^^^^^^^^^^^^^^^^^^^^^^^^^^^^^^
  File "C:\Users\pooja.akolkar\AppData\Local\anaconda3\Lib\site-packages\django\db\models\query.py", line 1868, in _insert
    return query.get_compiler(using=using).execute_sql(returning_fields)
           ^^^^^^^^^^^^^^^^^^^^^^^^^^^^^^^^^^^^^^^^^^^^^^^^^^^^^^^^^^^^^
  File "C:\Users\pooja.akolkar\AppData\Local\anaconda3\Lib\site-packages\django\db\models\sql\compiler.py", line 1881, in execute_sql
    for sql, params in self.as_sql():
                       ^^^^^^^^^^^^^
  File "C:\Users\pooja.akolkar\AppData\Local\anaconda3\Lib\site-packages\django\db\models\sql\compiler.py", line 1806, in as_sql
    self.prepare_value(field, self.pre_save_val(field, obj))
  File "C:\Users\pooja.akolkar\AppData\Local\anaconda3\Lib\site-packages\django\db\models\sql\compiler.py", line 1741, in prepare_value
    return field.get_db_prep_save(value, connection=self.connection)
           ^^^^^^^^^^^^^^^^^^^^^^^^^^^^^^^^^^^^^^^^^^^^^^^^^^^^^^^^^
  File "C:\Users\pooja.akolkar\AppData\Local\anaconda3\Lib\site-packages\django\db\models\fields\__init__.py", line 1012, in get_db_prep_save
    return self.get_db_prep_value(value, connection=connection, prepared=False)
           ^^^^^^^^^^^^^^^^^^^^^^^^^^^^^^^^^^^^^^^^^^^^^^^^^^^^^^^^^^^^^^^^^^^^
  File "C:\Users\pooja.akolkar\AppData\Local\anaconda3\Lib\site-packages\django\db\models\fields\__init__.py", line 2135, in get_db_prep_value
    value = super().get_db_prep_value(value, connection, prepared)
            ^^^^^^^^^^^^^^^^^^^^^^^^^^^^^^^^^^^^^^^^^^^^^^^^^^^^^^
  File "C:\Users\pooja.akolkar\AppData\Local\anaconda3\Lib\site-packages\django\db\models\fields\__init__.py", line 1005, in get_db_prep_value
    value = self.get_prep_value(value)
            ^^^^^^^^^^^^^^^^^^^^^^^^^^
  File "C:\Users\pooja.akolkar\AppData\Local\anaconda3\Lib\site-packages\django\db\models\fields\__init__.py", line 2130, in get_prep_value
    raise e.__class__(
ValueError: Field 'input_token' expected a number but got ''.
2025-06-28 11:56:25,776 | ERROR    | ImageApp1.views | post                 | Line 579  | Error while processing document.
Traceback (most recent call last):
  File "C:\Users\pooja.akolkar\AppData\Local\anaconda3\Lib\site-packages\django\db\models\fields\__init__.py", line 2128, in get_prep_value
    return int(value)
           ^^^^^^^^^^
ValueError: invalid literal for int() with base 10: ''

The above exception was the direct cause of the following exception:

Traceback (most recent call last):
  File "D:\IDP_Project\ImageExtraction\ImageApp1\views.py", line 558, in post
    doc = Document.objects.create(
          ^^^^^^^^^^^^^^^^^^^^^^^^
  File "C:\Users\pooja.akolkar\AppData\Local\anaconda3\Lib\site-packages\django\db\models\manager.py", line 87, in manager_method
    return getattr(self.get_queryset(), name)(*args, **kwargs)
           ^^^^^^^^^^^^^^^^^^^^^^^^^^^^^^^^^^^^^^^^^^^^^^^^^^^
  File "C:\Users\pooja.akolkar\AppData\Local\anaconda3\Lib\site-packages\django\db\models\query.py", line 663, in create
    obj.save(force_insert=True, using=self.db)
  File "C:\Users\pooja.akolkar\AppData\Local\anaconda3\Lib\site-packages\django\db\models\base.py", line 902, in save
    self.save_base(
  File "C:\Users\pooja.akolkar\AppData\Local\anaconda3\Lib\site-packages\django\db\models\base.py", line 1008, in save_base
    updated = self._save_table(
              ^^^^^^^^^^^^^^^^^
  File "C:\Users\pooja.akolkar\AppData\Local\anaconda3\Lib\site-packages\django\db\models\base.py", line 1169, in _save_table
    results = self._do_insert(
              ^^^^^^^^^^^^^^^^
  File "C:\Users\pooja.akolkar\AppData\Local\anaconda3\Lib\site-packages\django\db\models\base.py", line 1210, in _do_insert
    return manager._insert(
           ^^^^^^^^^^^^^^^^
  File "C:\Users\pooja.akolkar\AppData\Local\anaconda3\Lib\site-packages\django\db\models\manager.py", line 87, in manager_method
    return getattr(self.get_queryset(), name)(*args, **kwargs)
           ^^^^^^^^^^^^^^^^^^^^^^^^^^^^^^^^^^^^^^^^^^^^^^^^^^^
  File "C:\Users\pooja.akolkar\AppData\Local\anaconda3\Lib\site-packages\django\db\models\query.py", line 1868, in _insert
    return query.get_compiler(using=using).execute_sql(returning_fields)
           ^^^^^^^^^^^^^^^^^^^^^^^^^^^^^^^^^^^^^^^^^^^^^^^^^^^^^^^^^^^^^
  File "C:\Users\pooja.akolkar\AppData\Local\anaconda3\Lib\site-packages\django\db\models\sql\compiler.py", line 1881, in execute_sql
    for sql, params in self.as_sql():
                       ^^^^^^^^^^^^^
  File "C:\Users\pooja.akolkar\AppData\Local\anaconda3\Lib\site-packages\django\db\models\sql\compiler.py", line 1806, in as_sql
    self.prepare_value(field, self.pre_save_val(field, obj))
  File "C:\Users\pooja.akolkar\AppData\Local\anaconda3\Lib\site-packages\django\db\models\sql\compiler.py", line 1741, in prepare_value
    return field.get_db_prep_save(value, connection=self.connection)
           ^^^^^^^^^^^^^^^^^^^^^^^^^^^^^^^^^^^^^^^^^^^^^^^^^^^^^^^^^
  File "C:\Users\pooja.akolkar\AppData\Local\anaconda3\Lib\site-packages\django\db\models\fields\__init__.py", line 1012, in get_db_prep_save
    return self.get_db_prep_value(value, connection=connection, prepared=False)
           ^^^^^^^^^^^^^^^^^^^^^^^^^^^^^^^^^^^^^^^^^^^^^^^^^^^^^^^^^^^^^^^^^^^^
  File "C:\Users\pooja.akolkar\AppData\Local\anaconda3\Lib\site-packages\django\db\models\fields\__init__.py", line 2135, in get_db_prep_value
    value = super().get_db_prep_value(value, connection, prepared)
            ^^^^^^^^^^^^^^^^^^^^^^^^^^^^^^^^^^^^^^^^^^^^^^^^^^^^^^
  File "C:\Users\pooja.akolkar\AppData\Local\anaconda3\Lib\site-packages\django\db\models\fields\__init__.py", line 1005, in get_db_prep_value
    value = self.get_prep_value(value)
            ^^^^^^^^^^^^^^^^^^^^^^^^^^
  File "C:\Users\pooja.akolkar\AppData\Local\anaconda3\Lib\site-packages\django\db\models\fields\__init__.py", line 2130, in get_prep_value
    raise e.__class__(
ValueError: Field 'input_token' expected a number but got ''.
2025-06-28 11:56:25,786 | ERROR    | ImageApp1.views | log_exception        | Line 71   | Exception occurred in D:\IDP_Project\ImageExtraction\ImageApp1\views.py, line 558: doc = Document.objects.create(
2025-06-28 11:56:25,787 | ERROR    | ImageApp1.views | log_exception        | Line 71   | Exception occurred in C:\Users\pooja.akolkar\AppData\Local\anaconda3\Lib\site-packages\django\db\models\manager.py, line 87: return getattr(self.get_queryset(), name)(*args, **kwargs)
2025-06-28 11:56:25,787 | ERROR    | ImageApp1.views | log_exception        | Line 71   | Exception occurred in C:\Users\pooja.akolkar\AppData\Local\anaconda3\Lib\site-packages\django\db\models\query.py, line 663: obj.save(force_insert=True, using=self.db)
2025-06-28 11:56:25,788 | ERROR    | ImageApp1.views | log_exception        | Line 71   | Exception occurred in C:\Users\pooja.akolkar\AppData\Local\anaconda3\Lib\site-packages\django\db\models\base.py, line 902: self.save_base(
2025-06-28 11:56:25,789 | ERROR    | ImageApp1.views | log_exception        | Line 71   | Exception occurred in C:\Users\pooja.akolkar\AppData\Local\anaconda3\Lib\site-packages\django\db\models\base.py, line 1008: updated = self._save_table(
2025-06-28 11:56:25,789 | ERROR    | ImageApp1.views | log_exception        | Line 71   | Exception occurred in C:\Users\pooja.akolkar\AppData\Local\anaconda3\Lib\site-packages\django\db\models\base.py, line 1169: results = self._do_insert(
2025-06-28 11:56:25,790 | ERROR    | ImageApp1.views | log_exception        | Line 71   | Exception occurred in C:\Users\pooja.akolkar\AppData\Local\anaconda3\Lib\site-packages\django\db\models\base.py, line 1210: return manager._insert(
2025-06-28 11:56:25,791 | ERROR    | ImageApp1.views | log_exception        | Line 71   | Exception occurred in C:\Users\pooja.akolkar\AppData\Local\anaconda3\Lib\site-packages\django\db\models\manager.py, line 87: return getattr(self.get_queryset(), name)(*args, **kwargs)
2025-06-28 11:56:25,791 | ERROR    | ImageApp1.views | log_exception        | Line 71   | Exception occurred in C:\Users\pooja.akolkar\AppData\Local\anaconda3\Lib\site-packages\django\db\models\query.py, line 1868: return query.get_compiler(using=using).execute_sql(returning_fields)
2025-06-28 11:56:25,792 | ERROR    | ImageApp1.views | log_exception        | Line 71   | Exception occurred in C:\Users\pooja.akolkar\AppData\Local\anaconda3\Lib\site-packages\django\db\models\sql\compiler.py, line 1881: for sql, params in self.as_sql():
2025-06-28 11:56:25,792 | ERROR    | ImageApp1.views | log_exception        | Line 71   | Exception occurred in C:\Users\pooja.akolkar\AppData\Local\anaconda3\Lib\site-packages\django\db\models\sql\compiler.py, line 1806: self.prepare_value(field, self.pre_save_val(field, obj))
2025-06-28 11:56:25,793 | ERROR    | ImageApp1.views | log_exception        | Line 71   | Exception occurred in C:\Users\pooja.akolkar\AppData\Local\anaconda3\Lib\site-packages\django\db\models\sql\compiler.py, line 1741: return field.get_db_prep_save(value, connection=self.connection)
2025-06-28 11:56:25,795 | ERROR    | ImageApp1.views | log_exception        | Line 71   | Exception occurred in C:\Users\pooja.akolkar\AppData\Local\anaconda3\Lib\site-packages\django\db\models\fields\__init__.py, line 1012: return self.get_db_prep_value(value, connection=connection, prepared=False)
2025-06-28 11:56:25,796 | ERROR    | ImageApp1.views | log_exception        | Line 71   | Exception occurred in C:\Users\pooja.akolkar\AppData\Local\anaconda3\Lib\site-packages\django\db\models\fields\__init__.py, line 2135: value = super().get_db_prep_value(value, connection, prepared)
2025-06-28 11:56:25,796 | ERROR    | ImageApp1.views | log_exception        | Line 71   | Exception occurred in C:\Users\pooja.akolkar\AppData\Local\anaconda3\Lib\site-packages\django\db\models\fields\__init__.py, line 1005: value = self.get_prep_value(value)
2025-06-28 11:56:25,797 | ERROR    | ImageApp1.views | log_exception        | Line 71   | Exception occurred in C:\Users\pooja.akolkar\AppData\Local\anaconda3\Lib\site-packages\django\db\models\fields\__init__.py, line 2130: raise e.__class__(
2025-06-28 11:56:25,798 | ERROR    |  django.request | log_response         | Line 253  | Internal Server Error: /IDA/upload/
2025-06-28 11:59:51,483 | INFO     | django.utils.autoreload | trigger_reload       | Line 265  | D:\IDP_Project\ImageExtraction\ImageApp1\views.py changed, reloading.
2025-06-28 11:59:53,580 | INFO     | django.utils.autoreload | run_with_reloader    | Line 667  | Watching for file changes with StatReloader
2025-06-28 12:00:00,219 | DEBUG    | google.cloud.storage._opentelemetry_tracing | <module>             | Line 42   | This service is instrumented using OpenTelemetry. OpenTelemetry or one of its components could not be imported; please add compatible versions of opentelemetry-api and opentelemetry-instrumentation packages in order to get Storage Tracing data.
2025-06-28 12:00:06,152 | INFO     | ImageApp1.views | post                 | Line 321  | Upload request received
2025-06-28 12:00:38,890 | DEBUG    | ImageApp1.views | post                 | Line 460  | Usage metadata not included in this Gemini response.
2025-06-28 12:01:30,678 | ERROR    | ImageApp1.views | post                 | Line 578  | 500
Traceback (most recent call last):
  File "C:\Users\pooja.akolkar\AppData\Local\anaconda3\Lib\site-packages\django\db\models\fields\__init__.py", line 2128, in get_prep_value
    return int(value)
           ^^^^^^^^^^
ValueError: invalid literal for int() with base 10: ''

The above exception was the direct cause of the following exception:

Traceback (most recent call last):
  File "D:\IDP_Project\ImageExtraction\ImageApp1\views.py", line 558, in post
    doc = Document.objects.create(
          ^^^^^^^^^^^^^^^^^^^^^^^^
  File "C:\Users\pooja.akolkar\AppData\Local\anaconda3\Lib\site-packages\django\db\models\manager.py", line 87, in manager_method
    return getattr(self.get_queryset(), name)(*args, **kwargs)
           ^^^^^^^^^^^^^^^^^^^^^^^^^^^^^^^^^^^^^^^^^^^^^^^^^^^
  File "C:\Users\pooja.akolkar\AppData\Local\anaconda3\Lib\site-packages\django\db\models\query.py", line 663, in create
    obj.save(force_insert=True, using=self.db)
  File "C:\Users\pooja.akolkar\AppData\Local\anaconda3\Lib\site-packages\django\db\models\base.py", line 902, in save
    self.save_base(
  File "C:\Users\pooja.akolkar\AppData\Local\anaconda3\Lib\site-packages\django\db\models\base.py", line 1008, in save_base
    updated = self._save_table(
              ^^^^^^^^^^^^^^^^^
  File "C:\Users\pooja.akolkar\AppData\Local\anaconda3\Lib\site-packages\django\db\models\base.py", line 1169, in _save_table
    results = self._do_insert(
              ^^^^^^^^^^^^^^^^
  File "C:\Users\pooja.akolkar\AppData\Local\anaconda3\Lib\site-packages\django\db\models\base.py", line 1210, in _do_insert
    return manager._insert(
           ^^^^^^^^^^^^^^^^
  File "C:\Users\pooja.akolkar\AppData\Local\anaconda3\Lib\site-packages\django\db\models\manager.py", line 87, in manager_method
    return getattr(self.get_queryset(), name)(*args, **kwargs)
           ^^^^^^^^^^^^^^^^^^^^^^^^^^^^^^^^^^^^^^^^^^^^^^^^^^^
  File "C:\Users\pooja.akolkar\AppData\Local\anaconda3\Lib\site-packages\django\db\models\query.py", line 1868, in _insert
    return query.get_compiler(using=using).execute_sql(returning_fields)
           ^^^^^^^^^^^^^^^^^^^^^^^^^^^^^^^^^^^^^^^^^^^^^^^^^^^^^^^^^^^^^
  File "C:\Users\pooja.akolkar\AppData\Local\anaconda3\Lib\site-packages\django\db\models\sql\compiler.py", line 1881, in execute_sql
    for sql, params in self.as_sql():
                       ^^^^^^^^^^^^^
  File "C:\Users\pooja.akolkar\AppData\Local\anaconda3\Lib\site-packages\django\db\models\sql\compiler.py", line 1806, in as_sql
    self.prepare_value(field, self.pre_save_val(field, obj))
  File "C:\Users\pooja.akolkar\AppData\Local\anaconda3\Lib\site-packages\django\db\models\sql\compiler.py", line 1741, in prepare_value
    return field.get_db_prep_save(value, connection=self.connection)
           ^^^^^^^^^^^^^^^^^^^^^^^^^^^^^^^^^^^^^^^^^^^^^^^^^^^^^^^^^
  File "C:\Users\pooja.akolkar\AppData\Local\anaconda3\Lib\site-packages\django\db\models\fields\__init__.py", line 1012, in get_db_prep_save
    return self.get_db_prep_value(value, connection=connection, prepared=False)
           ^^^^^^^^^^^^^^^^^^^^^^^^^^^^^^^^^^^^^^^^^^^^^^^^^^^^^^^^^^^^^^^^^^^^
  File "C:\Users\pooja.akolkar\AppData\Local\anaconda3\Lib\site-packages\django\db\models\fields\__init__.py", line 2135, in get_db_prep_value
    value = super().get_db_prep_value(value, connection, prepared)
            ^^^^^^^^^^^^^^^^^^^^^^^^^^^^^^^^^^^^^^^^^^^^^^^^^^^^^^
  File "C:\Users\pooja.akolkar\AppData\Local\anaconda3\Lib\site-packages\django\db\models\fields\__init__.py", line 1005, in get_db_prep_value
    value = self.get_prep_value(value)
            ^^^^^^^^^^^^^^^^^^^^^^^^^^
  File "C:\Users\pooja.akolkar\AppData\Local\anaconda3\Lib\site-packages\django\db\models\fields\__init__.py", line 2130, in get_prep_value
    raise e.__class__(
ValueError: Field 'input_token' expected a number but got ''.
2025-06-28 12:01:30,690 | ERROR    | ImageApp1.views | post                 | Line 579  | Error while processing document.
Traceback (most recent call last):
  File "C:\Users\pooja.akolkar\AppData\Local\anaconda3\Lib\site-packages\django\db\models\fields\__init__.py", line 2128, in get_prep_value
    return int(value)
           ^^^^^^^^^^
ValueError: invalid literal for int() with base 10: ''

The above exception was the direct cause of the following exception:

Traceback (most recent call last):
  File "D:\IDP_Project\ImageExtraction\ImageApp1\views.py", line 558, in post
    doc = Document.objects.create(
          ^^^^^^^^^^^^^^^^^^^^^^^^
  File "C:\Users\pooja.akolkar\AppData\Local\anaconda3\Lib\site-packages\django\db\models\manager.py", line 87, in manager_method
    return getattr(self.get_queryset(), name)(*args, **kwargs)
           ^^^^^^^^^^^^^^^^^^^^^^^^^^^^^^^^^^^^^^^^^^^^^^^^^^^
  File "C:\Users\pooja.akolkar\AppData\Local\anaconda3\Lib\site-packages\django\db\models\query.py", line 663, in create
    obj.save(force_insert=True, using=self.db)
  File "C:\Users\pooja.akolkar\AppData\Local\anaconda3\Lib\site-packages\django\db\models\base.py", line 902, in save
    self.save_base(
  File "C:\Users\pooja.akolkar\AppData\Local\anaconda3\Lib\site-packages\django\db\models\base.py", line 1008, in save_base
    updated = self._save_table(
              ^^^^^^^^^^^^^^^^^
  File "C:\Users\pooja.akolkar\AppData\Local\anaconda3\Lib\site-packages\django\db\models\base.py", line 1169, in _save_table
    results = self._do_insert(
              ^^^^^^^^^^^^^^^^
  File "C:\Users\pooja.akolkar\AppData\Local\anaconda3\Lib\site-packages\django\db\models\base.py", line 1210, in _do_insert
    return manager._insert(
           ^^^^^^^^^^^^^^^^
  File "C:\Users\pooja.akolkar\AppData\Local\anaconda3\Lib\site-packages\django\db\models\manager.py", line 87, in manager_method
    return getattr(self.get_queryset(), name)(*args, **kwargs)
           ^^^^^^^^^^^^^^^^^^^^^^^^^^^^^^^^^^^^^^^^^^^^^^^^^^^
  File "C:\Users\pooja.akolkar\AppData\Local\anaconda3\Lib\site-packages\django\db\models\query.py", line 1868, in _insert
    return query.get_compiler(using=using).execute_sql(returning_fields)
           ^^^^^^^^^^^^^^^^^^^^^^^^^^^^^^^^^^^^^^^^^^^^^^^^^^^^^^^^^^^^^
  File "C:\Users\pooja.akolkar\AppData\Local\anaconda3\Lib\site-packages\django\db\models\sql\compiler.py", line 1881, in execute_sql
    for sql, params in self.as_sql():
                       ^^^^^^^^^^^^^
  File "C:\Users\pooja.akolkar\AppData\Local\anaconda3\Lib\site-packages\django\db\models\sql\compiler.py", line 1806, in as_sql
    self.prepare_value(field, self.pre_save_val(field, obj))
  File "C:\Users\pooja.akolkar\AppData\Local\anaconda3\Lib\site-packages\django\db\models\sql\compiler.py", line 1741, in prepare_value
    return field.get_db_prep_save(value, connection=self.connection)
           ^^^^^^^^^^^^^^^^^^^^^^^^^^^^^^^^^^^^^^^^^^^^^^^^^^^^^^^^^
  File "C:\Users\pooja.akolkar\AppData\Local\anaconda3\Lib\site-packages\django\db\models\fields\__init__.py", line 1012, in get_db_prep_save
    return self.get_db_prep_value(value, connection=connection, prepared=False)
           ^^^^^^^^^^^^^^^^^^^^^^^^^^^^^^^^^^^^^^^^^^^^^^^^^^^^^^^^^^^^^^^^^^^^
  File "C:\Users\pooja.akolkar\AppData\Local\anaconda3\Lib\site-packages\django\db\models\fields\__init__.py", line 2135, in get_db_prep_value
    value = super().get_db_prep_value(value, connection, prepared)
            ^^^^^^^^^^^^^^^^^^^^^^^^^^^^^^^^^^^^^^^^^^^^^^^^^^^^^^
  File "C:\Users\pooja.akolkar\AppData\Local\anaconda3\Lib\site-packages\django\db\models\fields\__init__.py", line 1005, in get_db_prep_value
    value = self.get_prep_value(value)
            ^^^^^^^^^^^^^^^^^^^^^^^^^^
  File "C:\Users\pooja.akolkar\AppData\Local\anaconda3\Lib\site-packages\django\db\models\fields\__init__.py", line 2130, in get_prep_value
    raise e.__class__(
ValueError: Field 'input_token' expected a number but got ''.
2025-06-28 12:01:30,694 | ERROR    | ImageApp1.views | log_exception        | Line 71   | Exception occurred in D:\IDP_Project\ImageExtraction\ImageApp1\views.py, line 558: doc = Document.objects.create(
2025-06-28 12:01:30,695 | ERROR    | ImageApp1.views | log_exception        | Line 71   | Exception occurred in C:\Users\pooja.akolkar\AppData\Local\anaconda3\Lib\site-packages\django\db\models\manager.py, line 87: return getattr(self.get_queryset(), name)(*args, **kwargs)
2025-06-28 12:01:30,695 | ERROR    | ImageApp1.views | log_exception        | Line 71   | Exception occurred in C:\Users\pooja.akolkar\AppData\Local\anaconda3\Lib\site-packages\django\db\models\query.py, line 663: obj.save(force_insert=True, using=self.db)
2025-06-28 12:01:30,695 | ERROR    | ImageApp1.views | log_exception        | Line 71   | Exception occurred in C:\Users\pooja.akolkar\AppData\Local\anaconda3\Lib\site-packages\django\db\models\base.py, line 902: self.save_base(
2025-06-28 12:01:30,696 | ERROR    | ImageApp1.views | log_exception        | Line 71   | Exception occurred in C:\Users\pooja.akolkar\AppData\Local\anaconda3\Lib\site-packages\django\db\models\base.py, line 1008: updated = self._save_table(
2025-06-28 12:01:30,696 | ERROR    | ImageApp1.views | log_exception        | Line 71   | Exception occurred in C:\Users\pooja.akolkar\AppData\Local\anaconda3\Lib\site-packages\django\db\models\base.py, line 1169: results = self._do_insert(
2025-06-28 12:01:30,696 | ERROR    | ImageApp1.views | log_exception        | Line 71   | Exception occurred in C:\Users\pooja.akolkar\AppData\Local\anaconda3\Lib\site-packages\django\db\models\base.py, line 1210: return manager._insert(
2025-06-28 12:01:30,696 | ERROR    | ImageApp1.views | log_exception        | Line 71   | Exception occurred in C:\Users\pooja.akolkar\AppData\Local\anaconda3\Lib\site-packages\django\db\models\manager.py, line 87: return getattr(self.get_queryset(), name)(*args, **kwargs)
2025-06-28 12:01:30,697 | ERROR    | ImageApp1.views | log_exception        | Line 71   | Exception occurred in C:\Users\pooja.akolkar\AppData\Local\anaconda3\Lib\site-packages\django\db\models\query.py, line 1868: return query.get_compiler(using=using).execute_sql(returning_fields)
2025-06-28 12:01:30,697 | ERROR    | ImageApp1.views | log_exception        | Line 71   | Exception occurred in C:\Users\pooja.akolkar\AppData\Local\anaconda3\Lib\site-packages\django\db\models\sql\compiler.py, line 1881: for sql, params in self.as_sql():
2025-06-28 12:01:30,697 | ERROR    | ImageApp1.views | log_exception        | Line 71   | Exception occurred in C:\Users\pooja.akolkar\AppData\Local\anaconda3\Lib\site-packages\django\db\models\sql\compiler.py, line 1806: self.prepare_value(field, self.pre_save_val(field, obj))
2025-06-28 12:01:30,698 | ERROR    | ImageApp1.views | log_exception        | Line 71   | Exception occurred in C:\Users\pooja.akolkar\AppData\Local\anaconda3\Lib\site-packages\django\db\models\sql\compiler.py, line 1741: return field.get_db_prep_save(value, connection=self.connection)
2025-06-28 12:01:30,698 | ERROR    | ImageApp1.views | log_exception        | Line 71   | Exception occurred in C:\Users\pooja.akolkar\AppData\Local\anaconda3\Lib\site-packages\django\db\models\fields\__init__.py, line 1012: return self.get_db_prep_value(value, connection=connection, prepared=False)
2025-06-28 12:01:30,699 | ERROR    | ImageApp1.views | log_exception        | Line 71   | Exception occurred in C:\Users\pooja.akolkar\AppData\Local\anaconda3\Lib\site-packages\django\db\models\fields\__init__.py, line 2135: value = super().get_db_prep_value(value, connection, prepared)
2025-06-28 12:01:30,700 | ERROR    | ImageApp1.views | log_exception        | Line 71   | Exception occurred in C:\Users\pooja.akolkar\AppData\Local\anaconda3\Lib\site-packages\django\db\models\fields\__init__.py, line 1005: value = self.get_prep_value(value)
2025-06-28 12:01:30,700 | ERROR    | ImageApp1.views | log_exception        | Line 71   | Exception occurred in C:\Users\pooja.akolkar\AppData\Local\anaconda3\Lib\site-packages\django\db\models\fields\__init__.py, line 2130: raise e.__class__(
2025-06-28 12:01:30,701 | ERROR    |  django.request | log_response         | Line 253  | Internal Server Error: /IDA/upload/
2025-06-28 12:05:01,171 | INFO     | django.utils.autoreload | run_with_reloader    | Line 667  | Watching for file changes with StatReloader
2025-06-28 12:05:22,601 | DEBUG    | google.cloud.storage._opentelemetry_tracing | <module>             | Line 42   | This service is instrumented using OpenTelemetry. OpenTelemetry or one of its components could not be imported; please add compatible versions of opentelemetry-api and opentelemetry-instrumentation packages in order to get Storage Tracing data.
2025-06-28 12:05:49,028 | INFO     | django.utils.autoreload | trigger_reload       | Line 265  | D:\IDP_Project\ImageExtraction\ImageApp1\views.py changed, reloading.
2025-06-28 12:05:51,422 | INFO     | django.utils.autoreload | run_with_reloader    | Line 667  | Watching for file changes with StatReloader
2025-06-28 12:06:44,360 | INFO     | django.utils.autoreload | trigger_reload       | Line 265  | D:\IDP_Project\ImageExtraction\ImageApp1\views.py changed, reloading.
2025-06-28 12:06:45,988 | INFO     | django.utils.autoreload | run_with_reloader    | Line 667  | Watching for file changes with StatReloader
2025-06-28 12:06:55,757 | INFO     | django.utils.autoreload | trigger_reload       | Line 265  | D:\IDP_Project\ImageExtraction\ImageApp1\views.py changed, reloading.
2025-06-28 12:06:57,463 | INFO     | django.utils.autoreload | run_with_reloader    | Line 667  | Watching for file changes with StatReloader
2025-06-28 12:07:14,252 | INFO     | django.utils.autoreload | run_with_reloader    | Line 667  | Watching for file changes with StatReloader
2025-06-28 12:07:59,366 | INFO     | django.utils.autoreload | trigger_reload       | Line 265  | D:\IDP_Project\ImageExtraction\ImageApp1\views.py changed, reloading.
2025-06-28 12:08:01,535 | INFO     | django.utils.autoreload | run_with_reloader    | Line 667  | Watching for file changes with StatReloader
2025-06-28 12:08:11,039 | INFO     | django.utils.autoreload | run_with_reloader    | Line 667  | Watching for file changes with StatReloader
2025-06-28 12:08:38,456 | INFO     | django.utils.autoreload | trigger_reload       | Line 265  | D:\IDP_Project\ImageExtraction\ImageApp1\views.py changed, reloading.
2025-06-28 12:09:04,052 | INFO     | django.utils.autoreload | run_with_reloader    | Line 667  | Watching for file changes with StatReloader
2025-06-28 12:09:43,792 | INFO     | django.utils.autoreload | run_with_reloader    | Line 667  | Watching for file changes with StatReloader
2025-06-28 12:10:12,651 | INFO     | django.utils.autoreload | trigger_reload       | Line 265  | D:\IDP_Project\ImageExtraction\ImageApp1\views.py changed, reloading.
2025-06-28 12:10:14,300 | INFO     | django.utils.autoreload | run_with_reloader    | Line 667  | Watching for file changes with StatReloader
2025-06-28 12:10:24,313 | INFO     | django.utils.autoreload | trigger_reload       | Line 265  | D:\IDP_Project\ImageExtraction\ImageApp1\views.py changed, reloading.
2025-06-28 12:10:26,011 | INFO     | django.utils.autoreload | run_with_reloader    | Line 667  | Watching for file changes with StatReloader
2025-06-28 12:10:48,770 | INFO     | django.utils.autoreload | trigger_reload       | Line 265  | D:\IDP_Project\ImageExtraction\ImageApp1\views.py changed, reloading.
2025-06-28 12:10:50,524 | INFO     | django.utils.autoreload | run_with_reloader    | Line 667  | Watching for file changes with StatReloader
2025-06-28 12:11:03,914 | DEBUG    | google.cloud.storage._opentelemetry_tracing | <module>             | Line 42   | This service is instrumented using OpenTelemetry. OpenTelemetry or one of its components could not be imported; please add compatible versions of opentelemetry-api and opentelemetry-instrumentation packages in order to get Storage Tracing data.
2025-06-28 12:11:11,386 | INFO     | ImageApp1.views | post                 | Line 321  | Upload request received
2025-06-28 12:11:35,904 | INFO     | ImageApp1.views | post                 | Line 461  | Usage metadata not available in the response.
2025-06-28 12:12:07,220 | ERROR    | ImageApp1.views | post                 | Line 578  | 500
Traceback (most recent call last):
  File "C:\Users\pooja.akolkar\AppData\Local\anaconda3\Lib\site-packages\django\db\models\fields\__init__.py", line 2128, in get_prep_value
    return int(value)
           ^^^^^^^^^^
ValueError: invalid literal for int() with base 10: ''

The above exception was the direct cause of the following exception:

Traceback (most recent call last):
  File "D:\IDP_Project\ImageExtraction\ImageApp1\views.py", line 558, in post
    doc = Document.objects.create(
          ^^^^^^^^^^^^^^^^^^^^^^^^
  File "C:\Users\pooja.akolkar\AppData\Local\anaconda3\Lib\site-packages\django\db\models\manager.py", line 87, in manager_method
    return getattr(self.get_queryset(), name)(*args, **kwargs)
           ^^^^^^^^^^^^^^^^^^^^^^^^^^^^^^^^^^^^^^^^^^^^^^^^^^^
  File "C:\Users\pooja.akolkar\AppData\Local\anaconda3\Lib\site-packages\django\db\models\query.py", line 663, in create
    obj.save(force_insert=True, using=self.db)
  File "C:\Users\pooja.akolkar\AppData\Local\anaconda3\Lib\site-packages\django\db\models\base.py", line 902, in save
    self.save_base(
  File "C:\Users\pooja.akolkar\AppData\Local\anaconda3\Lib\site-packages\django\db\models\base.py", line 1008, in save_base
    updated = self._save_table(
              ^^^^^^^^^^^^^^^^^
  File "C:\Users\pooja.akolkar\AppData\Local\anaconda3\Lib\site-packages\django\db\models\base.py", line 1169, in _save_table
    results = self._do_insert(
              ^^^^^^^^^^^^^^^^
  File "C:\Users\pooja.akolkar\AppData\Local\anaconda3\Lib\site-packages\django\db\models\base.py", line 1210, in _do_insert
    return manager._insert(
           ^^^^^^^^^^^^^^^^
  File "C:\Users\pooja.akolkar\AppData\Local\anaconda3\Lib\site-packages\django\db\models\manager.py", line 87, in manager_method
    return getattr(self.get_queryset(), name)(*args, **kwargs)
           ^^^^^^^^^^^^^^^^^^^^^^^^^^^^^^^^^^^^^^^^^^^^^^^^^^^
  File "C:\Users\pooja.akolkar\AppData\Local\anaconda3\Lib\site-packages\django\db\models\query.py", line 1868, in _insert
    return query.get_compiler(using=using).execute_sql(returning_fields)
           ^^^^^^^^^^^^^^^^^^^^^^^^^^^^^^^^^^^^^^^^^^^^^^^^^^^^^^^^^^^^^
  File "C:\Users\pooja.akolkar\AppData\Local\anaconda3\Lib\site-packages\django\db\models\sql\compiler.py", line 1881, in execute_sql
    for sql, params in self.as_sql():
                       ^^^^^^^^^^^^^
  File "C:\Users\pooja.akolkar\AppData\Local\anaconda3\Lib\site-packages\django\db\models\sql\compiler.py", line 1806, in as_sql
    self.prepare_value(field, self.pre_save_val(field, obj))
  File "C:\Users\pooja.akolkar\AppData\Local\anaconda3\Lib\site-packages\django\db\models\sql\compiler.py", line 1741, in prepare_value
    return field.get_db_prep_save(value, connection=self.connection)
           ^^^^^^^^^^^^^^^^^^^^^^^^^^^^^^^^^^^^^^^^^^^^^^^^^^^^^^^^^
  File "C:\Users\pooja.akolkar\AppData\Local\anaconda3\Lib\site-packages\django\db\models\fields\__init__.py", line 1012, in get_db_prep_save
    return self.get_db_prep_value(value, connection=connection, prepared=False)
           ^^^^^^^^^^^^^^^^^^^^^^^^^^^^^^^^^^^^^^^^^^^^^^^^^^^^^^^^^^^^^^^^^^^^
  File "C:\Users\pooja.akolkar\AppData\Local\anaconda3\Lib\site-packages\django\db\models\fields\__init__.py", line 2135, in get_db_prep_value
    value = super().get_db_prep_value(value, connection, prepared)
            ^^^^^^^^^^^^^^^^^^^^^^^^^^^^^^^^^^^^^^^^^^^^^^^^^^^^^^
  File "C:\Users\pooja.akolkar\AppData\Local\anaconda3\Lib\site-packages\django\db\models\fields\__init__.py", line 1005, in get_db_prep_value
    value = self.get_prep_value(value)
            ^^^^^^^^^^^^^^^^^^^^^^^^^^
  File "C:\Users\pooja.akolkar\AppData\Local\anaconda3\Lib\site-packages\django\db\models\fields\__init__.py", line 2130, in get_prep_value
    raise e.__class__(
ValueError: Field 'input_token' expected a number but got ''.
2025-06-28 12:12:07,233 | ERROR    | ImageApp1.views | post                 | Line 579  | Error while processing document.
Traceback (most recent call last):
  File "C:\Users\pooja.akolkar\AppData\Local\anaconda3\Lib\site-packages\django\db\models\fields\__init__.py", line 2128, in get_prep_value
    return int(value)
           ^^^^^^^^^^
ValueError: invalid literal for int() with base 10: ''

The above exception was the direct cause of the following exception:

Traceback (most recent call last):
  File "D:\IDP_Project\ImageExtraction\ImageApp1\views.py", line 558, in post
    doc = Document.objects.create(
          ^^^^^^^^^^^^^^^^^^^^^^^^
  File "C:\Users\pooja.akolkar\AppData\Local\anaconda3\Lib\site-packages\django\db\models\manager.py", line 87, in manager_method
    return getattr(self.get_queryset(), name)(*args, **kwargs)
           ^^^^^^^^^^^^^^^^^^^^^^^^^^^^^^^^^^^^^^^^^^^^^^^^^^^
  File "C:\Users\pooja.akolkar\AppData\Local\anaconda3\Lib\site-packages\django\db\models\query.py", line 663, in create
    obj.save(force_insert=True, using=self.db)
  File "C:\Users\pooja.akolkar\AppData\Local\anaconda3\Lib\site-packages\django\db\models\base.py", line 902, in save
    self.save_base(
  File "C:\Users\pooja.akolkar\AppData\Local\anaconda3\Lib\site-packages\django\db\models\base.py", line 1008, in save_base
    updated = self._save_table(
              ^^^^^^^^^^^^^^^^^
  File "C:\Users\pooja.akolkar\AppData\Local\anaconda3\Lib\site-packages\django\db\models\base.py", line 1169, in _save_table
    results = self._do_insert(
              ^^^^^^^^^^^^^^^^
  File "C:\Users\pooja.akolkar\AppData\Local\anaconda3\Lib\site-packages\django\db\models\base.py", line 1210, in _do_insert
    return manager._insert(
           ^^^^^^^^^^^^^^^^
  File "C:\Users\pooja.akolkar\AppData\Local\anaconda3\Lib\site-packages\django\db\models\manager.py", line 87, in manager_method
    return getattr(self.get_queryset(), name)(*args, **kwargs)
           ^^^^^^^^^^^^^^^^^^^^^^^^^^^^^^^^^^^^^^^^^^^^^^^^^^^
  File "C:\Users\pooja.akolkar\AppData\Local\anaconda3\Lib\site-packages\django\db\models\query.py", line 1868, in _insert
    return query.get_compiler(using=using).execute_sql(returning_fields)
           ^^^^^^^^^^^^^^^^^^^^^^^^^^^^^^^^^^^^^^^^^^^^^^^^^^^^^^^^^^^^^
  File "C:\Users\pooja.akolkar\AppData\Local\anaconda3\Lib\site-packages\django\db\models\sql\compiler.py", line 1881, in execute_sql
    for sql, params in self.as_sql():
                       ^^^^^^^^^^^^^
  File "C:\Users\pooja.akolkar\AppData\Local\anaconda3\Lib\site-packages\django\db\models\sql\compiler.py", line 1806, in as_sql
    self.prepare_value(field, self.pre_save_val(field, obj))
  File "C:\Users\pooja.akolkar\AppData\Local\anaconda3\Lib\site-packages\django\db\models\sql\compiler.py", line 1741, in prepare_value
    return field.get_db_prep_save(value, connection=self.connection)
           ^^^^^^^^^^^^^^^^^^^^^^^^^^^^^^^^^^^^^^^^^^^^^^^^^^^^^^^^^
  File "C:\Users\pooja.akolkar\AppData\Local\anaconda3\Lib\site-packages\django\db\models\fields\__init__.py", line 1012, in get_db_prep_save
    return self.get_db_prep_value(value, connection=connection, prepared=False)
           ^^^^^^^^^^^^^^^^^^^^^^^^^^^^^^^^^^^^^^^^^^^^^^^^^^^^^^^^^^^^^^^^^^^^
  File "C:\Users\pooja.akolkar\AppData\Local\anaconda3\Lib\site-packages\django\db\models\fields\__init__.py", line 2135, in get_db_prep_value
    value = super().get_db_prep_value(value, connection, prepared)
            ^^^^^^^^^^^^^^^^^^^^^^^^^^^^^^^^^^^^^^^^^^^^^^^^^^^^^^
  File "C:\Users\pooja.akolkar\AppData\Local\anaconda3\Lib\site-packages\django\db\models\fields\__init__.py", line 1005, in get_db_prep_value
    value = self.get_prep_value(value)
            ^^^^^^^^^^^^^^^^^^^^^^^^^^
  File "C:\Users\pooja.akolkar\AppData\Local\anaconda3\Lib\site-packages\django\db\models\fields\__init__.py", line 2130, in get_prep_value
    raise e.__class__(
ValueError: Field 'input_token' expected a number but got ''.
2025-06-28 12:12:07,240 | ERROR    | ImageApp1.views | log_exception        | Line 71   | Exception occurred in D:\IDP_Project\ImageExtraction\ImageApp1\views.py, line 558: doc = Document.objects.create(
2025-06-28 12:12:07,240 | ERROR    | ImageApp1.views | log_exception        | Line 71   | Exception occurred in C:\Users\pooja.akolkar\AppData\Local\anaconda3\Lib\site-packages\django\db\models\manager.py, line 87: return getattr(self.get_queryset(), name)(*args, **kwargs)
2025-06-28 12:12:07,241 | ERROR    | ImageApp1.views | log_exception        | Line 71   | Exception occurred in C:\Users\pooja.akolkar\AppData\Local\anaconda3\Lib\site-packages\django\db\models\query.py, line 663: obj.save(force_insert=True, using=self.db)
2025-06-28 12:12:07,243 | ERROR    | ImageApp1.views | log_exception        | Line 71   | Exception occurred in C:\Users\pooja.akolkar\AppData\Local\anaconda3\Lib\site-packages\django\db\models\base.py, line 902: self.save_base(
2025-06-28 12:12:07,244 | ERROR    | ImageApp1.views | log_exception        | Line 71   | Exception occurred in C:\Users\pooja.akolkar\AppData\Local\anaconda3\Lib\site-packages\django\db\models\base.py, line 1008: updated = self._save_table(
2025-06-28 12:12:07,245 | ERROR    | ImageApp1.views | log_exception        | Line 71   | Exception occurred in C:\Users\pooja.akolkar\AppData\Local\anaconda3\Lib\site-packages\django\db\models\base.py, line 1169: results = self._do_insert(
2025-06-28 12:12:07,246 | ERROR    | ImageApp1.views | log_exception        | Line 71   | Exception occurred in C:\Users\pooja.akolkar\AppData\Local\anaconda3\Lib\site-packages\django\db\models\base.py, line 1210: return manager._insert(
2025-06-28 12:12:07,246 | ERROR    | ImageApp1.views | log_exception        | Line 71   | Exception occurred in C:\Users\pooja.akolkar\AppData\Local\anaconda3\Lib\site-packages\django\db\models\manager.py, line 87: return getattr(self.get_queryset(), name)(*args, **kwargs)
2025-06-28 12:12:07,247 | ERROR    | ImageApp1.views | log_exception        | Line 71   | Exception occurred in C:\Users\pooja.akolkar\AppData\Local\anaconda3\Lib\site-packages\django\db\models\query.py, line 1868: return query.get_compiler(using=using).execute_sql(returning_fields)
2025-06-28 12:12:07,247 | ERROR    | ImageApp1.views | log_exception        | Line 71   | Exception occurred in C:\Users\pooja.akolkar\AppData\Local\anaconda3\Lib\site-packages\django\db\models\sql\compiler.py, line 1881: for sql, params in self.as_sql():
2025-06-28 12:12:07,248 | ERROR    | ImageApp1.views | log_exception        | Line 71   | Exception occurred in C:\Users\pooja.akolkar\AppData\Local\anaconda3\Lib\site-packages\django\db\models\sql\compiler.py, line 1806: self.prepare_value(field, self.pre_save_val(field, obj))
2025-06-28 12:12:07,249 | ERROR    | ImageApp1.views | log_exception        | Line 71   | Exception occurred in C:\Users\pooja.akolkar\AppData\Local\anaconda3\Lib\site-packages\django\db\models\sql\compiler.py, line 1741: return field.get_db_prep_save(value, connection=self.connection)
2025-06-28 12:12:07,249 | ERROR    | ImageApp1.views | log_exception        | Line 71   | Exception occurred in C:\Users\pooja.akolkar\AppData\Local\anaconda3\Lib\site-packages\django\db\models\fields\__init__.py, line 1012: return self.get_db_prep_value(value, connection=connection, prepared=False)
2025-06-28 12:12:07,250 | ERROR    | ImageApp1.views | log_exception        | Line 71   | Exception occurred in C:\Users\pooja.akolkar\AppData\Local\anaconda3\Lib\site-packages\django\db\models\fields\__init__.py, line 2135: value = super().get_db_prep_value(value, connection, prepared)
2025-06-28 12:12:07,252 | ERROR    | ImageApp1.views | log_exception        | Line 71   | Exception occurred in C:\Users\pooja.akolkar\AppData\Local\anaconda3\Lib\site-packages\django\db\models\fields\__init__.py, line 1005: value = self.get_prep_value(value)
2025-06-28 12:12:07,253 | ERROR    | ImageApp1.views | log_exception        | Line 71   | Exception occurred in C:\Users\pooja.akolkar\AppData\Local\anaconda3\Lib\site-packages\django\db\models\fields\__init__.py, line 2130: raise e.__class__(
2025-06-28 12:12:07,260 | ERROR    |  django.request | log_response         | Line 253  | Internal Server Error: /IDA/upload/
2025-06-28 12:18:21,748 | INFO     | django.utils.autoreload | run_with_reloader    | Line 667  | Watching for file changes with StatReloader
2025-06-28 12:18:29,216 | DEBUG    | google.cloud.storage._opentelemetry_tracing | <module>             | Line 42   | This service is instrumented using OpenTelemetry. OpenTelemetry or one of its components could not be imported; please add compatible versions of opentelemetry-api and opentelemetry-instrumentation packages in order to get Storage Tracing data.
2025-06-28 12:19:55,416 | WARNING  |  django.request | log_response         | Line 253  | Unauthorized: /IDA/upload/
2025-06-28 12:20:01,152 | INFO     | authentication.views | post                 | Line 96   | Login attempt received.
2025-06-28 12:20:02,463 | INFO     | authentication.views | post                 | Line 113  | Login successful for user: abc
2025-06-28 12:20:15,436 | WARNING  |  django.request | log_response         | Line 253  | Unauthorized: /IDA/upload/
2025-06-28 12:20:29,461 | INFO     | ImageApp1.views | post                 | Line 317  | Upload request received
2025-06-28 12:21:02,567 | INFO     | ImageApp1.views | post                 | Line 457  | Usage metadata not available in the response.
2025-06-28 12:21:50,954 | INFO     | ImageApp1.views | post                 | Line 575  | Document processed and saved successfully. Document ID: gAAAAABoX5EGa95O1CREXHWv1CcXCtuvARKxK4PSHRHctaJ_8M_5hGf2oTzE5dhNDnRelbKLhWfCNcnWJUwxpu18ZzfHAcxZmw==
2025-06-28 12:22:32,973 | WARNING  |  django.request | log_response         | Line 253  | Unauthorized: /IDA/get-document/gAAAAABoX5EGa95O1CREXHWv1CcXCtuvARKxK4PSHRHctaJ_8M_5hGf2oTzE5dhNDnRelbKLhWfCNcnWJUwxpu18ZzfHAcxZmw==/
2025-06-28 12:22:50,731 | INFO     | ImageApp1.views | get                  | Line 106  | GetDocumentByIdView called with encrypted ID: gAAAAABoX5EGa95O1CREXHWv1CcXCtuvARKxK4PSHRHctaJ_8M_5hGf2oTzE5dhNDnRelbKLhWfCNcnWJUwxpu18ZzfHAcxZmw==
2025-06-28 12:22:50,732 | DEBUG    | ImageApp1.views | get                  | Line 110  | Decrypted ID: 198
2025-06-28 12:22:50,744 | INFO     | ImageApp1.views | get                  | Line 114  | Document 198 retrieved successfully
2025-06-28 12:41:40,175 | INFO     | ImageApp1.views | post                 | Line 317  | Upload request received
2025-06-28 12:30:41,724 | INFO     | django.utils.autoreload | trigger_reload       | Line 265  | D:\IDP_Project\ImageExtraction\ImageApp1\views.py changed, reloading.
2025-06-28 12:42:41,455 | INFO     | django.utils.autoreload | run_with_reloader    | Line 667  | Watching for file changes with StatReloader
2025-06-28 12:42:48,201 | DEBUG    | google.cloud.storage._opentelemetry_tracing | <module>             | Line 42   | This service is instrumented using OpenTelemetry. OpenTelemetry or one of its components could not be imported; please add compatible versions of opentelemetry-api and opentelemetry-instrumentation packages in order to get Storage Tracing data.
2025-06-28 12:42:53,724 | INFO     | ImageApp1.views | post                 | Line 317  | Upload request received
2025-06-28 12:45:32,773 | INFO     | ImageApp1.views | post                 | Line 457  | Usage metadata not available in the response.
2025-06-28 12:45:32,775 | ERROR    | ImageApp1.views | post                 | Line 460  | Input tokens is empty
NoneType: None
2025-06-28 12:48:03,534 | INFO     | django.utils.autoreload | trigger_reload       | Line 265  | D:\IDP_Project\ImageExtraction\ImageApp1\views.py changed, reloading.
2025-06-28 12:48:14,680 | INFO     | django.utils.autoreload | run_with_reloader    | Line 667  | Watching for file changes with StatReloader
2025-06-28 12:48:22,290 | DEBUG    | google.cloud.storage._opentelemetry_tracing | <module>             | Line 42   | This service is instrumented using OpenTelemetry. OpenTelemetry or one of its components could not be imported; please add compatible versions of opentelemetry-api and opentelemetry-instrumentation packages in order to get Storage Tracing data.
2025-06-28 12:49:43,617 | INFO     | ImageApp1.views | post                 | Line 317  | Upload request received
2025-06-28 12:56:46,517 | INFO     | django.utils.autoreload | trigger_reload       | Line 265  | D:\IDP_Project\ImageExtraction\ImageApp1\views.py changed, reloading.
2025-06-28 12:57:18,702 | INFO     | django.utils.autoreload | run_with_reloader    | Line 667  | Watching for file changes with StatReloader
2025-06-28 12:57:25,929 | DEBUG    | google.cloud.storage._opentelemetry_tracing | <module>             | Line 42   | This service is instrumented using OpenTelemetry. OpenTelemetry or one of its components could not be imported; please add compatible versions of opentelemetry-api and opentelemetry-instrumentation packages in order to get Storage Tracing data.
2025-06-28 12:57:53,228 | WARNING  |  django.request | log_response         | Line 253  | Unauthorized: /IDA/upload/
2025-06-28 13:00:13,739 | INFO     | authentication.views | post                 | Line 96   | Login attempt received.
2025-06-28 13:00:14,955 | INFO     | authentication.views | post                 | Line 113  | Login successful for user: abc
2025-06-28 13:00:25,633 | INFO     | ImageApp1.views | post                 | Line 308  | Upload request received
2025-06-28 13:02:02,892 | ERROR    | ImageApp1.views | post                 | Line 405  | Error processing API response for JSON extraction: API request failed after 5 retries: 400 Invalid Endpoint name: projects/vdxexccenter/locations/us-central1/publishers/google/models/gemini-1.5-Flash.
Traceback (most recent call last):
  File "C:\Users\pooja.akolkar\AppData\Local\anaconda3\Lib\site-packages\google\api_core\grpc_helpers.py", line 76, in error_remapped_callable
    return callable_(*args, **kwargs)
           ^^^^^^^^^^^^^^^^^^^^^^^^^^
  File "C:\Users\pooja.akolkar\AppData\Local\anaconda3\Lib\site-packages\grpc\_channel.py", line 1181, in __call__
    return _end_unary_response_blocking(state, call, False, None)
           ^^^^^^^^^^^^^^^^^^^^^^^^^^^^^^^^^^^^^^^^^^^^^^^^^^^^^^
  File "C:\Users\pooja.akolkar\AppData\Local\anaconda3\Lib\site-packages\grpc\_channel.py", line 1006, in _end_unary_response_blocking
    raise _InactiveRpcError(state)  # pytype: disable=not-instantiable
    ^^^^^^^^^^^^^^^^^^^^^^^^^^^^^^
grpc._channel._InactiveRpcError: <_InactiveRpcError of RPC that terminated with:
	status = StatusCode.INVALID_ARGUMENT
	details = "Invalid Endpoint name: projects/vdxexccenter/locations/us-central1/publishers/google/models/gemini-1.5-Flash."
	debug_error_string = "UNKNOWN:Error received from peer ipv6:%5B2404:6800:4009:80b::200a%5D:443 {created_time:"2025-06-28T07:32:02.8484555+00:00", grpc_status:3, grpc_message:"Invalid Endpoint name: projects/vdxexccenter/locations/us-central1/publishers/google/models/gemini-1.5-Flash."}"
>

The above exception was the direct cause of the following exception:

Traceback (most recent call last):
  File "D:\IDP_Project\ImageExtraction\ImageApp1\vertex_model.py", line 163, in call_gemini_api
    response = model.generate_content(
               ^^^^^^^^^^^^^^^^^^^^^^^
  File "C:\Users\pooja.akolkar\AppData\Local\anaconda3\Lib\site-packages\vertexai\generative_models\_generative_models.py", line 654, in generate_content
    return self._generate_content(
           ^^^^^^^^^^^^^^^^^^^^^^^
  File "C:\Users\pooja.akolkar\AppData\Local\anaconda3\Lib\site-packages\vertexai\generative_models\_generative_models.py", line 779, in _generate_content
    gapic_response = self._prediction_client.generate_content(request=request)
                     ^^^^^^^^^^^^^^^^^^^^^^^^^^^^^^^^^^^^^^^^^^^^^^^^^^^^^^^^^
  File "C:\Users\pooja.akolkar\AppData\Local\anaconda3\Lib\site-packages\google\cloud\aiplatform_v1\services\prediction_service\client.py", line 2159, in generate_content
    response = rpc(
               ^^^^
  File "C:\Users\pooja.akolkar\AppData\Local\anaconda3\Lib\site-packages\google\api_core\gapic_v1\method.py", line 131, in __call__
    return wrapped_func(*args, **kwargs)
           ^^^^^^^^^^^^^^^^^^^^^^^^^^^^^
  File "C:\Users\pooja.akolkar\AppData\Local\anaconda3\Lib\site-packages\google\api_core\grpc_helpers.py", line 78, in error_remapped_callable
    raise exceptions.from_grpc_error(exc) from exc
google.api_core.exceptions.InvalidArgument: 400 Invalid Endpoint name: projects/vdxexccenter/locations/us-central1/publishers/google/models/gemini-1.5-Flash.

During handling of the above exception, another exception occurred:

Traceback (most recent call last):
  File "D:\IDP_Project\ImageExtraction\ImageApp1\views.py", line 373, in post
    response = call_gemini_api(
               ^^^^^^^^^^^^^^^^
  File "D:\IDP_Project\ImageExtraction\ImageApp1\vertex_model.py", line 242, in call_gemini_api
    raise Exception(f"API request failed after {max_retries} retries: {str(e)}")
Exception: API request failed after 5 retries: 400 Invalid Endpoint name: projects/vdxexccenter/locations/us-central1/publishers/google/models/gemini-1.5-Flash.
2025-06-28 13:02:08,835 | ERROR    |  django.request | log_response         | Line 253  | Internal Server Error: /IDA/upload/
2025-06-28 13:03:36,838 | INFO     | django.utils.autoreload | trigger_reload       | Line 265  | D:\IDP_Project\ImageExtraction\ImageApp1\views.py changed, reloading.
2025-06-28 13:03:40,508 | INFO     | django.utils.autoreload | run_with_reloader    | Line 667  | Watching for file changes with StatReloader
2025-06-28 13:04:35,336 | DEBUG    | google.cloud.storage._opentelemetry_tracing | <module>             | Line 42   | This service is instrumented using OpenTelemetry. OpenTelemetry or one of its components could not be imported; please add compatible versions of opentelemetry-api and opentelemetry-instrumentation packages in order to get Storage Tracing data.
2025-06-28 13:04:51,500 | INFO     | ImageApp1.views | post                 | Line 308  | Upload request received
2025-06-28 13:22:37,340 | INFO     | django.utils.autoreload | run_with_reloader    | Line 667  | Watching for file changes with StatReloader
2025-06-28 13:22:49,890 | DEBUG    | google.cloud.storage._opentelemetry_tracing | <module>             | Line 42   | This service is instrumented using OpenTelemetry. OpenTelemetry or one of its components could not be imported; please add compatible versions of opentelemetry-api and opentelemetry-instrumentation packages in order to get Storage Tracing data.
2025-06-28 13:22:56,072 | INFO     | ImageApp1.views | post                 | Line 323  | Upload request received
2025-06-28 13:23:39,876 | ERROR    | ImageApp1.views | post                 | Line 425  | Error during JSON extraction API call: API request failed after 5 retries: 400 Invalid Endpoint name: projects/vdxexccenter/locations/us-central1/publishers/google/models/gemini-1.5-Flash.
Traceback (most recent call last):
  File "C:\Users\pooja.akolkar\AppData\Local\anaconda3\Lib\site-packages\google\api_core\grpc_helpers.py", line 76, in error_remapped_callable
    return callable_(*args, **kwargs)
           ^^^^^^^^^^^^^^^^^^^^^^^^^^
  File "C:\Users\pooja.akolkar\AppData\Local\anaconda3\Lib\site-packages\grpc\_channel.py", line 1181, in __call__
    return _end_unary_response_blocking(state, call, False, None)
           ^^^^^^^^^^^^^^^^^^^^^^^^^^^^^^^^^^^^^^^^^^^^^^^^^^^^^^
  File "C:\Users\pooja.akolkar\AppData\Local\anaconda3\Lib\site-packages\grpc\_channel.py", line 1006, in _end_unary_response_blocking
    raise _InactiveRpcError(state)  # pytype: disable=not-instantiable
    ^^^^^^^^^^^^^^^^^^^^^^^^^^^^^^
grpc._channel._InactiveRpcError: <_InactiveRpcError of RPC that terminated with:
	status = StatusCode.INVALID_ARGUMENT
	details = "Invalid Endpoint name: projects/vdxexccenter/locations/us-central1/publishers/google/models/gemini-1.5-Flash."
	debug_error_string = "UNKNOWN:Error received from peer ipv6:%5B2404:6800:4009:813::200a%5D:443 {created_time:"2025-06-28T07:53:39.7770657+00:00", grpc_status:3, grpc_message:"Invalid Endpoint name: projects/vdxexccenter/locations/us-central1/publishers/google/models/gemini-1.5-Flash."}"
>

The above exception was the direct cause of the following exception:

Traceback (most recent call last):
  File "D:\IDP_Project\ImageExtraction\ImageApp1\vertex_model.py", line 163, in call_gemini_api
    response = model.generate_content(
               ^^^^^^^^^^^^^^^^^^^^^^^
  File "C:\Users\pooja.akolkar\AppData\Local\anaconda3\Lib\site-packages\vertexai\generative_models\_generative_models.py", line 654, in generate_content
    return self._generate_content(
           ^^^^^^^^^^^^^^^^^^^^^^^
  File "C:\Users\pooja.akolkar\AppData\Local\anaconda3\Lib\site-packages\vertexai\generative_models\_generative_models.py", line 779, in _generate_content
    gapic_response = self._prediction_client.generate_content(request=request)
                     ^^^^^^^^^^^^^^^^^^^^^^^^^^^^^^^^^^^^^^^^^^^^^^^^^^^^^^^^^
  File "C:\Users\pooja.akolkar\AppData\Local\anaconda3\Lib\site-packages\google\cloud\aiplatform_v1\services\prediction_service\client.py", line 2159, in generate_content
    response = rpc(
               ^^^^
  File "C:\Users\pooja.akolkar\AppData\Local\anaconda3\Lib\site-packages\google\api_core\gapic_v1\method.py", line 131, in __call__
    return wrapped_func(*args, **kwargs)
           ^^^^^^^^^^^^^^^^^^^^^^^^^^^^^
  File "C:\Users\pooja.akolkar\AppData\Local\anaconda3\Lib\site-packages\google\api_core\grpc_helpers.py", line 78, in error_remapped_callable
    raise exceptions.from_grpc_error(exc) from exc
google.api_core.exceptions.InvalidArgument: 400 Invalid Endpoint name: projects/vdxexccenter/locations/us-central1/publishers/google/models/gemini-1.5-Flash.

During handling of the above exception, another exception occurred:

Traceback (most recent call last):
  File "D:\IDP_Project\ImageExtraction\ImageApp1\views.py", line 394, in post
    response = call_gemini_api(
               ^^^^^^^^^^^^^^^^
  File "D:\IDP_Project\ImageExtraction\ImageApp1\vertex_model.py", line 242, in call_gemini_api
    raise Exception(f"API request failed after {max_retries} retries: {str(e)}")
Exception: API request failed after 5 retries: 400 Invalid Endpoint name: projects/vdxexccenter/locations/us-central1/publishers/google/models/gemini-1.5-Flash.
2025-06-28 13:23:39,909 | ERROR    |  django.request | log_response         | Line 253  | Internal Server Error: /IDA/upload/
2025-06-28 13:25:27,922 | INFO     | ImageApp1.views | post                 | Line 323  | Upload request received
2025-06-28 13:26:11,144 | ERROR    | ImageApp1.views | post                 | Line 425  | Error during JSON extraction API call: API request failed after 5 retries: 400 Invalid Endpoint name: projects/vdxexccenter/locations/us-central1/publishers/google/models/gemini-1.5-Flash.
Traceback (most recent call last):
  File "C:\Users\pooja.akolkar\AppData\Local\anaconda3\Lib\site-packages\google\api_core\grpc_helpers.py", line 76, in error_remapped_callable
    return callable_(*args, **kwargs)
           ^^^^^^^^^^^^^^^^^^^^^^^^^^
  File "C:\Users\pooja.akolkar\AppData\Local\anaconda3\Lib\site-packages\grpc\_channel.py", line 1181, in __call__
    return _end_unary_response_blocking(state, call, False, None)
           ^^^^^^^^^^^^^^^^^^^^^^^^^^^^^^^^^^^^^^^^^^^^^^^^^^^^^^
  File "C:\Users\pooja.akolkar\AppData\Local\anaconda3\Lib\site-packages\grpc\_channel.py", line 1006, in _end_unary_response_blocking
    raise _InactiveRpcError(state)  # pytype: disable=not-instantiable
    ^^^^^^^^^^^^^^^^^^^^^^^^^^^^^^
grpc._channel._InactiveRpcError: <_InactiveRpcError of RPC that terminated with:
	status = StatusCode.INVALID_ARGUMENT
	details = "Invalid Endpoint name: projects/vdxexccenter/locations/us-central1/publishers/google/models/gemini-1.5-Flash."
	debug_error_string = "UNKNOWN:Error received from peer ipv6:%5B2404:6800:4009:813::200a%5D:443 {grpc_message:"Invalid Endpoint name: projects/vdxexccenter/locations/us-central1/publishers/google/models/gemini-1.5-Flash.", grpc_status:3, created_time:"2025-06-28T07:56:11.1026498+00:00"}"
>

The above exception was the direct cause of the following exception:

Traceback (most recent call last):
  File "D:\IDP_Project\ImageExtraction\ImageApp1\vertex_model.py", line 163, in call_gemini_api
    response = model.generate_content(
               ^^^^^^^^^^^^^^^^^^^^^^^
  File "C:\Users\pooja.akolkar\AppData\Local\anaconda3\Lib\site-packages\vertexai\generative_models\_generative_models.py", line 654, in generate_content
    return self._generate_content(
           ^^^^^^^^^^^^^^^^^^^^^^^
  File "C:\Users\pooja.akolkar\AppData\Local\anaconda3\Lib\site-packages\vertexai\generative_models\_generative_models.py", line 779, in _generate_content
    gapic_response = self._prediction_client.generate_content(request=request)
                     ^^^^^^^^^^^^^^^^^^^^^^^^^^^^^^^^^^^^^^^^^^^^^^^^^^^^^^^^^
  File "C:\Users\pooja.akolkar\AppData\Local\anaconda3\Lib\site-packages\google\cloud\aiplatform_v1\services\prediction_service\client.py", line 2159, in generate_content
    response = rpc(
               ^^^^
  File "C:\Users\pooja.akolkar\AppData\Local\anaconda3\Lib\site-packages\google\api_core\gapic_v1\method.py", line 131, in __call__
    return wrapped_func(*args, **kwargs)
           ^^^^^^^^^^^^^^^^^^^^^^^^^^^^^
  File "C:\Users\pooja.akolkar\AppData\Local\anaconda3\Lib\site-packages\google\api_core\grpc_helpers.py", line 78, in error_remapped_callable
    raise exceptions.from_grpc_error(exc) from exc
google.api_core.exceptions.InvalidArgument: 400 Invalid Endpoint name: projects/vdxexccenter/locations/us-central1/publishers/google/models/gemini-1.5-Flash.

During handling of the above exception, another exception occurred:

Traceback (most recent call last):
  File "D:\IDP_Project\ImageExtraction\ImageApp1\views.py", line 394, in post
    response = call_gemini_api(
               ^^^^^^^^^^^^^^^^
  File "D:\IDP_Project\ImageExtraction\ImageApp1\vertex_model.py", line 242, in call_gemini_api
    raise Exception(f"API request failed after {max_retries} retries: {str(e)}")
Exception: API request failed after 5 retries: 400 Invalid Endpoint name: projects/vdxexccenter/locations/us-central1/publishers/google/models/gemini-1.5-Flash.
2025-06-28 13:26:11,149 | ERROR    |  django.request | log_response         | Line 253  | Internal Server Error: /IDA/upload/
2025-06-28 13:26:38,113 | INFO     | django.utils.autoreload | run_with_reloader    | Line 667  | Watching for file changes with StatReloader
2025-06-28 13:26:46,508 | DEBUG    | google.cloud.storage._opentelemetry_tracing | <module>             | Line 42   | This service is instrumented using OpenTelemetry. OpenTelemetry or one of its components could not be imported; please add compatible versions of opentelemetry-api and opentelemetry-instrumentation packages in order to get Storage Tracing data.
2025-06-28 13:27:01,759 | INFO     | ImageApp1.views | post                 | Line 323  | Upload request received
2025-06-28 13:27:48,233 | INFO     | ImageApp1.views | post                 | Line 323  | Upload request received
2025-06-28 13:27:59,138 | ERROR    | ImageApp1.views | post                 | Line 425  | Error during JSON extraction API call: API request failed after 5 retries: 404 Publisher Model `projects/vdxexccenter/locations/us-central1/publishers/google/models/gemini-1.5-flash` was not found or your project does not have access to it. Please ensure you are using a valid model version. For more information, see: https://cloud.google.com/vertex-ai/generative-ai/docs/learn/model-versions
Traceback (most recent call last):
  File "C:\Users\pooja.akolkar\AppData\Local\anaconda3\Lib\site-packages\google\api_core\grpc_helpers.py", line 76, in error_remapped_callable
    return callable_(*args, **kwargs)
           ^^^^^^^^^^^^^^^^^^^^^^^^^^
  File "C:\Users\pooja.akolkar\AppData\Local\anaconda3\Lib\site-packages\grpc\_channel.py", line 1181, in __call__
    return _end_unary_response_blocking(state, call, False, None)
           ^^^^^^^^^^^^^^^^^^^^^^^^^^^^^^^^^^^^^^^^^^^^^^^^^^^^^^
  File "C:\Users\pooja.akolkar\AppData\Local\anaconda3\Lib\site-packages\grpc\_channel.py", line 1006, in _end_unary_response_blocking
    raise _InactiveRpcError(state)  # pytype: disable=not-instantiable
    ^^^^^^^^^^^^^^^^^^^^^^^^^^^^^^
grpc._channel._InactiveRpcError: <_InactiveRpcError of RPC that terminated with:
	status = StatusCode.NOT_FOUND
	details = "Publisher Model `projects/vdxexccenter/locations/us-central1/publishers/google/models/gemini-1.5-flash` was not found or your project does not have access to it. Please ensure you are using a valid model version. For more information, see: https://cloud.google.com/vertex-ai/generative-ai/docs/learn/model-versions"
	debug_error_string = "UNKNOWN:Error received from peer ipv6:%5B2404:6800:4009:813::200a%5D:443 {created_time:"2025-06-28T07:57:55.8889055+00:00", grpc_status:5, grpc_message:"Publisher Model `projects/vdxexccenter/locations/us-central1/publishers/google/models/gemini-1.5-flash` was not found or your project does not have access to it. Please ensure you are using a valid model version. For more information, see: https://cloud.google.com/vertex-ai/generative-ai/docs/learn/model-versions"}"
>

The above exception was the direct cause of the following exception:

Traceback (most recent call last):
  File "D:\IDP_Project\ImageExtraction\ImageApp1\vertex_model.py", line 163, in call_gemini_api
    response = model.generate_content(
               ^^^^^^^^^^^^^^^^^^^^^^^
  File "C:\Users\pooja.akolkar\AppData\Local\anaconda3\Lib\site-packages\vertexai\generative_models\_generative_models.py", line 654, in generate_content
    return self._generate_content(
           ^^^^^^^^^^^^^^^^^^^^^^^
  File "C:\Users\pooja.akolkar\AppData\Local\anaconda3\Lib\site-packages\vertexai\generative_models\_generative_models.py", line 779, in _generate_content
    gapic_response = self._prediction_client.generate_content(request=request)
                     ^^^^^^^^^^^^^^^^^^^^^^^^^^^^^^^^^^^^^^^^^^^^^^^^^^^^^^^^^
  File "C:\Users\pooja.akolkar\AppData\Local\anaconda3\Lib\site-packages\google\cloud\aiplatform_v1\services\prediction_service\client.py", line 2159, in generate_content
    response = rpc(
               ^^^^
  File "C:\Users\pooja.akolkar\AppData\Local\anaconda3\Lib\site-packages\google\api_core\gapic_v1\method.py", line 131, in __call__
    return wrapped_func(*args, **kwargs)
           ^^^^^^^^^^^^^^^^^^^^^^^^^^^^^
  File "C:\Users\pooja.akolkar\AppData\Local\anaconda3\Lib\site-packages\google\api_core\grpc_helpers.py", line 78, in error_remapped_callable
    raise exceptions.from_grpc_error(exc) from exc
google.api_core.exceptions.NotFound: 404 Publisher Model `projects/vdxexccenter/locations/us-central1/publishers/google/models/gemini-1.5-flash` was not found or your project does not have access to it. Please ensure you are using a valid model version. For more information, see: https://cloud.google.com/vertex-ai/generative-ai/docs/learn/model-versions

During handling of the above exception, another exception occurred:

Traceback (most recent call last):
  File "D:\IDP_Project\ImageExtraction\ImageApp1\views.py", line 394, in post
    response = call_gemini_api(
               ^^^^^^^^^^^^^^^^
  File "D:\IDP_Project\ImageExtraction\ImageApp1\vertex_model.py", line 242, in call_gemini_api
    raise Exception(f"API request failed after {max_retries} retries: {str(e)}")
Exception: API request failed after 5 retries: 404 Publisher Model `projects/vdxexccenter/locations/us-central1/publishers/google/models/gemini-1.5-flash` was not found or your project does not have access to it. Please ensure you are using a valid model version. For more information, see: https://cloud.google.com/vertex-ai/generative-ai/docs/learn/model-versions
2025-06-28 13:27:59,160 | ERROR    |  django.request | log_response         | Line 253  | Internal Server Error: /IDA/upload/
2025-06-28 13:28:58,509 | ERROR    | ImageApp1.views | post                 | Line 425  | Error during JSON extraction API call: API request failed after 5 retries: 404 Publisher Model `projects/vdxexccenter/locations/us-central1/publishers/google/models/gemini-1.5-flash` was not found or your project does not have access to it. Please ensure you are using a valid model version. For more information, see: https://cloud.google.com/vertex-ai/generative-ai/docs/learn/model-versions
Traceback (most recent call last):
  File "C:\Users\pooja.akolkar\AppData\Local\anaconda3\Lib\site-packages\google\api_core\grpc_helpers.py", line 76, in error_remapped_callable
    return callable_(*args, **kwargs)
           ^^^^^^^^^^^^^^^^^^^^^^^^^^
  File "C:\Users\pooja.akolkar\AppData\Local\anaconda3\Lib\site-packages\grpc\_channel.py", line 1181, in __call__
    return _end_unary_response_blocking(state, call, False, None)
           ^^^^^^^^^^^^^^^^^^^^^^^^^^^^^^^^^^^^^^^^^^^^^^^^^^^^^^
  File "C:\Users\pooja.akolkar\AppData\Local\anaconda3\Lib\site-packages\grpc\_channel.py", line 1006, in _end_unary_response_blocking
    raise _InactiveRpcError(state)  # pytype: disable=not-instantiable
    ^^^^^^^^^^^^^^^^^^^^^^^^^^^^^^
grpc._channel._InactiveRpcError: <_InactiveRpcError of RPC that terminated with:
	status = StatusCode.NOT_FOUND
	details = "Publisher Model `projects/vdxexccenter/locations/us-central1/publishers/google/models/gemini-1.5-flash` was not found or your project does not have access to it. Please ensure you are using a valid model version. For more information, see: https://cloud.google.com/vertex-ai/generative-ai/docs/learn/model-versions"
	debug_error_string = "UNKNOWN:Error received from peer ipv6:%5B2404:6800:4009:813::200a%5D:443 {grpc_message:"Publisher Model `projects/vdxexccenter/locations/us-central1/publishers/google/models/gemini-1.5-flash` was not found or your project does not have access to it. Please ensure you are using a valid model version. For more information, see: https://cloud.google.com/vertex-ai/generative-ai/docs/learn/model-versions", grpc_status:5, created_time:"2025-06-28T07:58:58.4501056+00:00"}"
>

The above exception was the direct cause of the following exception:

Traceback (most recent call last):
  File "D:\IDP_Project\ImageExtraction\ImageApp1\vertex_model.py", line 163, in call_gemini_api
    response = model.generate_content(
               ^^^^^^^^^^^^^^^^^^^^^^^
  File "C:\Users\pooja.akolkar\AppData\Local\anaconda3\Lib\site-packages\vertexai\generative_models\_generative_models.py", line 654, in generate_content
    return self._generate_content(
           ^^^^^^^^^^^^^^^^^^^^^^^
  File "C:\Users\pooja.akolkar\AppData\Local\anaconda3\Lib\site-packages\vertexai\generative_models\_generative_models.py", line 779, in _generate_content
    gapic_response = self._prediction_client.generate_content(request=request)
                     ^^^^^^^^^^^^^^^^^^^^^^^^^^^^^^^^^^^^^^^^^^^^^^^^^^^^^^^^^
  File "C:\Users\pooja.akolkar\AppData\Local\anaconda3\Lib\site-packages\google\cloud\aiplatform_v1\services\prediction_service\client.py", line 2159, in generate_content
    response = rpc(
               ^^^^
  File "C:\Users\pooja.akolkar\AppData\Local\anaconda3\Lib\site-packages\google\api_core\gapic_v1\method.py", line 131, in __call__
    return wrapped_func(*args, **kwargs)
           ^^^^^^^^^^^^^^^^^^^^^^^^^^^^^
  File "C:\Users\pooja.akolkar\AppData\Local\anaconda3\Lib\site-packages\google\api_core\grpc_helpers.py", line 78, in error_remapped_callable
    raise exceptions.from_grpc_error(exc) from exc
google.api_core.exceptions.NotFound: 404 Publisher Model `projects/vdxexccenter/locations/us-central1/publishers/google/models/gemini-1.5-flash` was not found or your project does not have access to it. Please ensure you are using a valid model version. For more information, see: https://cloud.google.com/vertex-ai/generative-ai/docs/learn/model-versions

During handling of the above exception, another exception occurred:

Traceback (most recent call last):
  File "D:\IDP_Project\ImageExtraction\ImageApp1\views.py", line 394, in post
    response = call_gemini_api(
               ^^^^^^^^^^^^^^^^
  File "D:\IDP_Project\ImageExtraction\ImageApp1\vertex_model.py", line 242, in call_gemini_api
    raise Exception(f"API request failed after {max_retries} retries: {str(e)}")
Exception: API request failed after 5 retries: 404 Publisher Model `projects/vdxexccenter/locations/us-central1/publishers/google/models/gemini-1.5-flash` was not found or your project does not have access to it. Please ensure you are using a valid model version. For more information, see: https://cloud.google.com/vertex-ai/generative-ai/docs/learn/model-versions
2025-06-28 13:28:58,513 | ERROR    |  django.request | log_response         | Line 253  | Internal Server Error: /IDA/upload/
2025-06-28 13:29:38,165 | INFO     | django.utils.autoreload | run_with_reloader    | Line 667  | Watching for file changes with StatReloader
2025-06-28 13:31:16,216 | INFO     | django.utils.autoreload | run_with_reloader    | Line 667  | Watching for file changes with StatReloader
2025-06-28 13:31:40,610 | DEBUG    | google.cloud.storage._opentelemetry_tracing | <module>             | Line 42   | This service is instrumented using OpenTelemetry. OpenTelemetry or one of its components could not be imported; please add compatible versions of opentelemetry-api and opentelemetry-instrumentation packages in order to get Storage Tracing data.
2025-06-28 13:31:51,047 | WARNING  |  django.request | log_response         | Line 253  | Unauthorized: /IDA/upload/
2025-06-28 13:31:58,653 | INFO     | authentication.views | post                 | Line 96   | Login attempt received.
2025-06-28 13:32:02,993 | INFO     | authentication.views | post                 | Line 113  | Login successful for user: abc
2025-06-28 13:32:15,680 | INFO     | ImageApp1.views | post                 | Line 323  | Upload request received
2025-06-28 13:32:40,550 | INFO     | ImageApp1.views | post                 | Line 435  | JSON Extraction - Usage metadata not available in the response.
2025-06-28 13:33:10,152 | INFO     | ImageApp1.views | post                 | Line 484  | Document processed and saved successfully. Document ID: gAAAAABoX6G-HjPzH9pCFtwTwY01oEQcd5cUM7Urs0mDWyI2yA5SxaTXrHLGRjCcnWPWr60FYAq752ztKb0S5OSgwS55ogIDfA==
2025-06-28 13:34:29,008 | WARNING  |  django.request | log_response         | Line 253  | Unauthorized: /IDA/get-document/gAAAAABoX6G-HjPzH9pCFtwTwY01oEQcd5cUM7Urs0mDWyI2yA5SxaTXrHLGRjCcnWPWr60FYAq752ztKb0S5OSgwS55ogIDfA==/
2025-06-28 13:34:48,144 | INFO     | ImageApp1.views | get                  | Line 144  | GetDocumentByIdView called with encrypted ID: gAAAAABoX6G-HjPzH9pCFtwTwY01oEQcd5cUM7Urs0mDWyI2yA5SxaTXrHLGRjCcnWPWr60FYAq752ztKb0S5OSgwS55ogIDfA==
2025-06-28 13:34:48,146 | DEBUG    | ImageApp1.views | get                  | Line 148  | Decrypted ID: 199
2025-06-28 13:34:48,218 | INFO     | ImageApp1.views | get                  | Line 152  | Document 199 retrieved successfully
2025-06-28 13:38:01,293 | INFO     | django.utils.autoreload | trigger_reload       | Line 265  | D:\IDP_Project\ImageExtraction\ImageApp1\vertex_model.py changed, reloading.
2025-06-28 13:38:17,329 | INFO     | django.utils.autoreload | run_with_reloader    | Line 667  | Watching for file changes with StatReloader
2025-06-28 13:38:51,114 | DEBUG    | google.cloud.storage._opentelemetry_tracing | <module>             | Line 42   | This service is instrumented using OpenTelemetry. OpenTelemetry or one of its components could not be imported; please add compatible versions of opentelemetry-api and opentelemetry-instrumentation packages in order to get Storage Tracing data.
2025-06-28 13:39:10,688 | INFO     | ImageApp1.views | post                 | Line 323  | Upload request received
2025-06-28 13:40:45,195 | INFO     | ImageApp1.views | post                 | Line 433  | JSON Extraction - Input Tokens: 1361, Output Tokens: 618
2025-06-28 13:41:19,273 | INFO     | ImageApp1.views | post                 | Line 484  | Document processed and saved successfully. Document ID: gAAAAABoX6OnJQpHvPaunNhNGMGui6w7dW6EBgendjjrpbcMjGCuk--uGrLTClWZLEkTx3lC-JF8saVUGKtRpfX-kIQnXDPQgw==
2025-06-28 13:43:54,939 | INFO     | django.utils.autoreload | trigger_reload       | Line 265  | D:\IDP_Project\ImageExtraction\ImageExtraction\logger.py changed, reloading.
2025-06-28 13:51:10 - django.utils.autoreload - INFO - Watching for file changes with StatReloader
2025-06-28 13:51:43 - ImageApp1.views - INFO - Upload request received
2025-06-28 13:52:04 - ImageApp1.views - DEBUG - Raw JSON API response: ```json
{
  "merchant_name": "M.N.S. ಶಾಮಿಯಾನ ಹೌಸ್ ಅಂಡ್ ಫ್ಲವರ್ ಡೆಕೋರೇಟರ್ಸ್",
  "merchant_address": "ಮಾಡಿಕೆರೆ ಕ್ರಾಸ್, ಊಲವಾಡಿ ಪಂಚಾಯ್ತಿ, ಚಿಂತಾಮಣಿ ತಾಲ್ಲೂಕು, ಚಿಕ್ಕಬಳ್ಳಾಪುರ ಜಿಲ್ಲೆ.",
  "merchant_phone": "9902711519",
  "alternate_phone": "9743917615",
  "customer_name": "ASHOKA. K.V.",
  "customer_organization": "Malyco Pvt Ltd",
  "invoice_number": "51",
  "invoice_date": "2021-12-22",
  "line_items": [
    {
      "item_code": 32,
      "description": "20x20",
      "quantity": 2,
      "unit_price": 1500,
      "amount": 3000
    },
    {
      "item_code": 38,
      "description": "ಚೇರ್",
      "quantity": 150,
      "unit_price": 10,
      "amount": 1500
    },
    {
      "item_code": 39,
      "description": "ಸೈಡ್ ವಾಲ್",
      "quantity": 6,
      "unit_price": 500,
      "amount": 3000
    },
    {
      "item_code": 42,
      "description": "ನೀರಿನ ಡ್ರಮ್",
      "quantity": 2,
      "unit_price": 200,
      "amount": 400
    },
    {
      "item_code": 44,
      "description": "ಸ್ಟೀನ್ ಬಟ್ಟೆ",
      "quantity": null,
      "unit_price": 300,
      "amount": 300
    },
    {
      "item_code": 60,
      "description": "ಬಾಡಿಗೆ",
      "quantity": 1,
      "unit_price": 1800,
      "amount": 1800
    }
  ],
  "total_amount": 10000.0,
  "advance": null,
  "balance_due": 10000.0,
  "currency": null
}
```
2025-06-28 13:52:04 - ImageApp1.views - INFO - JSON Extraction - Input Tokens: 1361, Output Tokens: 625
2025-06-28 13:52:41 - ImageApp1.views - DEBUG - Raw HTML API response: <!DOCTYPE html>
<html lang="en">
<head>
    <meta charset="UTF-8">
    <title>Invoice #51</title>
    <style>
        @import url('https://fonts.googleapis.com/css2?family=Noto+Sans&family=Noto+Sans+Kannada&display=swap');
        
        body {
            font-family: 'Noto Sans', 'Noto Sans Kannada', sans-serif;
            margin: 0;
            padding: 20px;
            background-color: #f4f4f4;
            color: #333;
        }
        .container {
            max-width: 850px;
            margin: 0 auto;
            background: #fff;
            padding: 30px;
            box-shadow: 0 4px 8px rgba(0,0,0,0.1);
            border-radius: 8px;
        }
        .header {
            display: flex;
            justify-content: space-between;
            align-items: flex-start;
            border-bottom: 2px solid #eee;
            padding-bottom: 20px;
            margin-bottom: 20px;
        }
        .merchant-details {
            max-width: 60%;
        }
        .merchant-details h2 {
            margin: 0 0 10px 0;
            font-size: 1.5em;
            color: #0056b3;
        }
        .merchant-details p {
            margin: 4px 0;
            font-size: 0.9em;
            color: #555;
            line-height: 1.4;
        }
        .invoice-info {
            text-align: right;
        }
        .invoice-info h1 {
            margin: 0;
            color: #333;
            text-transform: uppercase;
            font-size: 2.2em;
        }
        .invoice-info p {
            margin: 5px 0;
            font-size: 1em;
        }
        .customer-details {
            margin-bottom: 30px;
        }
        .customer-details h3 {
            margin-bottom: 10px;
            border-bottom: 1px solid #ddd;
            padding-bottom: 5px;
            font-size: 1.1em;
            color: #444;
        }
        .customer-details p {
            margin: 2px 0;
            font-size: 1em;
        }
        .items-table {
            width: 100%;
            border-collapse: collapse;
            margin-bottom: 30px;
        }
        .items-table th, .items-table td {
            border: 1px solid #ddd;
            padding: 12px;
            text-align: left;
        }
        .items-table thead {
            background-color: #0056b3;
            color: #ffffff;
        }
        .items-table th {
            font-weight: bold;
        }
        .items-table tbody tr:nth-child(even) {
            background-color: #f9f9f9;
        }
        .text-right {
            text-align: right;
        }
        .text-center {
            text-align: center;
        }
        .null-value {
            color: #999;
            font-style: italic;
        }
        .totals-section {
            display: flex;
            justify-content: flex-end;
        }
        .totals-table {
            width: 45%;
            border-collapse: collapse;
        }
        .totals-table td {
            padding: 10px 12px;
            font-size: 1.1em;
        }
        .totals-table tr.total-due td {
            font-weight: bold;
            font-size: 1.3em;
            color: #0056b3;
            border-top: 2px solid #0056b3;
        }
        .totals-label {
            text-align: right;
            font-weight: bold;
            color: #555;
        }
        .totals-value {
            text-align: right;
        }
    </style>
</head>
<body>
    <div class="container">
        <div class="header">
            <div class="merchant-details">
                <h2>M.N.S. ಶಾಮಿಯಾನ ಹೌಸ್ ಅಂಡ್ ಫ್ಲವರ್ ಡೆಕೋರೇಟರ್ಸ್</h2>
                <p>ಮಾಡಿಕೆರೆ ಕ್ರಾಸ್, ಊಲವಾಡಿ ಪಂಚಾಯ್ತಿ, ಚಿಂತಾಮಣಿ ತಾಲ್ಲೂಕು, ಚಿಕ್ಕಬಳ್ಳಾಪುರ ಜಿಲ್ಲೆ.</p>
                <p>Phone: 9902711519, 9743917615</p>
            </div>
            <div class="invoice-info">
                <h1>Invoice</h1>
                <p><strong>Invoice #:</strong> 51</p>
                <p><strong>Date:</strong> 2021-12-22</p>
            </div>
        </div>

        <div class="customer-details">
            <h3>Bill To</h3>
            <p><strong>Customer:</strong> ASHOKA. K.V.</p>
            <p><strong>Organization:</strong> Malyco Pvt Ltd</p>
        </div>

        <table class="items-table">
            <thead>
                <tr>
                    <th class="text-center">Item Code</th>
                    <th>Description</th>
                    <th class="text-center">Quantity</th>
                    <th class="text-right">Unit Price</th>
                    <th class="text-right">Amount</th>
                </tr>
            </thead>
            <tbody>
                <tr>
                    <td class="text-center">32</td>
                    <td>20x20</td>
                    <td class="text-center">2</td>
                    <td class="text-right">₹1,500.00</td>
                    <td class="text-right">₹3,000.00</td>
                </tr>
                <tr>
                    <td class="text-center">38</td>
                    <td>ಚೇರ್</td>
                    <td class="text-center">150</td>
                    <td class="text-right">₹10.00</td>
                    <td class="text-right">₹1,500.00</td>
                </tr>
                <tr>
                    <td class="text-center">39</td>
                    <td>ಸೈಡ್ ವಾಲ್</td>
                    <td class="text-center">6</td>
                    <td class="text-right">₹500.00</td>
                    <td class="text-right">₹3,000.00</td>
                </tr>
                <tr>
                    <td class="text-center">42</td>
                    <td>ನೀರಿನ ಡ್ರಮ್</td>
                    <td class="text-center">2</td>
                    <td class="text-right">₹200.00</td>
                    <td class="text-right">₹400.00</td>
                </tr>
                <tr>
                    <td class="text-center">44</td>
                    <td>ಸ್ಟೀನ್ ಬಟ್ಟೆ</td>
                    <td class="text-center null-value">-</td>
                    <td class="text-right">₹300.00</td>
                    <td class="text-right">₹300.00</td>
                </tr>
                <tr>
                    <td class="text-center">60</td>
                    <td>ಬಾಡಿಗೆ</td>
                    <td class="text-center">1</td>
                    <td class="text-right">₹1,800.00</td>
                    <td class="text-right">₹1,800.00</td>
                </tr>
            </tbody>
        </table>

        <div class="totals-section">
            <table class="totals-table">
                <tbody>
                    <tr>
                        <td class="totals-label">Total</td>
                        <td class="totals-value">₹10,000.00</td>
                    </tr>
                    <tr>
                        <td class="totals-label">Advance</td>
                        <td class="totals-value">₹0.00</td>
                    </tr>
                    <tr class="total-due">
                        <td class="totals-label">Balance Due</td>
                        <td class="totals-value">₹10,000.00</td>
                    </tr>
                </tbody>
            </table>
        </div>
    </div>
</body>
</html>
2025-06-28 13:52:41 - ImageApp1.views - INFO - Document processed and saved successfully. Document ID: gAAAAABoX6ZRqK7fj0AxKCYd5APT7ckCLScHtHEyO-aGuYOxmpRE6MBXrZ-BQAG2IwA7k7gfWQ8XUoqSgk4IWY4mL9i0YgdmLA==
2025-06-28 13:57:01 - ImageApp1.views - INFO - Upload request received
2025-06-28 13:56:53 - django.utils.autoreload - INFO - D:\IDP_Project\ImageExtraction\ImageApp1\views.py changed, reloading.
2025-06-28 14:26:47 - django.request - WARNING - Unauthorized: /IDA/upload/
2025-06-28 14:32:37 - django.request - WARNING - Unauthorized: /IDA/upload/
2025-06-28 14:33:54 - django.utils.autoreload - INFO - Watching for file changes with StatReloader
2025-06-28 14:34:27 - django.utils.autoreload - INFO - Watching for file changes with StatReloader
2025-06-28 14:36:33 - authentication.views - INFO - Login attempt received.
2025-06-28 14:36:37 - authentication.views - INFO - Login successful for user: abc
2025-06-28 14:36:53 - ImageApp1.views - INFO - Upload request received
2025-06-28 14:38:41 - ImageApp1.views - INFO - JSON Extraction - Input Tokens: 2651, Output Tokens: 5948
2025-06-28 14:40:01 - ImageApp1.views - INFO - Document processed and saved successfully. Document ID: gAAAAABoX7FpvCRbZFCYYeMW13tci_JtdMMAmkgkxH7VDdxjKsGCEp3t-amF1LsG7XQDwuvMiHfSeVE2jCl070awtu-keBvq_A==
2025-06-28 14:41:09 - django.request - WARNING - Unauthorized: /IDA/get-document/gAAAAABoX7FpvCRbZFCYYeMW13tci_JtdMMAmkgkxH7VDdxjKsGCEp3t-amF1LsG7XQDwuvMiHfSeVE2jCl070awtu-keBvq_A==/
2025-06-28 14:41:33 - ImageApp1.views - INFO - GetDocumentByIdView called with encrypted ID: gAAAAABoX7FpvCRbZFCYYeMW13tci_JtdMMAmkgkxH7VDdxjKsGCEp3t-amF1LsG7XQDwuvMiHfSeVE2jCl070awtu-keBvq_A==
2025-06-28 14:41:33 - ImageApp1.views - DEBUG - Decrypted ID: 202
2025-06-28 14:41:33 - ImageApp1.views - INFO - Document 202 retrieved successfully
2025-06-28 14:44:08 - ImageApp1.views - INFO - Upload request received
2025-06-28 14:44:08 - ImageApp1.views - WARNING - No specific prompt provided for doc_type: re. Using generic prompt.
2025-06-28 14:45:31 - ImageApp1.views - INFO - JSON Extraction - Input Tokens: 785, Output Tokens: 4283
2025-06-28 14:46:29 - authentication.views - INFO - Login attempt received.
2025-06-28 14:46:34 - authentication.views - INFO - Login successful for user: abc
2025-06-28 14:46:42 - ImageApp1.views - INFO - Document processed and saved successfully. Document ID: gAAAAABoX7L6IodjpaLFJXh2klnledz_q9AtguuhvWFwQRRBSlITPmEuWDevQgyj8cFz8QyH6F32UjefVkNIktDUxvewjqGR5g==
2025-06-28 14:47:35 - django.utils.autoreload - INFO - D:\IDP_Project\ImageExtraction\ImageApp1\views.py changed, reloading.
