2025-06-27 12:11:48,584 | INFO     | django.utils.autoreload | run_with_reloader    | Line 667  | Watching for file changes with StatReloader
2025-06-27 12:13:58,810 | INFO     | django.utils.autoreload | trigger_reload       | Line 265  | D:\IDP_Project\ImageExtraction\ImageExtraction\settings.py changed, reloading.
2025-06-27 12:15:10,749 | INFO     | django.utils.autoreload | run_with_reloader    | Line 667  | Watching for file changes with StatReloader
2025-06-27 12:15:42,098 | INFO     | authentication.views | post                 | Line 99   | Login attempt received.
2025-06-27 12:15:59,314 | INFO     | authentication.views | post                 | Line 116  | Login successful for user: abc
2025-06-27 12:16:35,967 | INFO     | ImageApp1.views | post                 | Line 301  | Upload request received
2025-06-27 12:16:36,076 | DEBUG    | urllib3.connectionpool | _new_conn            | Line 1052 | Starting new HTTPS connection (1): oauth2.googleapis.com:443
2025-06-27 12:16:36,795 | DEBUG    | urllib3.connectionpool | _make_request        | Line 546  | https://oauth2.googleapis.com:443 "POST /token HTTP/1.1" 200 None
2025-06-27 12:16:36,822 | DEBUG    | urllib3.connectionpool | _new_conn            | Line 1052 | Starting new HTTPS connection (1): us-central1-aiplatform.googleapis.com:443
2025-06-27 12:16:46,698 | DEBUG    | urllib3.connectionpool | _make_request        | Line 546  | https://us-central1-aiplatform.googleapis.com:443 "POST /v1/projects/vdxexccenter/locations/us-central1/publishers/google/models/gemini-2.5-pro:generateContent HTTP/1.1" 429 None
2025-06-27 12:16:46,699 | ERROR    | ImageApp1.views | post                 | Line 530  | 500
2025-06-27 12:16:46,700 | ERROR    | ImageApp1.views | post                 | Line 531  | Error while processing document.
2025-06-27 12:16:46,705 | ERROR    | ImageApp1.views | log_exception        | Line 71   | Exception occurred in D:\IDP_Project\ImageExtraction\ImageApp1\views.py, line 456: response = call_gemini_api(
2025-06-27 12:16:46,706 | ERROR    | ImageApp1.views | log_exception        | Line 71   | Exception occurred in D:\IDP_Project\ImageExtraction\ImageApp1\vertex_model.py, line 183: raise Exception(error_msg)
2025-06-27 12:16:46,707 | ERROR    |  django.request | log_response         | Line 253  | Internal Server Error: /IDA/upload/
2025-06-27 12:19:09,554 | INFO     | ImageApp1.views | post                 | Line 301  | Upload request received
2025-06-27 12:25:57,691 | INFO     | ImageApp1.views | post                 | Line 301  | Upload request received
2025-06-27 12:28:14,373 | INFO     | ImageApp1.views | post                 | Line 301  | Upload request received
2025-06-27 12:18:29,235 | INFO     | django.utils.autoreload | trigger_reload       | Line 265  | D:\IDP_Project\ImageExtraction\ImageApp1\views.py changed, reloading.
2025-06-27 12:31:03,790 | WARNING  |  django.request | log_response         | Line 253  | Unauthorized: /IDA/upload/
2025-06-27 12:31:32,990 | INFO     | django.utils.autoreload | run_with_reloader    | Line 667  | Watching for file changes with StatReloader
2025-06-27 12:31:50,920 | INFO     | authentication.views | post                 | Line 99   | Login attempt received.
2025-06-27 12:31:52,446 | INFO     | authentication.views | post                 | Line 116  | Login successful for user: abc
2025-06-27 12:32:14,129 | INFO     | ImageApp1.views | post                 | Line 301  | Upload request received
2025-06-27 12:32:14,192 | DEBUG    | urllib3.connectionpool | _new_conn            | Line 1052 | Starting new HTTPS connection (1): oauth2.googleapis.com:443
2025-06-27 12:32:16,079 | DEBUG    | urllib3.connectionpool | _make_request        | Line 546  | https://oauth2.googleapis.com:443 "POST /token HTTP/1.1" 200 None
2025-06-27 12:32:16,095 | DEBUG    | urllib3.connectionpool | _new_conn            | Line 1052 | Starting new HTTPS connection (1): us-central1-aiplatform.googleapis.com:443
2025-06-27 12:32:43,304 | DEBUG    | urllib3.connectionpool | _make_request        | Line 546  | https://us-central1-aiplatform.googleapis.com:443 "POST /v1/projects/vdxexccenter/locations/us-central1/publishers/google/models/gemini-2.5-pro:generateContent HTTP/1.1" 200 None
2025-06-27 12:32:45,192 | ERROR    | ImageApp1.views | post                 | Line 530  | 500
Traceback (most recent call last):
  File "D:\IDP_Project\ImageExtraction\ImageApp1\views.py", line 461, in post
    extracted_json = json.loads(response.text)
                                ^^^^^^^^^^^^^
AttributeError: 'dict' object has no attribute 'text'
2025-06-27 12:32:45,202 | ERROR    | ImageApp1.views | post                 | Line 531  | Error while processing document.
Traceback (most recent call last):
  File "D:\IDP_Project\ImageExtraction\ImageApp1\views.py", line 461, in post
    extracted_json = json.loads(response.text)
                                ^^^^^^^^^^^^^
AttributeError: 'dict' object has no attribute 'text'
2025-06-27 12:32:45,204 | ERROR    | ImageApp1.views | log_exception        | Line 71   | Exception occurred in D:\IDP_Project\ImageExtraction\ImageApp1\views.py, line 461: extracted_json = json.loads(response.text)
2025-06-27 12:32:45,207 | ERROR    |  django.request | log_response         | Line 253  | Internal Server Error: /IDA/upload/
2025-06-27 12:34:07,242 | INFO     | django.utils.autoreload | trigger_reload       | Line 265  | D:\IDP_Project\ImageExtraction\ImageApp1\views.py changed, reloading.
2025-06-27 12:34:09,995 | INFO     | django.utils.autoreload | run_with_reloader    | Line 667  | Watching for file changes with StatReloader
2025-06-27 12:34:21,919 | INFO     | django.utils.autoreload | trigger_reload       | Line 265  | D:\IDP_Project\ImageExtraction\ImageApp1\views.py changed, reloading.
2025-06-27 12:34:23,997 | INFO     | django.utils.autoreload | run_with_reloader    | Line 667  | Watching for file changes with StatReloader
2025-06-27 12:34:44,571 | INFO     | authentication.views | post                 | Line 99   | Login attempt received.
2025-06-27 12:34:46,369 | INFO     | authentication.views | post                 | Line 116  | Login successful for user: abc
2025-06-27 12:35:10,311 | INFO     | ImageApp1.views | post                 | Line 301  | Upload request received
2025-06-27 12:35:10,389 | DEBUG    | urllib3.connectionpool | _new_conn            | Line 1052 | Starting new HTTPS connection (1): oauth2.googleapis.com:443
2025-06-27 12:35:10,887 | DEBUG    | urllib3.connectionpool | _make_request        | Line 546  | https://oauth2.googleapis.com:443 "POST /token HTTP/1.1" 200 None
2025-06-27 12:35:10,904 | DEBUG    | urllib3.connectionpool | _new_conn            | Line 1052 | Starting new HTTPS connection (1): us-central1-aiplatform.googleapis.com:443
2025-06-27 12:35:30,053 | DEBUG    | urllib3.connectionpool | _make_request        | Line 546  | https://us-central1-aiplatform.googleapis.com:443 "POST /v1/projects/vdxexccenter/locations/us-central1/publishers/google/models/gemini-2.5-pro:generateContent HTTP/1.1" 200 None
2025-06-27 12:35:33,658 | ERROR    | ImageApp1.views | post                 | Line 530  | 500
Traceback (most recent call last):
  File "D:\IDP_Project\ImageExtraction\ImageApp1\views.py", line 461, in post
    extracted_json = json.loads(response)
                     ^^^^^^^^^^^^^^^^^^^^
  File "C:\Users\pooja.akolkar\AppData\Local\anaconda3\Lib\json\__init__.py", line 339, in loads
    raise TypeError(f'the JSON object must be str, bytes or bytearray, '
TypeError: the JSON object must be str, bytes or bytearray, not dict
2025-06-27 12:35:33,739 | ERROR    | ImageApp1.views | post                 | Line 531  | Error while processing document.
Traceback (most recent call last):
  File "D:\IDP_Project\ImageExtraction\ImageApp1\views.py", line 461, in post
    extracted_json = json.loads(response)
                     ^^^^^^^^^^^^^^^^^^^^
  File "C:\Users\pooja.akolkar\AppData\Local\anaconda3\Lib\json\__init__.py", line 339, in loads
    raise TypeError(f'the JSON object must be str, bytes or bytearray, '
TypeError: the JSON object must be str, bytes or bytearray, not dict
2025-06-27 12:35:33,748 | ERROR    | ImageApp1.views | log_exception        | Line 71   | Exception occurred in D:\IDP_Project\ImageExtraction\ImageApp1\views.py, line 461: extracted_json = json.loads(response)
2025-06-27 12:35:33,754 | ERROR    | ImageApp1.views | log_exception        | Line 71   | Exception occurred in C:\Users\pooja.akolkar\AppData\Local\anaconda3\Lib\json\__init__.py, line 339: raise TypeError(f'the JSON object must be str, bytes or bytearray, '
2025-06-27 12:35:33,755 | ERROR    |  django.request | log_response         | Line 253  | Internal Server Error: /IDA/upload/
2025-06-27 12:36:46,609 | INFO     | django.utils.autoreload | trigger_reload       | Line 265  | D:\IDP_Project\ImageExtraction\ImageApp1\views.py changed, reloading.
2025-06-27 12:36:48,684 | INFO     | django.utils.autoreload | run_with_reloader    | Line 667  | Watching for file changes with StatReloader
2025-06-27 12:37:55,855 | INFO     | ImageApp1.views | post                 | Line 301  | Upload request received
2025-06-27 12:37:55,936 | DEBUG    | urllib3.connectionpool | _new_conn            | Line 1052 | Starting new HTTPS connection (1): oauth2.googleapis.com:443
2025-06-27 12:37:56,848 | DEBUG    | urllib3.connectionpool | _make_request        | Line 546  | https://oauth2.googleapis.com:443 "POST /token HTTP/1.1" 200 None
2025-06-27 12:37:56,877 | DEBUG    | urllib3.connectionpool | _new_conn            | Line 1052 | Starting new HTTPS connection (1): us-central1-aiplatform.googleapis.com:443
2025-06-27 12:38:05,835 | DEBUG    | urllib3.connectionpool | _make_request        | Line 546  | https://us-central1-aiplatform.googleapis.com:443 "POST /v1/projects/vdxexccenter/locations/us-central1/publishers/google/models/gemini-2.5-pro:generateContent HTTP/1.1" 200 None
2025-06-27 12:38:05,859 | ERROR    | ImageApp1.views | post                 | Line 531  | 500
Traceback (most recent call last):
  File "D:\IDP_Project\ImageExtraction\ImageApp1\views.py", line 462, in post
    extracted_json = json.loads(response)
                     ^^^^^^^^^^^^^^^^^^^^
  File "C:\Users\pooja.akolkar\AppData\Local\anaconda3\Lib\json\__init__.py", line 339, in loads
    raise TypeError(f'the JSON object must be str, bytes or bytearray, '
TypeError: the JSON object must be str, bytes or bytearray, not dict
2025-06-27 12:38:05,867 | ERROR    | ImageApp1.views | post                 | Line 532  | Error while processing document.
Traceback (most recent call last):
  File "D:\IDP_Project\ImageExtraction\ImageApp1\views.py", line 462, in post
    extracted_json = json.loads(response)
                     ^^^^^^^^^^^^^^^^^^^^
  File "C:\Users\pooja.akolkar\AppData\Local\anaconda3\Lib\json\__init__.py", line 339, in loads
    raise TypeError(f'the JSON object must be str, bytes or bytearray, '
TypeError: the JSON object must be str, bytes or bytearray, not dict
2025-06-27 12:38:05,869 | ERROR    | ImageApp1.views | log_exception        | Line 71   | Exception occurred in D:\IDP_Project\ImageExtraction\ImageApp1\views.py, line 462: extracted_json = json.loads(response)
2025-06-27 12:38:05,869 | ERROR    | ImageApp1.views | log_exception        | Line 71   | Exception occurred in C:\Users\pooja.akolkar\AppData\Local\anaconda3\Lib\json\__init__.py, line 339: raise TypeError(f'the JSON object must be str, bytes or bytearray, '
2025-06-27 12:38:05,871 | ERROR    |  django.request | log_response         | Line 253  | Internal Server Error: /IDA/upload/
2025-06-27 12:43:53,781 | INFO     | authentication.views | post                 | Line 99   | Login attempt received.
2025-06-27 12:42:07,103 | INFO     | django.utils.autoreload | trigger_reload       | Line 265  | D:\IDP_Project\ImageExtraction\ImageApp1\views.py changed, reloading.
2025-06-27 12:44:44,114 | INFO     | django.utils.autoreload | run_with_reloader    | Line 667  | Watching for file changes with StatReloader
2025-06-27 12:44:54,107 | INFO     | authentication.views | post                 | Line 99   | Login attempt received.
2025-06-27 12:44:55,708 | INFO     | authentication.views | post                 | Line 116  | Login successful for user: abc
2025-06-27 12:45:23,570 | INFO     | ImageApp1.views | post                 | Line 302  | Upload request received
2025-06-27 12:45:23,637 | DEBUG    | urllib3.connectionpool | _new_conn            | Line 1052 | Starting new HTTPS connection (1): oauth2.googleapis.com:443
2025-06-27 12:45:24,387 | DEBUG    | urllib3.connectionpool | _make_request        | Line 546  | https://oauth2.googleapis.com:443 "POST /token HTTP/1.1" 200 None
2025-06-27 12:45:24,412 | DEBUG    | urllib3.connectionpool | _new_conn            | Line 1052 | Starting new HTTPS connection (1): us-central1-aiplatform.googleapis.com:443
2025-06-27 12:45:29,298 | DEBUG    | urllib3.connectionpool | _make_request        | Line 546  | https://us-central1-aiplatform.googleapis.com:443 "POST /v1/projects/vdxexccenter/locations/us-central1/publishers/google/models/gemini-2.5-pro:generateContent HTTP/1.1" 429 None
2025-06-27 12:45:30,620 | ERROR    | ImageApp1.views | post                 | Line 535  | 500
Traceback (most recent call last):
  File "D:\IDP_Project\ImageExtraction\ImageApp1\vertex_model.py", line 177, in call_gemini_api
    response.raise_for_status()
  File "C:\Users\pooja.akolkar\AppData\Local\anaconda3\Lib\site-packages\requests\models.py", line 1024, in raise_for_status
    raise HTTPError(http_error_msg, response=self)
requests.exceptions.HTTPError: 429 Client Error: Too Many Requests for url: https://us-central1-aiplatform.googleapis.com/v1/projects/vdxexccenter/locations/us-central1/publishers/google/models/gemini-2.5-pro:generateContent

During handling of the above exception, another exception occurred:

Traceback (most recent call last):
  File "D:\IDP_Project\ImageExtraction\ImageApp1\views.py", line 459, in post
    response = call_gemini_api(
               ^^^^^^^^^^^^^^^^
  File "D:\IDP_Project\ImageExtraction\ImageApp1\vertex_model.py", line 183, in call_gemini_api
    raise Exception(error_msg)
Exception: API request failed: 429 Client Error: Too Many Requests for url: https://us-central1-aiplatform.googleapis.com/v1/projects/vdxexccenter/locations/us-central1/publishers/google/models/gemini-2.5-pro:generateContent
Response: {
  "error": {
    "code": 429,
    "message": "Resource exhausted. Please try again later. Please refer to https://cloud.google.com/vertex-ai/generative-ai/docs/error-code-429 for more details.",
    "status": "RESOURCE_EXHAUSTED"
  }
}

2025-06-27 12:45:30,723 | ERROR    | ImageApp1.views | post                 | Line 536  | Error while processing document.
Traceback (most recent call last):
  File "D:\IDP_Project\ImageExtraction\ImageApp1\vertex_model.py", line 177, in call_gemini_api
    response.raise_for_status()
  File "C:\Users\pooja.akolkar\AppData\Local\anaconda3\Lib\site-packages\requests\models.py", line 1024, in raise_for_status
    raise HTTPError(http_error_msg, response=self)
requests.exceptions.HTTPError: 429 Client Error: Too Many Requests for url: https://us-central1-aiplatform.googleapis.com/v1/projects/vdxexccenter/locations/us-central1/publishers/google/models/gemini-2.5-pro:generateContent

During handling of the above exception, another exception occurred:

Traceback (most recent call last):
  File "D:\IDP_Project\ImageExtraction\ImageApp1\views.py", line 459, in post
    response = call_gemini_api(
               ^^^^^^^^^^^^^^^^
  File "D:\IDP_Project\ImageExtraction\ImageApp1\vertex_model.py", line 183, in call_gemini_api
    raise Exception(error_msg)
Exception: API request failed: 429 Client Error: Too Many Requests for url: https://us-central1-aiplatform.googleapis.com/v1/projects/vdxexccenter/locations/us-central1/publishers/google/models/gemini-2.5-pro:generateContent
Response: {
  "error": {
    "code": 429,
    "message": "Resource exhausted. Please try again later. Please refer to https://cloud.google.com/vertex-ai/generative-ai/docs/error-code-429 for more details.",
    "status": "RESOURCE_EXHAUSTED"
  }
}

2025-06-27 12:45:30,734 | ERROR    | ImageApp1.views | log_exception        | Line 71   | Exception occurred in D:\IDP_Project\ImageExtraction\ImageApp1\views.py, line 459: response = call_gemini_api(
2025-06-27 12:45:30,734 | ERROR    | ImageApp1.views | log_exception        | Line 71   | Exception occurred in D:\IDP_Project\ImageExtraction\ImageApp1\vertex_model.py, line 183: raise Exception(error_msg)
2025-06-27 12:45:30,737 | ERROR    |  django.request | log_response         | Line 253  | Internal Server Error: /IDA/upload/
2025-06-27 12:45:36,871 | INFO     | ImageApp1.views | post                 | Line 302  | Upload request received
2025-06-27 12:45:39,009 | DEBUG    | urllib3.connectionpool | _new_conn            | Line 1052 | Starting new HTTPS connection (1): oauth2.googleapis.com:443
2025-06-27 12:45:39,391 | DEBUG    | urllib3.connectionpool | _make_request        | Line 546  | https://oauth2.googleapis.com:443 "POST /token HTTP/1.1" 200 None
2025-06-27 12:45:39,409 | DEBUG    | urllib3.connectionpool | _new_conn            | Line 1052 | Starting new HTTPS connection (1): us-central1-aiplatform.googleapis.com:443
2025-06-27 12:45:53,189 | DEBUG    | urllib3.connectionpool | _make_request        | Line 546  | https://us-central1-aiplatform.googleapis.com:443 "POST /v1/projects/vdxexccenter/locations/us-central1/publishers/google/models/gemini-2.5-pro:generateContent HTTP/1.1" 200 None
2025-06-27 12:45:53,190 | ERROR    | ImageApp1.views | post                 | Line 535  | 500
Traceback (most recent call last):
  File "D:\IDP_Project\ImageExtraction\ImageApp1\views.py", line 469, in post
    if response.usage_metadata:
       ^^^^^^^^^^^^^^^^^^^^^^^
AttributeError: 'dict' object has no attribute 'usage_metadata'
2025-06-27 12:45:53,192 | ERROR    | ImageApp1.views | post                 | Line 536  | Error while processing document.
Traceback (most recent call last):
  File "D:\IDP_Project\ImageExtraction\ImageApp1\views.py", line 469, in post
    if response.usage_metadata:
       ^^^^^^^^^^^^^^^^^^^^^^^
AttributeError: 'dict' object has no attribute 'usage_metadata'
2025-06-27 12:45:53,195 | ERROR    | ImageApp1.views | log_exception        | Line 71   | Exception occurred in D:\IDP_Project\ImageExtraction\ImageApp1\views.py, line 469: if response.usage_metadata:
2025-06-27 12:45:53,195 | ERROR    |  django.request | log_response         | Line 253  | Internal Server Error: /IDA/upload/
2025-06-27 12:50:09,341 | INFO     | django.utils.autoreload | trigger_reload       | Line 265  | D:\IDP_Project\ImageExtraction\ImageApp1\views.py changed, reloading.
2025-06-27 12:50:11,422 | INFO     | django.utils.autoreload | run_with_reloader    | Line 667  | Watching for file changes with StatReloader
2025-06-27 12:52:31,856 | INFO     | authentication.views | post                 | Line 99   | Login attempt received.
2025-06-27 12:52:33,521 | INFO     | authentication.views | post                 | Line 116  | Login successful for user: abc
2025-06-27 12:52:43,165 | INFO     | ImageApp1.views | post                 | Line 302  | Upload request received
2025-06-27 12:52:43,230 | DEBUG    | urllib3.connectionpool | _new_conn            | Line 1052 | Starting new HTTPS connection (1): oauth2.googleapis.com:443
2025-06-27 12:52:43,636 | DEBUG    | urllib3.connectionpool | _make_request        | Line 546  | https://oauth2.googleapis.com:443 "POST /token HTTP/1.1" 200 None
2025-06-27 12:52:43,675 | DEBUG    | urllib3.connectionpool | _new_conn            | Line 1052 | Starting new HTTPS connection (1): us-central1-aiplatform.googleapis.com:443
2025-06-27 12:52:55,125 | DEBUG    | urllib3.connectionpool | _make_request        | Line 546  | https://us-central1-aiplatform.googleapis.com:443 "POST /v1/projects/vdxexccenter/locations/us-central1/publishers/google/models/gemini-2.5-pro:generateContent HTTP/1.1" 200 None
2025-06-27 12:52:55,137 | INFO     |            root | post                 | Line 478  | Input tokens: 1563, Output tokens: 76
2025-06-27 12:52:55,179 | DEBUG    | urllib3.connectionpool | _new_conn            | Line 1052 | Starting new HTTPS connection (1): oauth2.googleapis.com:443
2025-06-27 12:52:55,446 | DEBUG    | urllib3.connectionpool | _make_request        | Line 546  | https://oauth2.googleapis.com:443 "POST /token HTTP/1.1" 200 None
2025-06-27 12:52:55,448 | DEBUG    | urllib3.connectionpool | _new_conn            | Line 1052 | Starting new HTTPS connection (1): us-central1-aiplatform.googleapis.com:443
2025-06-27 12:53:20,677 | DEBUG    | urllib3.connectionpool | _make_request        | Line 546  | https://us-central1-aiplatform.googleapis.com:443 "POST /v1/projects/vdxexccenter/locations/us-central1/publishers/google/models/gemini-2.5-pro:generateContent HTTP/1.1" 200 None
2025-06-27 12:53:20,781 | INFO     | ImageApp1.views | post                 | Line 525  | Document processed and saved successfully. Document ID: gAAAAABoXkboPq7-HPhPxY_YMvm6zV2svjp_a6UASwafY6G3v01fYk-kuSY5aQVRUmDV_NdWkPcCjfIGijTXUt3JBOwP2UphZQ==
2025-06-27 12:56:16,957 | INFO     | ImageApp1.views | post                 | Line 302  | Upload request received
2025-06-27 12:56:17,060 | DEBUG    | urllib3.connectionpool | _new_conn            | Line 1052 | Starting new HTTPS connection (1): oauth2.googleapis.com:443
2025-06-27 12:56:17,373 | DEBUG    | urllib3.connectionpool | _make_request        | Line 546  | https://oauth2.googleapis.com:443 "POST /token HTTP/1.1" 200 None
2025-06-27 12:56:17,403 | DEBUG    | urllib3.connectionpool | _new_conn            | Line 1052 | Starting new HTTPS connection (1): us-central1-aiplatform.googleapis.com:443
2025-06-27 12:56:35,746 | DEBUG    | urllib3.connectionpool | _make_request        | Line 546  | https://us-central1-aiplatform.googleapis.com:443 "POST /v1/projects/vdxexccenter/locations/us-central1/publishers/google/models/gemini-2.5-pro:generateContent HTTP/1.1" 200 None
2025-06-27 12:56:35,758 | INFO     |            root | post                 | Line 478  | Input tokens: 1047, Output tokens: 167
2025-06-27 12:56:35,807 | DEBUG    | urllib3.connectionpool | _new_conn            | Line 1052 | Starting new HTTPS connection (1): oauth2.googleapis.com:443
2025-06-27 12:56:36,086 | DEBUG    | urllib3.connectionpool | _make_request        | Line 546  | https://oauth2.googleapis.com:443 "POST /token HTTP/1.1" 200 None
2025-06-27 12:56:36,089 | DEBUG    | urllib3.connectionpool | _new_conn            | Line 1052 | Starting new HTTPS connection (1): us-central1-aiplatform.googleapis.com:443
2025-06-27 12:57:09,373 | DEBUG    | urllib3.connectionpool | _make_request        | Line 546  | https://us-central1-aiplatform.googleapis.com:443 "POST /v1/projects/vdxexccenter/locations/us-central1/publishers/google/models/gemini-2.5-pro:generateContent HTTP/1.1" 200 None
2025-06-27 12:57:09,427 | INFO     | ImageApp1.views | post                 | Line 525  | Document processed and saved successfully. Document ID: gAAAAABoXkfN81ruHdyUwHHBZYlUWJYOuyVWK39qEjKLzTxMfsWx68KVxnz3dUquaUtgwi1CRuz8tSb_7njABYHO96OnItd3kQ==
2025-06-27 12:58:52,190 | WARNING  |  django.request | log_response         | Line 253  | Unauthorized: /IDA/get-document/gAAAAABoXkfN81ruHdyUwHHBZYlUWJYOuyVWK39qEjKLzTxMfsWx68KVxnz3dUquaUtgwi1CRuz8tSb_7njABYHO96OnItd3kQ==/
2025-06-27 12:58:58,066 | INFO     | authentication.views | post                 | Line 99   | Login attempt received.
2025-06-27 12:58:59,310 | INFO     | authentication.views | post                 | Line 116  | Login successful for user: abc
2025-06-27 12:59:23,689 | INFO     | ImageApp1.views | get                  | Line 91   | GetDocumentByIdView called with encrypted ID: gAAAAABoXkfN81ruHdyUwHHBZYlUWJYOuyVWK39qEjKLzTxMfsWx68KVxnz3dUquaUtgwi1CRuz8tSb_7njABYHO96OnItd3kQ==
2025-06-27 12:59:23,689 | DEBUG    | ImageApp1.views | get                  | Line 95   | Decrypted ID: 190
2025-06-27 12:59:23,766 | INFO     | ImageApp1.views | get                  | Line 99   | Document 190 retrieved successfully
2025-06-27 13:05:07,367 | INFO     | django.utils.autoreload | trigger_reload       | Line 265  | D:\IDP_Project\ImageExtraction\ImageApp1\views.py changed, reloading.
2025-06-27 13:05:09,767 | INFO     | django.utils.autoreload | run_with_reloader    | Line 667  | Watching for file changes with StatReloader
2025-06-27 13:05:45,748 | INFO     | django.utils.autoreload | trigger_reload       | Line 265  | D:\IDP_Project\ImageExtraction\ImageApp1\views.py changed, reloading.
2025-06-27 13:05:47,979 | INFO     | django.utils.autoreload | run_with_reloader    | Line 667  | Watching for file changes with StatReloader
2025-06-27 13:07:16,478 | INFO     | django.utils.autoreload | trigger_reload       | Line 265  | D:\IDP_Project\ImageExtraction\ImageApp1\views.py changed, reloading.
2025-06-27 13:07:28,608 | INFO     | django.utils.autoreload | run_with_reloader    | Line 667  | Watching for file changes with StatReloader
2025-06-27 13:08:15,010 | INFO     | django.utils.autoreload | trigger_reload       | Line 265  | D:\IDP_Project\ImageExtraction\authentication\views.py changed, reloading.
2025-06-27 13:08:17,256 | INFO     | django.utils.autoreload | run_with_reloader    | Line 667  | Watching for file changes with StatReloader
2025-06-27 13:10:44,618 | INFO     | authentication.views | post                 | Line 99   | Login attempt received.
2025-06-27 13:10:45,941 | INFO     | authentication.views | post                 | Line 116  | Login successful for user: abc
2025-06-27 13:11:07,499 | INFO     | ImageApp1.views | post                 | Line 302  | Upload request received
2025-06-27 13:11:07,560 | DEBUG    | urllib3.connectionpool | _new_conn            | Line 1052 | Starting new HTTPS connection (1): oauth2.googleapis.com:443
2025-06-27 13:11:07,994 | DEBUG    | urllib3.connectionpool | _make_request        | Line 546  | https://oauth2.googleapis.com:443 "POST /token HTTP/1.1" 200 None
2025-06-27 13:11:08,031 | DEBUG    | urllib3.connectionpool | _new_conn            | Line 1052 | Starting new HTTPS connection (1): us-central1-aiplatform.googleapis.com:443
2025-06-27 13:11:26,322 | DEBUG    | urllib3.connectionpool | _make_request        | Line 546  | https://us-central1-aiplatform.googleapis.com:443 "POST /v1/projects/vdxexccenter/locations/us-central1/publishers/google/models/gemini-2.5-pro:generateContent HTTP/1.1" 200 None
2025-06-27 13:11:26,333 | INFO     |            root | post                 | Line 477  | Input tokens: 1047, Output tokens: 146
2025-06-27 13:11:26,382 | DEBUG    | urllib3.connectionpool | _new_conn            | Line 1052 | Starting new HTTPS connection (1): oauth2.googleapis.com:443
2025-06-27 13:11:26,599 | DEBUG    | urllib3.connectionpool | _make_request        | Line 546  | https://oauth2.googleapis.com:443 "POST /token HTTP/1.1" 200 None
2025-06-27 13:11:26,602 | DEBUG    | urllib3.connectionpool | _new_conn            | Line 1052 | Starting new HTTPS connection (1): us-central1-aiplatform.googleapis.com:443
2025-06-27 13:11:58,585 | DEBUG    | urllib3.connectionpool | _make_request        | Line 546  | https://us-central1-aiplatform.googleapis.com:443 "POST /v1/projects/vdxexccenter/locations/us-central1/publishers/google/models/gemini-2.5-pro:generateContent HTTP/1.1" 200 None
2025-06-27 13:11:58,852 | INFO     | ImageApp1.views | post                 | Line 524  | Document processed and saved successfully. Document ID: gAAAAABoXktG0PmeITNoOx3QZZUJy2hG2uNVxCcDP2uLerVQrncBIOX8nBAlqrZEfWfiS110bKJ2FuFwz-z7_gHI_5d72gNCbA==
2025-06-27 13:17:16,564 | INFO     | ImageApp1.views | post                 | Line 302  | Upload request received
2025-06-27 13:17:16,568 | ERROR    | ImageApp1.views | post                 | Line 345  | Unsupported file type
NoneType: None
2025-06-27 13:17:16,569 | WARNING  |  django.request | log_response         | Line 253  | Bad Request: /IDA/upload/
2025-06-27 13:17:31,794 | INFO     | ImageApp1.views | post                 | Line 302  | Upload request received
2025-06-27 13:17:31,801 | ERROR    | ImageApp1.views | post                 | Line 345  | Unsupported file type
NoneType: None
2025-06-27 13:17:31,802 | WARNING  |  django.request | log_response         | Line 253  | Bad Request: /IDA/upload/
2025-06-27 13:18:00,037 | INFO     | ImageApp1.views | post                 | Line 302  | Upload request received
2025-06-27 13:18:00,092 | DEBUG    | urllib3.connectionpool | _new_conn            | Line 1052 | Starting new HTTPS connection (1): oauth2.googleapis.com:443
2025-06-27 13:18:00,499 | DEBUG    | urllib3.connectionpool | _make_request        | Line 546  | https://oauth2.googleapis.com:443 "POST /token HTTP/1.1" 200 None
2025-06-27 13:18:00,512 | DEBUG    | urllib3.connectionpool | _new_conn            | Line 1052 | Starting new HTTPS connection (1): us-central1-aiplatform.googleapis.com:443
2025-06-27 13:18:13,910 | DEBUG    | urllib3.connectionpool | _make_request        | Line 546  | https://us-central1-aiplatform.googleapis.com:443 "POST /v1/projects/vdxexccenter/locations/us-central1/publishers/google/models/gemini-2.5-pro:generateContent HTTP/1.1" 200 None
2025-06-27 13:18:13,919 | INFO     |            root | post                 | Line 477  | Input tokens: 1563, Output tokens: 201
2025-06-27 13:18:13,971 | DEBUG    | urllib3.connectionpool | _new_conn            | Line 1052 | Starting new HTTPS connection (1): oauth2.googleapis.com:443
2025-06-27 13:18:14,198 | DEBUG    | urllib3.connectionpool | _make_request        | Line 546  | https://oauth2.googleapis.com:443 "POST /token HTTP/1.1" 200 None
2025-06-27 13:18:14,201 | DEBUG    | urllib3.connectionpool | _new_conn            | Line 1052 | Starting new HTTPS connection (1): us-central1-aiplatform.googleapis.com:443
2025-06-27 13:18:49,875 | DEBUG    | urllib3.connectionpool | _make_request        | Line 546  | https://us-central1-aiplatform.googleapis.com:443 "POST /v1/projects/vdxexccenter/locations/us-central1/publishers/google/models/gemini-2.5-pro:generateContent HTTP/1.1" 200 None
2025-06-27 13:18:49,897 | INFO     | ImageApp1.views | post                 | Line 524  | Document processed and saved successfully. Document ID: gAAAAABoXkzhS1GQM_S78aJ_rzkca8l8x7H2JM0lrnmk-QVPQimEN5np1143dzHvaexBVFasK5t9tepOxTpJQ9lzXm3Wo4p6SQ==
2025-06-27 13:19:26,732 | INFO     | ImageApp1.views | post                 | Line 302  | Upload request received
2025-06-27 13:19:26,963 | DEBUG    | urllib3.connectionpool | _new_conn            | Line 1052 | Starting new HTTPS connection (1): oauth2.googleapis.com:443
2025-06-27 13:19:27,193 | DEBUG    | urllib3.connectionpool | _make_request        | Line 546  | https://oauth2.googleapis.com:443 "POST /token HTTP/1.1" 200 None
2025-06-27 13:19:27,202 | DEBUG    | urllib3.connectionpool | _new_conn            | Line 1052 | Starting new HTTPS connection (1): us-central1-aiplatform.googleapis.com:443
2025-06-27 13:19:43,013 | DEBUG    | urllib3.connectionpool | _make_request        | Line 546  | https://us-central1-aiplatform.googleapis.com:443 "POST /v1/projects/vdxexccenter/locations/us-central1/publishers/google/models/gemini-2.5-pro:generateContent HTTP/1.1" 200 None
2025-06-27 13:19:43,027 | INFO     |            root | post                 | Line 477  | Input tokens: 2079, Output tokens: 128
2025-06-27 13:19:43,075 | DEBUG    | urllib3.connectionpool | _new_conn            | Line 1052 | Starting new HTTPS connection (1): oauth2.googleapis.com:443
2025-06-27 13:19:43,423 | DEBUG    | urllib3.connectionpool | _make_request        | Line 546  | https://oauth2.googleapis.com:443 "POST /token HTTP/1.1" 200 None
2025-06-27 13:19:43,427 | DEBUG    | urllib3.connectionpool | _new_conn            | Line 1052 | Starting new HTTPS connection (1): us-central1-aiplatform.googleapis.com:443
2025-06-27 13:20:16,480 | DEBUG    | urllib3.connectionpool | _make_request        | Line 546  | https://us-central1-aiplatform.googleapis.com:443 "POST /v1/projects/vdxexccenter/locations/us-central1/publishers/google/models/gemini-2.5-pro:generateContent HTTP/1.1" 200 None
2025-06-27 13:20:16,561 | INFO     | ImageApp1.views | post                 | Line 524  | Document processed and saved successfully. Document ID: gAAAAABoXk04DfNZcXIO8HZucoWf3nsYYRJF1EGTtlfnyEAtEQbzsgHIJ-Q3ObSSB_un-yX_eAPK2BO0wo7QY_8wXeDx1pULXg==
2025-06-27 13:23:51,692 | INFO     | ImageApp1.views | post                 | Line 302  | Upload request received
2025-06-27 13:23:51,708 | ERROR    | ImageApp1.views | post                 | Line 345  | Unsupported file type
NoneType: None
2025-06-27 13:23:51,710 | WARNING  |  django.request | log_response         | Line 253  | Bad Request: /IDA/upload/
2025-06-27 13:24:44,451 | INFO     | django.utils.autoreload | trigger_reload       | Line 265  | D:\IDP_Project\ImageExtraction\ImageApp1\views.py changed, reloading.
2025-06-27 13:24:58,692 | INFO     | django.utils.autoreload | run_with_reloader    | Line 667  | Watching for file changes with StatReloader
2025-06-27 13:29:24,466 | INFO     | django.utils.autoreload | trigger_reload       | Line 265  | D:\IDP_Project\ImageExtraction\ImageExtraction\settings.py changed, reloading.
2025-06-27 13:29:29,862 | INFO     | django.utils.autoreload | run_with_reloader    | Line 667  | Watching for file changes with StatReloader
2025-06-27 13:30:27,443 | INFO     | django.utils.autoreload | trigger_reload       | Line 265  | D:\IDP_Project\ImageExtraction\ImageExtraction\settings.py changed, reloading.
2025-06-27 13:30:36,376 | INFO     | django.utils.autoreload | run_with_reloader    | Line 667  | Watching for file changes with StatReloader
2025-06-27 14:08:04,065 | INFO     | django.utils.autoreload | run_with_reloader    | Line 667  | Watching for file changes with StatReloader
2025-06-27 14:08:27,226 | INFO     | authentication.views | post                 | Line 99   | Login attempt received.
2025-06-27 14:08:32,097 | INFO     | authentication.views | post                 | Line 116  | Login successful for user: abc
2025-06-27 14:10:17,421 | WARNING  |  django.request | log_response         | Line 253  | Unauthorized: /IDA/upload/
2025-06-27 14:10:43,195 | INFO     | ImageApp1.views | post                 | Line 302  | Upload request received
2025-06-27 14:10:43,339 | DEBUG    | urllib3.connectionpool | _new_conn            | Line 1052 | Starting new HTTPS connection (1): oauth2.googleapis.com:443
2025-06-27 14:10:43,770 | DEBUG    | urllib3.connectionpool | _make_request        | Line 546  | https://oauth2.googleapis.com:443 "POST /token HTTP/1.1" 200 None
2025-06-27 14:10:43,818 | DEBUG    | urllib3.connectionpool | _new_conn            | Line 1052 | Starting new HTTPS connection (1): us-central1-aiplatform.googleapis.com:443
2025-06-27 14:13:00,618 | DEBUG    | urllib3.connectionpool | _make_request        | Line 546  | https://us-central1-aiplatform.googleapis.com:443 "POST /v1/projects/vdxexccenter/locations/us-central1/publishers/google/models/gemini-2.5-pro:generateContent HTTP/1.1" 200 None
2025-06-27 14:13:00,877 | DEBUG    | urllib3.connectionpool | _new_conn            | Line 1052 | Starting new HTTPS connection (1): oauth2.googleapis.com:443
2025-06-27 14:13:01,133 | DEBUG    | urllib3.connectionpool | _make_request        | Line 546  | https://oauth2.googleapis.com:443 "POST /token HTTP/1.1" 200 None
2025-06-27 14:13:01,148 | DEBUG    | urllib3.connectionpool | _new_conn            | Line 1052 | Starting new HTTPS connection (1): us-central1-aiplatform.googleapis.com:443
2025-06-27 14:14:08,818 | INFO     | authentication.views | post                 | Line 99   | Login attempt received.
2025-06-27 14:14:14,109 | INFO     | authentication.views | post                 | Line 116  | Login successful for user: abc
2025-06-27 14:14:34,212 | INFO     | ImageApp1.views | post                 | Line 302  | Upload request received
2025-06-27 14:14:34,392 | DEBUG    | urllib3.connectionpool | _new_conn            | Line 1052 | Starting new HTTPS connection (1): oauth2.googleapis.com:443
2025-06-27 14:14:34,679 | DEBUG    | urllib3.connectionpool | _make_request        | Line 546  | https://oauth2.googleapis.com:443 "POST /token HTTP/1.1" 200 None
2025-06-27 14:14:34,765 | DEBUG    | urllib3.connectionpool | _new_conn            | Line 1052 | Starting new HTTPS connection (1): us-central1-aiplatform.googleapis.com:443
2025-06-27 14:14:36,858 | DEBUG    | urllib3.connectionpool | _make_request        | Line 546  | https://us-central1-aiplatform.googleapis.com:443 "POST /v1/projects/vdxexccenter/locations/us-central1/publishers/google/models/gemini-2.5-pro:generateContent HTTP/1.1" 200 None
2025-06-27 14:14:37,010 | INFO     | ImageApp1.views | post                 | Line 524  | Document processed and saved successfully. Document ID: gAAAAABoXln1n7glv3lCVPyKxmwSMQ_saQ7GP4voGtY8EpWWDG9NidRF55G_-HYtO6uATQyx9jfl1L-Op_-4MF5Rro4KRsoOWA==
2025-06-27 14:14:38,159 | DEBUG    | urllib3.connectionpool | _make_request        | Line 546  | https://us-central1-aiplatform.googleapis.com:443 "POST /v1/projects/vdxexccenter/locations/us-central1/publishers/google/models/gemini-2.5-pro:generateContent HTTP/1.1" 429 None
2025-06-27 14:14:38,163 | ERROR    | ImageApp1.views | post                 | Line 532  | 500
Traceback (most recent call last):
  File "D:\IDP_Project\ImageExtraction\ImageApp1\vertex_model.py", line 177, in call_gemini_api
    response.raise_for_status()
  File "C:\Users\pooja.akolkar\AppData\Local\anaconda3\Lib\site-packages\requests\models.py", line 1024, in raise_for_status
    raise HTTPError(http_error_msg, response=self)
requests.exceptions.HTTPError: 429 Client Error: Too Many Requests for url: https://us-central1-aiplatform.googleapis.com/v1/projects/vdxexccenter/locations/us-central1/publishers/google/models/gemini-2.5-pro:generateContent

During handling of the above exception, another exception occurred:

Traceback (most recent call last):
  File "D:\IDP_Project\ImageExtraction\ImageApp1\views.py", line 399, in post
    response = call_gemini_api(
               ^^^^^^^^^^^^^^^^
  File "D:\IDP_Project\ImageExtraction\ImageApp1\vertex_model.py", line 183, in call_gemini_api
    raise Exception(error_msg)
Exception: API request failed: 429 Client Error: Too Many Requests for url: https://us-central1-aiplatform.googleapis.com/v1/projects/vdxexccenter/locations/us-central1/publishers/google/models/gemini-2.5-pro:generateContent
Response: {
  "error": {
    "code": 429,
    "message": "Resource exhausted. Please try again later. Please refer to https://cloud.google.com/vertex-ai/generative-ai/docs/error-code-429 for more details.",
    "status": "RESOURCE_EXHAUSTED"
  }
}

2025-06-27 14:14:38,176 | ERROR    | ImageApp1.views | post                 | Line 533  | Error while processing document.
Traceback (most recent call last):
  File "D:\IDP_Project\ImageExtraction\ImageApp1\vertex_model.py", line 177, in call_gemini_api
    response.raise_for_status()
  File "C:\Users\pooja.akolkar\AppData\Local\anaconda3\Lib\site-packages\requests\models.py", line 1024, in raise_for_status
    raise HTTPError(http_error_msg, response=self)
requests.exceptions.HTTPError: 429 Client Error: Too Many Requests for url: https://us-central1-aiplatform.googleapis.com/v1/projects/vdxexccenter/locations/us-central1/publishers/google/models/gemini-2.5-pro:generateContent

During handling of the above exception, another exception occurred:

Traceback (most recent call last):
  File "D:\IDP_Project\ImageExtraction\ImageApp1\views.py", line 399, in post
    response = call_gemini_api(
               ^^^^^^^^^^^^^^^^
  File "D:\IDP_Project\ImageExtraction\ImageApp1\vertex_model.py", line 183, in call_gemini_api
    raise Exception(error_msg)
Exception: API request failed: 429 Client Error: Too Many Requests for url: https://us-central1-aiplatform.googleapis.com/v1/projects/vdxexccenter/locations/us-central1/publishers/google/models/gemini-2.5-pro:generateContent
Response: {
  "error": {
    "code": 429,
    "message": "Resource exhausted. Please try again later. Please refer to https://cloud.google.com/vertex-ai/generative-ai/docs/error-code-429 for more details.",
    "status": "RESOURCE_EXHAUSTED"
  }
}

2025-06-27 14:14:38,185 | ERROR    | ImageApp1.views | log_exception        | Line 71   | Exception occurred in D:\IDP_Project\ImageExtraction\ImageApp1\views.py, line 399: response = call_gemini_api(
2025-06-27 14:14:38,187 | ERROR    | ImageApp1.views | log_exception        | Line 71   | Exception occurred in D:\IDP_Project\ImageExtraction\ImageApp1\vertex_model.py, line 183: raise Exception(error_msg)
2025-06-27 14:14:38,189 | ERROR    |  django.request | log_response         | Line 253  | Internal Server Error: /IDA/upload/
2025-06-27 14:17:20,193 | INFO     | ImageApp1.views | post                 | Line 302  | Upload request received
2025-06-27 14:19:36,672 | INFO     | ImageApp1.views | post                 | Line 302  | Upload request received
2025-06-27 14:20:37,678 | INFO     | ImageApp1.views | post                 | Line 302  | Upload request received
2025-06-27 14:21:01,840 | DEBUG    | urllib3.connectionpool | _new_conn            | Line 1052 | Starting new HTTPS connection (1): oauth2.googleapis.com:443
2025-06-27 14:21:01,845 | DEBUG    | urllib3.connectionpool | _new_conn            | Line 1052 | Starting new HTTPS connection (1): oauth2.googleapis.com:443
2025-06-27 14:21:01,847 | DEBUG    | urllib3.connectionpool | _new_conn            | Line 1052 | Starting new HTTPS connection (1): oauth2.googleapis.com:443
2025-06-27 14:21:02,250 | DEBUG    | urllib3.connectionpool | _make_request        | Line 546  | https://oauth2.googleapis.com:443 "POST /token HTTP/1.1" 200 None
2025-06-27 14:21:02,264 | DEBUG    | urllib3.connectionpool | _make_request        | Line 546  | https://oauth2.googleapis.com:443 "POST /token HTTP/1.1" 200 None
2025-06-27 14:21:02,297 | DEBUG    | urllib3.connectionpool | _make_request        | Line 546  | https://oauth2.googleapis.com:443 "POST /token HTTP/1.1" 200 None
2025-06-27 14:21:02,361 | DEBUG    | urllib3.connectionpool | _new_conn            | Line 1052 | Starting new HTTPS connection (1): us-central1-aiplatform.googleapis.com:443
2025-06-27 14:21:02,437 | DEBUG    | urllib3.connectionpool | _new_conn            | Line 1052 | Starting new HTTPS connection (1): us-central1-aiplatform.googleapis.com:443
2025-06-27 14:21:02,444 | DEBUG    | urllib3.connectionpool | _new_conn            | Line 1052 | Starting new HTTPS connection (1): us-central1-aiplatform.googleapis.com:443
2025-06-27 14:21:25,282 | INFO     | django.utils.autoreload | run_with_reloader    | Line 667  | Watching for file changes with StatReloader
2025-06-27 14:22:02,537 | INFO     | django.utils.autoreload | run_with_reloader    | Line 667  | Watching for file changes with StatReloader
2025-06-27 14:22:27,769 | INFO     | ImageApp1.views | post                 | Line 302  | Upload request received
2025-06-27 14:22:27,967 | DEBUG    | urllib3.connectionpool | _new_conn            | Line 1052 | Starting new HTTPS connection (1): oauth2.googleapis.com:443
2025-06-27 14:22:28,238 | DEBUG    | urllib3.connectionpool | _make_request        | Line 546  | https://oauth2.googleapis.com:443 "POST /token HTTP/1.1" 200 None
2025-06-27 14:22:28,280 | DEBUG    | urllib3.connectionpool | _new_conn            | Line 1052 | Starting new HTTPS connection (1): us-central1-aiplatform.googleapis.com:443
2025-06-27 14:22:47,344 | DEBUG    | urllib3.connectionpool | _make_request        | Line 546  | https://us-central1-aiplatform.googleapis.com:443 "POST /v1/projects/vdxexccenter/locations/us-central1/publishers/google/models/gemini-2.5-pro:generateContent HTTP/1.1" 200 None
2025-06-27 14:22:47,368 | INFO     |            root | post                 | Line 477  | Input tokens: 1563, Output tokens: 147
2025-06-27 14:22:47,634 | DEBUG    | urllib3.connectionpool | _new_conn            | Line 1052 | Starting new HTTPS connection (1): oauth2.googleapis.com:443
2025-06-27 14:22:47,881 | DEBUG    | urllib3.connectionpool | _make_request        | Line 546  | https://oauth2.googleapis.com:443 "POST /token HTTP/1.1" 200 None
2025-06-27 14:22:47,896 | DEBUG    | urllib3.connectionpool | _new_conn            | Line 1052 | Starting new HTTPS connection (1): us-central1-aiplatform.googleapis.com:443
2025-06-27 14:22:49,623 | DEBUG    | urllib3.connectionpool | _make_request        | Line 546  | https://us-central1-aiplatform.googleapis.com:443 "POST /v1/projects/vdxexccenter/locations/us-central1/publishers/google/models/gemini-2.5-pro:generateContent HTTP/1.1" 429 None
2025-06-27 14:22:51,516 | ERROR    | ImageApp1.views | post                 | Line 532  | 500
Traceback (most recent call last):
  File "D:\IDP_Project\ImageExtraction\ImageApp1\vertex_model.py", line 177, in call_gemini_api
    response.raise_for_status()
  File "C:\Users\pooja.akolkar\AppData\Local\anaconda3\Lib\site-packages\requests\models.py", line 1024, in raise_for_status
    raise HTTPError(http_error_msg, response=self)
requests.exceptions.HTTPError: 429 Client Error: Too Many Requests for url: https://us-central1-aiplatform.googleapis.com/v1/projects/vdxexccenter/locations/us-central1/publishers/google/models/gemini-2.5-pro:generateContent

During handling of the above exception, another exception occurred:

Traceback (most recent call last):
  File "D:\IDP_Project\ImageExtraction\ImageApp1\views.py", line 488, in post
    html_response = call_gemini_api(
                    ^^^^^^^^^^^^^^^^
  File "D:\IDP_Project\ImageExtraction\ImageApp1\vertex_model.py", line 183, in call_gemini_api
    raise Exception(error_msg)
Exception: API request failed: 429 Client Error: Too Many Requests for url: https://us-central1-aiplatform.googleapis.com/v1/projects/vdxexccenter/locations/us-central1/publishers/google/models/gemini-2.5-pro:generateContent
Response: {
  "error": {
    "code": 429,
    "message": "Resource exhausted. Please try again later. Please refer to https://cloud.google.com/vertex-ai/generative-ai/docs/error-code-429 for more details.",
    "status": "RESOURCE_EXHAUSTED"
  }
}

2025-06-27 14:22:51,582 | ERROR    | ImageApp1.views | post                 | Line 533  | Error while processing document.
Traceback (most recent call last):
  File "D:\IDP_Project\ImageExtraction\ImageApp1\vertex_model.py", line 177, in call_gemini_api
    response.raise_for_status()
  File "C:\Users\pooja.akolkar\AppData\Local\anaconda3\Lib\site-packages\requests\models.py", line 1024, in raise_for_status
    raise HTTPError(http_error_msg, response=self)
requests.exceptions.HTTPError: 429 Client Error: Too Many Requests for url: https://us-central1-aiplatform.googleapis.com/v1/projects/vdxexccenter/locations/us-central1/publishers/google/models/gemini-2.5-pro:generateContent

During handling of the above exception, another exception occurred:

Traceback (most recent call last):
  File "D:\IDP_Project\ImageExtraction\ImageApp1\views.py", line 488, in post
    html_response = call_gemini_api(
                    ^^^^^^^^^^^^^^^^
  File "D:\IDP_Project\ImageExtraction\ImageApp1\vertex_model.py", line 183, in call_gemini_api
    raise Exception(error_msg)
Exception: API request failed: 429 Client Error: Too Many Requests for url: https://us-central1-aiplatform.googleapis.com/v1/projects/vdxexccenter/locations/us-central1/publishers/google/models/gemini-2.5-pro:generateContent
Response: {
  "error": {
    "code": 429,
    "message": "Resource exhausted. Please try again later. Please refer to https://cloud.google.com/vertex-ai/generative-ai/docs/error-code-429 for more details.",
    "status": "RESOURCE_EXHAUSTED"
  }
}

2025-06-27 14:22:51,594 | ERROR    | ImageApp1.views | log_exception        | Line 71   | Exception occurred in D:\IDP_Project\ImageExtraction\ImageApp1\views.py, line 488: html_response = call_gemini_api(
2025-06-27 14:22:51,594 | ERROR    | ImageApp1.views | log_exception        | Line 71   | Exception occurred in D:\IDP_Project\ImageExtraction\ImageApp1\vertex_model.py, line 183: raise Exception(error_msg)
2025-06-27 14:22:51,598 | ERROR    |  django.request | log_response         | Line 253  | Internal Server Error: /IDA/upload/
2025-06-27 14:23:18,260 | INFO     | django.utils.autoreload | run_with_reloader    | Line 667  | Watching for file changes with StatReloader
2025-06-27 14:24:06,767 | INFO     | django.utils.autoreload | run_with_reloader    | Line 667  | Watching for file changes with StatReloader
2025-06-27 14:24:32,174 | INFO     | ImageApp1.views | post                 | Line 302  | Upload request received
2025-06-27 14:24:32,504 | DEBUG    | urllib3.connectionpool | _new_conn            | Line 1052 | Starting new HTTPS connection (1): oauth2.googleapis.com:443
2025-06-27 14:24:32,776 | DEBUG    | urllib3.connectionpool | _make_request        | Line 546  | https://oauth2.googleapis.com:443 "POST /token HTTP/1.1" 200 None
2025-06-27 14:24:32,851 | DEBUG    | urllib3.connectionpool | _new_conn            | Line 1052 | Starting new HTTPS connection (1): us-central1-aiplatform.googleapis.com:443
2025-06-27 14:24:48,537 | DEBUG    | urllib3.connectionpool | _make_request        | Line 546  | https://us-central1-aiplatform.googleapis.com:443 "POST /v1/projects/vdxexccenter/locations/us-central1/publishers/google/models/gemini-2.5-pro:generateContent HTTP/1.1" 200 None
2025-06-27 14:24:48,552 | INFO     |            root | post                 | Line 477  | Input tokens: 1563, Output tokens: 141
2025-06-27 14:24:48,728 | DEBUG    | urllib3.connectionpool | _new_conn            | Line 1052 | Starting new HTTPS connection (1): oauth2.googleapis.com:443
2025-06-27 14:24:48,967 | DEBUG    | urllib3.connectionpool | _make_request        | Line 546  | https://oauth2.googleapis.com:443 "POST /token HTTP/1.1" 200 None
2025-06-27 14:24:48,975 | DEBUG    | urllib3.connectionpool | _new_conn            | Line 1052 | Starting new HTTPS connection (1): us-central1-aiplatform.googleapis.com:443
2025-06-27 14:25:30,168 | DEBUG    | urllib3.connectionpool | _make_request        | Line 546  | https://us-central1-aiplatform.googleapis.com:443 "POST /v1/projects/vdxexccenter/locations/us-central1/publishers/google/models/gemini-2.5-pro:generateContent HTTP/1.1" 200 None
2025-06-27 14:25:30,200 | INFO     | ImageApp1.views | post                 | Line 524  | Document processed and saved successfully. Document ID: gAAAAABoXlyCm18b3S7s7cO5J3JPvzXotdjLvtnM37Cr8osW_h9zTcSk8qRDsOJep_XNMpFe9ufkdf5ArnvCblz4CSN_eEcryg==
2025-06-27 14:26:29,503 | INFO     | ImageApp1.views | post                 | Line 302  | Upload request received
2025-06-27 14:26:29,691 | DEBUG    | urllib3.connectionpool | _new_conn            | Line 1052 | Starting new HTTPS connection (1): oauth2.googleapis.com:443
2025-06-27 14:26:30,125 | DEBUG    | urllib3.connectionpool | _make_request        | Line 546  | https://oauth2.googleapis.com:443 "POST /token HTTP/1.1" 200 None
2025-06-27 14:26:30,191 | DEBUG    | urllib3.connectionpool | _new_conn            | Line 1052 | Starting new HTTPS connection (1): us-central1-aiplatform.googleapis.com:443
2025-06-27 14:27:04,317 | DEBUG    | urllib3.connectionpool | _make_request        | Line 546  | https://us-central1-aiplatform.googleapis.com:443 "POST /v1/projects/vdxexccenter/locations/us-central1/publishers/google/models/gemini-2.5-pro:generateContent HTTP/1.1" 200 None
2025-06-27 14:27:04,589 | DEBUG    | urllib3.connectionpool | _new_conn            | Line 1052 | Starting new HTTPS connection (1): oauth2.googleapis.com:443
2025-06-27 14:27:04,857 | DEBUG    | urllib3.connectionpool | _make_request        | Line 546  | https://oauth2.googleapis.com:443 "POST /token HTTP/1.1" 200 None
2025-06-27 14:27:04,871 | DEBUG    | urllib3.connectionpool | _new_conn            | Line 1052 | Starting new HTTPS connection (1): us-central1-aiplatform.googleapis.com:443
2025-06-27 14:27:43,579 | DEBUG    | urllib3.connectionpool | _make_request        | Line 546  | https://us-central1-aiplatform.googleapis.com:443 "POST /v1/projects/vdxexccenter/locations/us-central1/publishers/google/models/gemini-2.5-pro:generateContent HTTP/1.1" 200 None
2025-06-27 14:27:43,630 | INFO     | ImageApp1.views | post                 | Line 524  | Document processed and saved successfully. Document ID: gAAAAABoXl0Hr9Wi69g78JYUKiQ4mQ15Bx6tBIBsyy_5WE2DBkYvFKMd2y_jnY7eyyIFUcYsVg9oCHKhDdiU2dDgal6-jBw5Aw==
2025-06-27 15:45:24,354 | INFO     | django.utils.autoreload | run_with_reloader    | Line 667  | Watching for file changes with StatReloader
2025-06-27 15:46:08,264 | INFO     | authentication.views | post                 | Line 97   | Login attempt received.
2025-06-27 15:46:36,316 | INFO     | authentication.views | post                 | Line 114  | Login successful for user: abc
2025-06-27 15:47:25,026 | INFO     | ImageApp1.views | post                 | Line 302  | Upload request received
2025-06-27 15:47:25,073 | ERROR    | ImageApp1.views | post                 | Line 532  | 500
Traceback (most recent call last):
  File "D:\IDP_Project\ImageExtraction\ImageApp1\views.py", line 399, in post
    response = call_gemini_api(
               ^^^^^^^^^^^^^^^^
  File "D:\IDP_Project\ImageExtraction\ImageApp1\vertex_model.py", line 129, in call_gemini_api
    access_token, project_id = get_auth_details(service_account_key_path, scopes)
                               ^^^^^^^^^^^^^^^^^^^^^^^^^^^^^^^^^^^^^^^^^^^^^^^^^^
  File "D:\IDP_Project\ImageExtraction\ImageApp1\vertex_model.py", line 38, in get_auth_details
    raise FileNotFoundError(f"Service account key file not found at: {service_account_key_path}")
FileNotFoundError: Service account key file not found at: vdxexccenter-4b1dff9ce849.json
2025-06-27 15:47:25,105 | ERROR    | ImageApp1.views | post                 | Line 533  | Error while processing document.
Traceback (most recent call last):
  File "D:\IDP_Project\ImageExtraction\ImageApp1\views.py", line 399, in post
    response = call_gemini_api(
               ^^^^^^^^^^^^^^^^
  File "D:\IDP_Project\ImageExtraction\ImageApp1\vertex_model.py", line 129, in call_gemini_api
    access_token, project_id = get_auth_details(service_account_key_path, scopes)
                               ^^^^^^^^^^^^^^^^^^^^^^^^^^^^^^^^^^^^^^^^^^^^^^^^^^
  File "D:\IDP_Project\ImageExtraction\ImageApp1\vertex_model.py", line 38, in get_auth_details
    raise FileNotFoundError(f"Service account key file not found at: {service_account_key_path}")
FileNotFoundError: Service account key file not found at: vdxexccenter-4b1dff9ce849.json
2025-06-27 15:47:25,130 | ERROR    | ImageApp1.views | log_exception        | Line 71   | Exception occurred in D:\IDP_Project\ImageExtraction\ImageApp1\views.py, line 399: response = call_gemini_api(
2025-06-27 15:47:25,131 | ERROR    | ImageApp1.views | log_exception        | Line 71   | Exception occurred in D:\IDP_Project\ImageExtraction\ImageApp1\vertex_model.py, line 129: access_token, project_id = get_auth_details(service_account_key_path, scopes)
2025-06-27 15:47:25,134 | ERROR    | ImageApp1.views | log_exception        | Line 71   | Exception occurred in D:\IDP_Project\ImageExtraction\ImageApp1\vertex_model.py, line 38: raise FileNotFoundError(f"Service account key file not found at: {service_account_key_path}")
2025-06-27 15:47:25,162 | ERROR    |  django.request | log_response         | Line 253  | Internal Server Error: /IDA/upload/
2025-06-27 15:48:47,736 | INFO     | ImageApp1.views | post                 | Line 302  | Upload request received
2025-06-27 15:48:47,791 | ERROR    | ImageApp1.views | post                 | Line 532  | 500
Traceback (most recent call last):
  File "D:\IDP_Project\ImageExtraction\ImageApp1\views.py", line 399, in post
    response = call_gemini_api(
               ^^^^^^^^^^^^^^^^
  File "D:\IDP_Project\ImageExtraction\ImageApp1\vertex_model.py", line 129, in call_gemini_api
    access_token, project_id = get_auth_details(service_account_key_path, scopes)
                               ^^^^^^^^^^^^^^^^^^^^^^^^^^^^^^^^^^^^^^^^^^^^^^^^^^
  File "D:\IDP_Project\ImageExtraction\ImageApp1\vertex_model.py", line 38, in get_auth_details
    raise FileNotFoundError(f"Service account key file not found at: {service_account_key_path}")
FileNotFoundError: Service account key file not found at: vdxexccenter-4b1dff9ce849.json
2025-06-27 15:48:47,796 | ERROR    | ImageApp1.views | post                 | Line 533  | Error while processing document.
Traceback (most recent call last):
  File "D:\IDP_Project\ImageExtraction\ImageApp1\views.py", line 399, in post
    response = call_gemini_api(
               ^^^^^^^^^^^^^^^^
  File "D:\IDP_Project\ImageExtraction\ImageApp1\vertex_model.py", line 129, in call_gemini_api
    access_token, project_id = get_auth_details(service_account_key_path, scopes)
                               ^^^^^^^^^^^^^^^^^^^^^^^^^^^^^^^^^^^^^^^^^^^^^^^^^^
  File "D:\IDP_Project\ImageExtraction\ImageApp1\vertex_model.py", line 38, in get_auth_details
    raise FileNotFoundError(f"Service account key file not found at: {service_account_key_path}")
FileNotFoundError: Service account key file not found at: vdxexccenter-4b1dff9ce849.json
2025-06-27 15:48:47,816 | ERROR    | ImageApp1.views | log_exception        | Line 71   | Exception occurred in D:\IDP_Project\ImageExtraction\ImageApp1\views.py, line 399: response = call_gemini_api(
2025-06-27 15:48:47,820 | ERROR    | ImageApp1.views | log_exception        | Line 71   | Exception occurred in D:\IDP_Project\ImageExtraction\ImageApp1\vertex_model.py, line 129: access_token, project_id = get_auth_details(service_account_key_path, scopes)
2025-06-27 15:48:47,829 | ERROR    | ImageApp1.views | log_exception        | Line 71   | Exception occurred in D:\IDP_Project\ImageExtraction\ImageApp1\vertex_model.py, line 38: raise FileNotFoundError(f"Service account key file not found at: {service_account_key_path}")
2025-06-27 15:48:47,836 | ERROR    |  django.request | log_response         | Line 253  | Internal Server Error: /IDA/upload/
2025-06-27 15:49:11,392 | INFO     | ImageApp1.views | post                 | Line 302  | Upload request received
2025-06-27 15:49:11,439 | ERROR    | ImageApp1.views | post                 | Line 532  | 500
Traceback (most recent call last):
  File "D:\IDP_Project\ImageExtraction\ImageApp1\views.py", line 399, in post
    response = call_gemini_api(
               ^^^^^^^^^^^^^^^^
  File "D:\IDP_Project\ImageExtraction\ImageApp1\vertex_model.py", line 129, in call_gemini_api
    access_token, project_id = get_auth_details(service_account_key_path, scopes)
                               ^^^^^^^^^^^^^^^^^^^^^^^^^^^^^^^^^^^^^^^^^^^^^^^^^^
  File "D:\IDP_Project\ImageExtraction\ImageApp1\vertex_model.py", line 38, in get_auth_details
    raise FileNotFoundError(f"Service account key file not found at: {service_account_key_path}")
FileNotFoundError: Service account key file not found at: vdxexccenter-4b1dff9ce849.json
2025-06-27 15:49:11,451 | ERROR    | ImageApp1.views | post                 | Line 533  | Error while processing document.
Traceback (most recent call last):
  File "D:\IDP_Project\ImageExtraction\ImageApp1\views.py", line 399, in post
    response = call_gemini_api(
               ^^^^^^^^^^^^^^^^
  File "D:\IDP_Project\ImageExtraction\ImageApp1\vertex_model.py", line 129, in call_gemini_api
    access_token, project_id = get_auth_details(service_account_key_path, scopes)
                               ^^^^^^^^^^^^^^^^^^^^^^^^^^^^^^^^^^^^^^^^^^^^^^^^^^
  File "D:\IDP_Project\ImageExtraction\ImageApp1\vertex_model.py", line 38, in get_auth_details
    raise FileNotFoundError(f"Service account key file not found at: {service_account_key_path}")
FileNotFoundError: Service account key file not found at: vdxexccenter-4b1dff9ce849.json
2025-06-27 15:49:11,473 | ERROR    | ImageApp1.views | log_exception        | Line 71   | Exception occurred in D:\IDP_Project\ImageExtraction\ImageApp1\views.py, line 399: response = call_gemini_api(
2025-06-27 15:49:11,477 | ERROR    | ImageApp1.views | log_exception        | Line 71   | Exception occurred in D:\IDP_Project\ImageExtraction\ImageApp1\vertex_model.py, line 129: access_token, project_id = get_auth_details(service_account_key_path, scopes)
2025-06-27 15:49:11,484 | ERROR    | ImageApp1.views | log_exception        | Line 71   | Exception occurred in D:\IDP_Project\ImageExtraction\ImageApp1\vertex_model.py, line 38: raise FileNotFoundError(f"Service account key file not found at: {service_account_key_path}")
2025-06-27 15:49:11,495 | ERROR    |  django.request | log_response         | Line 253  | Internal Server Error: /IDA/upload/
2025-06-27 15:49:35,668 | INFO     | authentication.views | post                 | Line 97   | Login attempt received.
2025-06-27 15:49:42,929 | INFO     | authentication.views | post                 | Line 114  | Login successful for user: abc
2025-06-27 15:50:11,704 | INFO     | ImageApp1.views | post                 | Line 302  | Upload request received
2025-06-27 15:50:12,388 | ERROR    | ImageApp1.views | post                 | Line 532  | 500
Traceback (most recent call last):
  File "D:\IDP_Project\ImageExtraction\ImageApp1\views.py", line 399, in post
    response = call_gemini_api(
               ^^^^^^^^^^^^^^^^
  File "D:\IDP_Project\ImageExtraction\ImageApp1\vertex_model.py", line 129, in call_gemini_api
    access_token, project_id = get_auth_details(service_account_key_path, scopes)
                               ^^^^^^^^^^^^^^^^^^^^^^^^^^^^^^^^^^^^^^^^^^^^^^^^^^
  File "D:\IDP_Project\ImageExtraction\ImageApp1\vertex_model.py", line 38, in get_auth_details
    raise FileNotFoundError(f"Service account key file not found at: {service_account_key_path}")
FileNotFoundError: Service account key file not found at: vdxexccenter-4b1dff9ce849.json
2025-06-27 15:50:12,395 | ERROR    | ImageApp1.views | post                 | Line 533  | Error while processing document.
Traceback (most recent call last):
  File "D:\IDP_Project\ImageExtraction\ImageApp1\views.py", line 399, in post
    response = call_gemini_api(
               ^^^^^^^^^^^^^^^^
  File "D:\IDP_Project\ImageExtraction\ImageApp1\vertex_model.py", line 129, in call_gemini_api
    access_token, project_id = get_auth_details(service_account_key_path, scopes)
                               ^^^^^^^^^^^^^^^^^^^^^^^^^^^^^^^^^^^^^^^^^^^^^^^^^^
  File "D:\IDP_Project\ImageExtraction\ImageApp1\vertex_model.py", line 38, in get_auth_details
    raise FileNotFoundError(f"Service account key file not found at: {service_account_key_path}")
FileNotFoundError: Service account key file not found at: vdxexccenter-4b1dff9ce849.json
2025-06-27 15:50:12,407 | ERROR    | ImageApp1.views | log_exception        | Line 71   | Exception occurred in D:\IDP_Project\ImageExtraction\ImageApp1\views.py, line 399: response = call_gemini_api(
2025-06-27 15:50:12,409 | ERROR    | ImageApp1.views | log_exception        | Line 71   | Exception occurred in D:\IDP_Project\ImageExtraction\ImageApp1\vertex_model.py, line 129: access_token, project_id = get_auth_details(service_account_key_path, scopes)
2025-06-27 15:50:12,412 | ERROR    | ImageApp1.views | log_exception        | Line 71   | Exception occurred in D:\IDP_Project\ImageExtraction\ImageApp1\vertex_model.py, line 38: raise FileNotFoundError(f"Service account key file not found at: {service_account_key_path}")
2025-06-27 15:50:12,417 | ERROR    |  django.request | log_response         | Line 253  | Internal Server Error: /IDA/upload/
2025-06-27 15:50:16,701 | INFO     | ImageApp1.views | post                 | Line 302  | Upload request received
2025-06-27 15:50:16,730 | ERROR    | ImageApp1.views | post                 | Line 532  | 500
Traceback (most recent call last):
  File "D:\IDP_Project\ImageExtraction\ImageApp1\views.py", line 399, in post
    response = call_gemini_api(
               ^^^^^^^^^^^^^^^^
  File "D:\IDP_Project\ImageExtraction\ImageApp1\vertex_model.py", line 129, in call_gemini_api
    access_token, project_id = get_auth_details(service_account_key_path, scopes)
                               ^^^^^^^^^^^^^^^^^^^^^^^^^^^^^^^^^^^^^^^^^^^^^^^^^^
  File "D:\IDP_Project\ImageExtraction\ImageApp1\vertex_model.py", line 38, in get_auth_details
    raise FileNotFoundError(f"Service account key file not found at: {service_account_key_path}")
FileNotFoundError: Service account key file not found at: vdxexccenter-4b1dff9ce849.json
2025-06-27 15:50:16,733 | ERROR    | ImageApp1.views | post                 | Line 533  | Error while processing document.
Traceback (most recent call last):
  File "D:\IDP_Project\ImageExtraction\ImageApp1\views.py", line 399, in post
    response = call_gemini_api(
               ^^^^^^^^^^^^^^^^
  File "D:\IDP_Project\ImageExtraction\ImageApp1\vertex_model.py", line 129, in call_gemini_api
    access_token, project_id = get_auth_details(service_account_key_path, scopes)
                               ^^^^^^^^^^^^^^^^^^^^^^^^^^^^^^^^^^^^^^^^^^^^^^^^^^
  File "D:\IDP_Project\ImageExtraction\ImageApp1\vertex_model.py", line 38, in get_auth_details
    raise FileNotFoundError(f"Service account key file not found at: {service_account_key_path}")
FileNotFoundError: Service account key file not found at: vdxexccenter-4b1dff9ce849.json
2025-06-27 15:50:16,743 | ERROR    | ImageApp1.views | log_exception        | Line 71   | Exception occurred in D:\IDP_Project\ImageExtraction\ImageApp1\views.py, line 399: response = call_gemini_api(
2025-06-27 15:50:16,744 | ERROR    | ImageApp1.views | log_exception        | Line 71   | Exception occurred in D:\IDP_Project\ImageExtraction\ImageApp1\vertex_model.py, line 129: access_token, project_id = get_auth_details(service_account_key_path, scopes)
2025-06-27 15:50:16,747 | ERROR    | ImageApp1.views | log_exception        | Line 71   | Exception occurred in D:\IDP_Project\ImageExtraction\ImageApp1\vertex_model.py, line 38: raise FileNotFoundError(f"Service account key file not found at: {service_account_key_path}")
2025-06-27 15:50:16,749 | ERROR    |  django.request | log_response         | Line 253  | Internal Server Error: /IDA/upload/
2025-06-27 15:50:21,025 | INFO     | ImageApp1.views | post                 | Line 302  | Upload request received
2025-06-27 15:50:21,085 | ERROR    | ImageApp1.views | post                 | Line 532  | 500
Traceback (most recent call last):
  File "D:\IDP_Project\ImageExtraction\ImageApp1\views.py", line 399, in post
    response = call_gemini_api(
               ^^^^^^^^^^^^^^^^
  File "D:\IDP_Project\ImageExtraction\ImageApp1\vertex_model.py", line 129, in call_gemini_api
    access_token, project_id = get_auth_details(service_account_key_path, scopes)
                               ^^^^^^^^^^^^^^^^^^^^^^^^^^^^^^^^^^^^^^^^^^^^^^^^^^
  File "D:\IDP_Project\ImageExtraction\ImageApp1\vertex_model.py", line 38, in get_auth_details
    raise FileNotFoundError(f"Service account key file not found at: {service_account_key_path}")
FileNotFoundError: Service account key file not found at: vdxexccenter-4b1dff9ce849.json
2025-06-27 15:50:21,094 | ERROR    | ImageApp1.views | post                 | Line 533  | Error while processing document.
Traceback (most recent call last):
  File "D:\IDP_Project\ImageExtraction\ImageApp1\views.py", line 399, in post
    response = call_gemini_api(
               ^^^^^^^^^^^^^^^^
  File "D:\IDP_Project\ImageExtraction\ImageApp1\vertex_model.py", line 129, in call_gemini_api
    access_token, project_id = get_auth_details(service_account_key_path, scopes)
                               ^^^^^^^^^^^^^^^^^^^^^^^^^^^^^^^^^^^^^^^^^^^^^^^^^^
  File "D:\IDP_Project\ImageExtraction\ImageApp1\vertex_model.py", line 38, in get_auth_details
    raise FileNotFoundError(f"Service account key file not found at: {service_account_key_path}")
FileNotFoundError: Service account key file not found at: vdxexccenter-4b1dff9ce849.json
2025-06-27 15:50:21,109 | ERROR    | ImageApp1.views | log_exception        | Line 71   | Exception occurred in D:\IDP_Project\ImageExtraction\ImageApp1\views.py, line 399: response = call_gemini_api(
2025-06-27 15:50:21,111 | ERROR    | ImageApp1.views | log_exception        | Line 71   | Exception occurred in D:\IDP_Project\ImageExtraction\ImageApp1\vertex_model.py, line 129: access_token, project_id = get_auth_details(service_account_key_path, scopes)
2025-06-27 15:50:21,125 | ERROR    | ImageApp1.views | log_exception        | Line 71   | Exception occurred in D:\IDP_Project\ImageExtraction\ImageApp1\vertex_model.py, line 38: raise FileNotFoundError(f"Service account key file not found at: {service_account_key_path}")
2025-06-27 15:50:21,129 | ERROR    |  django.request | log_response         | Line 253  | Internal Server Error: /IDA/upload/
2025-06-27 15:51:15,830 | INFO     | django.utils.autoreload | run_with_reloader    | Line 667  | Watching for file changes with StatReloader
2025-06-27 15:51:56,771 | INFO     | django.utils.autoreload | run_with_reloader    | Line 667  | Watching for file changes with StatReloader
2025-06-27 15:54:10,447 | INFO     | authentication.views | post                 | Line 97   | Login attempt received.
2025-06-27 15:54:20,913 | INFO     | authentication.views | post                 | Line 114  | Login successful for user: abc
2025-06-27 15:54:55,534 | INFO     | ImageApp1.views | post                 | Line 302  | Upload request received
2025-06-27 15:55:07,419 | DEBUG    | urllib3.connectionpool | _new_conn            | Line 1052 | Starting new HTTPS connection (1): oauth2.googleapis.com:443
2025-06-27 15:55:07,910 | DEBUG    | urllib3.connectionpool | _make_request        | Line 546  | https://oauth2.googleapis.com:443 "POST /token HTTP/1.1" 200 None
2025-06-27 15:55:09,101 | DEBUG    | urllib3.connectionpool | _new_conn            | Line 1052 | Starting new HTTPS connection (1): us-central1-aiplatform.googleapis.com:443
2025-06-27 15:57:39,018 | DEBUG    | urllib3.connectionpool | _make_request        | Line 546  | https://us-central1-aiplatform.googleapis.com:443 "POST /v1/projects/vdxexccenter/locations/us-central1/publishers/google/models/gemini-2.5-pro:generateContent HTTP/1.1" 200 None
2025-06-27 15:57:39,303 | DEBUG    | urllib3.connectionpool | _new_conn            | Line 1052 | Starting new HTTPS connection (1): oauth2.googleapis.com:443
2025-06-27 15:57:39,587 | DEBUG    | urllib3.connectionpool | _make_request        | Line 546  | https://oauth2.googleapis.com:443 "POST /token HTTP/1.1" 200 None
2025-06-27 15:57:39,605 | DEBUG    | urllib3.connectionpool | _new_conn            | Line 1052 | Starting new HTTPS connection (1): us-central1-aiplatform.googleapis.com:443
2025-06-27 15:59:30,618 | DEBUG    | urllib3.connectionpool | _make_request        | Line 546  | https://us-central1-aiplatform.googleapis.com:443 "POST /v1/projects/vdxexccenter/locations/us-central1/publishers/google/models/gemini-2.5-pro:generateContent HTTP/1.1" 200 None
2025-06-27 15:59:30,812 | INFO     | ImageApp1.views | post                 | Line 524  | Document processed and saved successfully. Document ID: gAAAAABoXnKKcG-KQjBCx9jo6rNq8iX0ONe_FYVEo6uGB_nuS8j9HkGmsFHfCSNwX9vHdU2NQYuEUbW1cSrnVGpv2lZK5DRG6g==
2025-06-27 16:01:22,270 | INFO     | ImageApp1.views | get                  | Line 91   | GetDocumentByIdView called with encrypted ID: gAAAAABoXnKKcG-KQjBCx9jo6rNq8iX0ONe_FYVEo6uGB_nuS8j9HkGmsFHfCSNwX9vHdU2NQYuEUbW1cSrnVGpv2lZK5DRG6g==
2025-06-27 16:01:22,273 | DEBUG    | ImageApp1.views | get                  | Line 95   | Decrypted ID: 197
2025-06-27 16:01:22,334 | INFO     | ImageApp1.views | get                  | Line 99   | Document 197 retrieved successfully
2025-06-27 16:28:15,931 | INFO     | django.utils.autoreload | trigger_reload       | Line 265  | D:\IDP_Project\ImageExtraction\ImageExtraction\logger.py changed, reloading.
2025-06-27 16:28:24,023 | INFO     | django.utils.autoreload | run_with_reloader    | Line 667  | Watching for file changes with StatReloader
2025-06-27 16:33:51,628 | INFO     | django.utils.autoreload | trigger_reload       | Line 265  | D:\IDP_Project\ImageExtraction\authentication\views.py changed, reloading.
2025-06-27 16:34:00,571 | INFO     | django.utils.autoreload | run_with_reloader    | Line 667  | Watching for file changes with StatReloader
2025-06-27 18:47:42,616 | INFO     | django.utils.autoreload | trigger_reload       | Line 265  | D:\IDP_Project\ImageExtraction\ImageExtraction\settings.py changed, reloading.
2025-06-27 18:48:07,847 | INFO     | django.utils.autoreload | run_with_reloader    | Line 667  | Watching for file changes with StatReloader
2025-06-27 18:49:45,918 | INFO     | django.utils.autoreload | trigger_reload       | Line 265  | D:\IDP_Project\ImageExtraction\ImageExtraction\settings.py changed, reloading.
2025-06-27 18:50:01,079 | INFO     | django.utils.autoreload | run_with_reloader    | Line 667  | Watching for file changes with StatReloader
2025-06-27 19:01:55,971 | INFO     | django.utils.autoreload | trigger_reload       | Line 265  | D:\IDP_Project\ImageExtraction\ImageApp1\vertex_model.py changed, reloading.
2025-06-27 19:01:57,946 | INFO     | django.utils.autoreload | run_with_reloader    | Line 667  | Watching for file changes with StatReloader
2025-06-27 19:03:13,160 | INFO     | django.utils.autoreload | trigger_reload       | Line 265  | D:\IDP_Project\ImageExtraction\ImageApp1\vertex_model.py changed, reloading.
2025-06-27 19:03:15,047 | INFO     | django.utils.autoreload | run_with_reloader    | Line 667  | Watching for file changes with StatReloader
2025-06-27 19:05:17,354 | INFO     | django.utils.autoreload | run_with_reloader    | Line 667  | Watching for file changes with StatReloader
2025-06-27 19:07:21,040 | INFO     | django.utils.autoreload | run_with_reloader    | Line 667  | Watching for file changes with StatReloader
2025-06-27 19:07:39,449 | DEBUG    | google.cloud.storage._opentelemetry_tracing | <module>             | Line 42   | This service is instrumented using OpenTelemetry. OpenTelemetry or one of its components could not be imported; please add compatible versions of opentelemetry-api and opentelemetry-instrumentation packages in order to get Storage Tracing data.
2025-06-27 19:08:10,524 | INFO     | authentication.views | post                 | Line 96   | Login attempt received.
2025-06-27 19:08:12,537 | INFO     | authentication.views | post                 | Line 113  | Login successful for user: abc
2025-06-27 19:09:39,247 | INFO     | ImageApp1.views | post                 | Line 302  | Upload request received
2025-06-27 19:11:46,702 | ERROR    | ImageApp1.views | post                 | Line 532  | 500
Traceback (most recent call last):
  File "D:\IDP_Project\ImageExtraction\ImageApp1\views.py", line 405, in post
    parsed_json = json.loads(result)
                  ^^^^^^^^^^^^^^^^^^
  File "C:\Users\pooja.akolkar\AppData\Local\anaconda3\Lib\json\__init__.py", line 346, in loads
    return _default_decoder.decode(s)
           ^^^^^^^^^^^^^^^^^^^^^^^^^^
  File "C:\Users\pooja.akolkar\AppData\Local\anaconda3\Lib\json\decoder.py", line 337, in decode
    obj, end = self.raw_decode(s, idx=_w(s, 0).end())
               ^^^^^^^^^^^^^^^^^^^^^^^^^^^^^^^^^^^^^^
  File "C:\Users\pooja.akolkar\AppData\Local\anaconda3\Lib\json\decoder.py", line 355, in raw_decode
    raise JSONDecodeError("Expecting value", s, err.value) from None
json.decoder.JSONDecodeError: Expecting value: line 1 column 1 (char 0)
2025-06-27 19:11:46,725 | ERROR    | ImageApp1.views | post                 | Line 533  | Error while processing document.
Traceback (most recent call last):
  File "D:\IDP_Project\ImageExtraction\ImageApp1\views.py", line 405, in post
    parsed_json = json.loads(result)
                  ^^^^^^^^^^^^^^^^^^
  File "C:\Users\pooja.akolkar\AppData\Local\anaconda3\Lib\json\__init__.py", line 346, in loads
    return _default_decoder.decode(s)
           ^^^^^^^^^^^^^^^^^^^^^^^^^^
  File "C:\Users\pooja.akolkar\AppData\Local\anaconda3\Lib\json\decoder.py", line 337, in decode
    obj, end = self.raw_decode(s, idx=_w(s, 0).end())
               ^^^^^^^^^^^^^^^^^^^^^^^^^^^^^^^^^^^^^^
  File "C:\Users\pooja.akolkar\AppData\Local\anaconda3\Lib\json\decoder.py", line 355, in raw_decode
    raise JSONDecodeError("Expecting value", s, err.value) from None
json.decoder.JSONDecodeError: Expecting value: line 1 column 1 (char 0)
2025-06-27 19:11:46,734 | ERROR    | ImageApp1.views | log_exception        | Line 71   | Exception occurred in D:\IDP_Project\ImageExtraction\ImageApp1\views.py, line 405: parsed_json = json.loads(result)
2025-06-27 19:11:46,734 | ERROR    | ImageApp1.views | log_exception        | Line 71   | Exception occurred in C:\Users\pooja.akolkar\AppData\Local\anaconda3\Lib\json\__init__.py, line 346: return _default_decoder.decode(s)
2025-06-27 19:11:46,735 | ERROR    | ImageApp1.views | log_exception        | Line 71   | Exception occurred in C:\Users\pooja.akolkar\AppData\Local\anaconda3\Lib\json\decoder.py, line 337: obj, end = self.raw_decode(s, idx=_w(s, 0).end())
2025-06-27 19:11:46,736 | ERROR    | ImageApp1.views | log_exception        | Line 71   | Exception occurred in C:\Users\pooja.akolkar\AppData\Local\anaconda3\Lib\json\decoder.py, line 355: raise JSONDecodeError("Expecting value", s, err.value) from None
2025-06-27 19:11:46,738 | ERROR    |  django.request | log_response         | Line 253  | Internal Server Error: /IDA/upload/
2025-06-27 19:13:42,280 | INFO     | ImageApp1.views | post                 | Line 302  | Upload request received
2025-06-27 19:13:12,539 | INFO     | django.utils.autoreload | trigger_reload       | Line 265  | D:\IDP_Project\ImageExtraction\ImageApp1\views.py changed, reloading.
2025-06-27 19:14:15,606 | INFO     | django.utils.autoreload | run_with_reloader    | Line 667  | Watching for file changes with StatReloader
2025-06-27 19:15:16,042 | INFO     | django.utils.autoreload | run_with_reloader    | Line 667  | Watching for file changes with StatReloader
2025-06-27 19:15:22,311 | DEBUG    | google.cloud.storage._opentelemetry_tracing | <module>             | Line 42   | This service is instrumented using OpenTelemetry. OpenTelemetry or one of its components could not be imported; please add compatible versions of opentelemetry-api and opentelemetry-instrumentation packages in order to get Storage Tracing data.
2025-06-27 19:15:33,644 | INFO     | ImageApp1.views | post                 | Line 302  | Upload request received
2025-06-27 19:17:59,019 | ERROR    | ImageApp1.views | post                 | Line 533  | 500
Traceback (most recent call last):
  File "D:\IDP_Project\ImageExtraction\ImageApp1\views.py", line 406, in post
    parsed_json = json.loads(result)
                  ^^^^^^^^^^^^^^^^^^
  File "C:\Users\pooja.akolkar\AppData\Local\anaconda3\Lib\json\__init__.py", line 346, in loads
    return _default_decoder.decode(s)
           ^^^^^^^^^^^^^^^^^^^^^^^^^^
  File "C:\Users\pooja.akolkar\AppData\Local\anaconda3\Lib\json\decoder.py", line 337, in decode
    obj, end = self.raw_decode(s, idx=_w(s, 0).end())
               ^^^^^^^^^^^^^^^^^^^^^^^^^^^^^^^^^^^^^^
  File "C:\Users\pooja.akolkar\AppData\Local\anaconda3\Lib\json\decoder.py", line 355, in raw_decode
    raise JSONDecodeError("Expecting value", s, err.value) from None
json.decoder.JSONDecodeError: Expecting value: line 1 column 1 (char 0)
2025-06-27 19:17:59,028 | ERROR    | ImageApp1.views | post                 | Line 534  | Error while processing document.
Traceback (most recent call last):
  File "D:\IDP_Project\ImageExtraction\ImageApp1\views.py", line 406, in post
    parsed_json = json.loads(result)
                  ^^^^^^^^^^^^^^^^^^
  File "C:\Users\pooja.akolkar\AppData\Local\anaconda3\Lib\json\__init__.py", line 346, in loads
    return _default_decoder.decode(s)
           ^^^^^^^^^^^^^^^^^^^^^^^^^^
  File "C:\Users\pooja.akolkar\AppData\Local\anaconda3\Lib\json\decoder.py", line 337, in decode
    obj, end = self.raw_decode(s, idx=_w(s, 0).end())
               ^^^^^^^^^^^^^^^^^^^^^^^^^^^^^^^^^^^^^^
  File "C:\Users\pooja.akolkar\AppData\Local\anaconda3\Lib\json\decoder.py", line 355, in raw_decode
    raise JSONDecodeError("Expecting value", s, err.value) from None
json.decoder.JSONDecodeError: Expecting value: line 1 column 1 (char 0)
2025-06-27 19:17:59,031 | ERROR    | ImageApp1.views | log_exception        | Line 71   | Exception occurred in D:\IDP_Project\ImageExtraction\ImageApp1\views.py, line 406: parsed_json = json.loads(result)
2025-06-27 19:17:59,032 | ERROR    | ImageApp1.views | log_exception        | Line 71   | Exception occurred in C:\Users\pooja.akolkar\AppData\Local\anaconda3\Lib\json\__init__.py, line 346: return _default_decoder.decode(s)
2025-06-27 19:17:59,032 | ERROR    | ImageApp1.views | log_exception        | Line 71   | Exception occurred in C:\Users\pooja.akolkar\AppData\Local\anaconda3\Lib\json\decoder.py, line 337: obj, end = self.raw_decode(s, idx=_w(s, 0).end())
2025-06-27 19:17:59,033 | ERROR    | ImageApp1.views | log_exception        | Line 71   | Exception occurred in C:\Users\pooja.akolkar\AppData\Local\anaconda3\Lib\json\decoder.py, line 355: raise JSONDecodeError("Expecting value", s, err.value) from None
2025-06-27 19:17:59,034 | ERROR    |  django.request | log_response         | Line 253  | Internal Server Error: /IDA/upload/
2025-06-27 19:23:32,136 | INFO     | django.utils.autoreload | trigger_reload       | Line 265  | D:\IDP_Project\ImageExtraction\ImageApp1\views.py changed, reloading.
2025-06-27 19:23:34,527 | INFO     | django.utils.autoreload | run_with_reloader    | Line 667  | Watching for file changes with StatReloader
2025-06-27 19:23:42,668 | DEBUG    | google.cloud.storage._opentelemetry_tracing | <module>             | Line 42   | This service is instrumented using OpenTelemetry. OpenTelemetry or one of its components could not be imported; please add compatible versions of opentelemetry-api and opentelemetry-instrumentation packages in order to get Storage Tracing data.
2025-06-27 19:24:33,033 | INFO     | django.utils.autoreload | trigger_reload       | Line 265  | D:\IDP_Project\ImageExtraction\ImageApp1\views.py changed, reloading.
2025-06-27 19:24:35,705 | INFO     | django.utils.autoreload | run_with_reloader    | Line 667  | Watching for file changes with StatReloader
2025-06-27 19:24:41,954 | INFO     | django.utils.autoreload | run_with_reloader    | Line 667  | Watching for file changes with StatReloader
2025-06-27 19:24:48,725 | DEBUG    | google.cloud.storage._opentelemetry_tracing | <module>             | Line 42   | This service is instrumented using OpenTelemetry. OpenTelemetry or one of its components could not be imported; please add compatible versions of opentelemetry-api and opentelemetry-instrumentation packages in order to get Storage Tracing data.
2025-06-27 19:24:57,476 | INFO     | ImageApp1.views | post                 | Line 302  | Upload request received
2025-06-27 19:26:24,901 | INFO     | ImageApp1.views | post                 | Line 302  | Upload request received
2025-06-27 19:27:05,866 | ERROR    | ImageApp1.views | post                 | Line 411  | JSON decode error: Expecting value: line 1 column 1 (char 0)
Traceback (most recent call last):
  File "D:\IDP_Project\ImageExtraction\ImageApp1\views.py", line 409, in post
    parsed_json = json.loads(result)
                  ^^^^^^^^^^^^^^^^^^
  File "C:\Users\pooja.akolkar\AppData\Local\anaconda3\Lib\json\__init__.py", line 346, in loads
    return _default_decoder.decode(s)
           ^^^^^^^^^^^^^^^^^^^^^^^^^^
  File "C:\Users\pooja.akolkar\AppData\Local\anaconda3\Lib\json\decoder.py", line 337, in decode
    obj, end = self.raw_decode(s, idx=_w(s, 0).end())
               ^^^^^^^^^^^^^^^^^^^^^^^^^^^^^^^^^^^^^^
  File "C:\Users\pooja.akolkar\AppData\Local\anaconda3\Lib\json\decoder.py", line 355, in raw_decode
    raise JSONDecodeError("Expecting value", s, err.value) from None
json.decoder.JSONDecodeError: Expecting value: line 1 column 1 (char 0)
2025-06-27 19:27:05,873 | WARNING  |  django.request | log_response         | Line 253  | Bad Request: /IDA/upload/
2025-06-27 19:27:31,053 | ERROR    | ImageApp1.views | post                 | Line 411  | JSON decode error: Expecting value: line 1 column 1 (char 0)
Traceback (most recent call last):
  File "D:\IDP_Project\ImageExtraction\ImageApp1\views.py", line 409, in post
    parsed_json = json.loads(result)
                  ^^^^^^^^^^^^^^^^^^
  File "C:\Users\pooja.akolkar\AppData\Local\anaconda3\Lib\json\__init__.py", line 346, in loads
    return _default_decoder.decode(s)
           ^^^^^^^^^^^^^^^^^^^^^^^^^^
  File "C:\Users\pooja.akolkar\AppData\Local\anaconda3\Lib\json\decoder.py", line 337, in decode
    obj, end = self.raw_decode(s, idx=_w(s, 0).end())
               ^^^^^^^^^^^^^^^^^^^^^^^^^^^^^^^^^^^^^^
  File "C:\Users\pooja.akolkar\AppData\Local\anaconda3\Lib\json\decoder.py", line 355, in raw_decode
    raise JSONDecodeError("Expecting value", s, err.value) from None
json.decoder.JSONDecodeError: Expecting value: line 1 column 1 (char 0)
2025-06-27 19:27:31,055 | WARNING  |  django.request | log_response         | Line 253  | Bad Request: /IDA/upload/
2025-06-27 19:31:30,519 | INFO     | django.utils.autoreload | trigger_reload       | Line 265  | D:\IDP_Project\ImageExtraction\ImageApp1\views.py changed, reloading.
2025-06-27 19:31:32,971 | INFO     | django.utils.autoreload | run_with_reloader    | Line 667  | Watching for file changes with StatReloader
2025-06-27 19:31:40,732 | DEBUG    | google.cloud.storage._opentelemetry_tracing | <module>             | Line 42   | This service is instrumented using OpenTelemetry. OpenTelemetry or one of its components could not be imported; please add compatible versions of opentelemetry-api and opentelemetry-instrumentation packages in order to get Storage Tracing data.
2025-06-27 19:33:01,161 | INFO     | django.utils.autoreload | trigger_reload       | Line 265  | D:\IDP_Project\ImageExtraction\ImageApp1\views.py changed, reloading.
2025-06-27 19:33:03,431 | INFO     | django.utils.autoreload | run_with_reloader    | Line 667  | Watching for file changes with StatReloader
2025-06-27 19:33:12,983 | DEBUG    | google.cloud.storage._opentelemetry_tracing | <module>             | Line 42   | This service is instrumented using OpenTelemetry. OpenTelemetry or one of its components could not be imported; please add compatible versions of opentelemetry-api and opentelemetry-instrumentation packages in order to get Storage Tracing data.
2025-06-27 19:33:28,586 | INFO     | django.utils.autoreload | trigger_reload       | Line 265  | D:\IDP_Project\ImageExtraction\ImageApp1\views.py changed, reloading.
2025-06-27 19:33:30,842 | INFO     | django.utils.autoreload | run_with_reloader    | Line 667  | Watching for file changes with StatReloader
2025-06-27 19:33:37,776 | INFO     | django.utils.autoreload | run_with_reloader    | Line 667  | Watching for file changes with StatReloader
2025-06-27 19:33:44,637 | DEBUG    | google.cloud.storage._opentelemetry_tracing | <module>             | Line 42   | This service is instrumented using OpenTelemetry. OpenTelemetry or one of its components could not be imported; please add compatible versions of opentelemetry-api and opentelemetry-instrumentation packages in order to get Storage Tracing data.
2025-06-27 19:33:52,379 | INFO     | ImageApp1.views | post                 | Line 302  | Upload request received
2025-06-27 19:35:02,190 | ERROR    | ImageApp1.views | post                 | Line 548  | 500
Traceback (most recent call last):
  File "D:\IDP_Project\ImageExtraction\ImageApp1\views.py", line 410, in post
    parsed_json = json.loads(result)
                  ^^^^^^^^^^^^^^^^^^
  File "C:\Users\pooja.akolkar\AppData\Local\anaconda3\Lib\json\__init__.py", line 346, in loads
    return _default_decoder.decode(s)
           ^^^^^^^^^^^^^^^^^^^^^^^^^^
  File "C:\Users\pooja.akolkar\AppData\Local\anaconda3\Lib\json\decoder.py", line 337, in decode
    obj, end = self.raw_decode(s, idx=_w(s, 0).end())
               ^^^^^^^^^^^^^^^^^^^^^^^^^^^^^^^^^^^^^^
  File "C:\Users\pooja.akolkar\AppData\Local\anaconda3\Lib\json\decoder.py", line 355, in raw_decode
    raise JSONDecodeError("Expecting value", s, err.value) from None
json.decoder.JSONDecodeError: Expecting value: line 1 column 1 (char 0)
2025-06-27 19:35:02,196 | ERROR    | ImageApp1.views | post                 | Line 549  | Error while processing document.
Traceback (most recent call last):
  File "D:\IDP_Project\ImageExtraction\ImageApp1\views.py", line 410, in post
    parsed_json = json.loads(result)
                  ^^^^^^^^^^^^^^^^^^
  File "C:\Users\pooja.akolkar\AppData\Local\anaconda3\Lib\json\__init__.py", line 346, in loads
    return _default_decoder.decode(s)
           ^^^^^^^^^^^^^^^^^^^^^^^^^^
  File "C:\Users\pooja.akolkar\AppData\Local\anaconda3\Lib\json\decoder.py", line 337, in decode
    obj, end = self.raw_decode(s, idx=_w(s, 0).end())
               ^^^^^^^^^^^^^^^^^^^^^^^^^^^^^^^^^^^^^^
  File "C:\Users\pooja.akolkar\AppData\Local\anaconda3\Lib\json\decoder.py", line 355, in raw_decode
    raise JSONDecodeError("Expecting value", s, err.value) from None
json.decoder.JSONDecodeError: Expecting value: line 1 column 1 (char 0)
2025-06-27 19:35:02,199 | ERROR    | ImageApp1.views | log_exception        | Line 71   | Exception occurred in D:\IDP_Project\ImageExtraction\ImageApp1\views.py, line 410: parsed_json = json.loads(result)
2025-06-27 19:35:02,204 | ERROR    | ImageApp1.views | log_exception        | Line 71   | Exception occurred in C:\Users\pooja.akolkar\AppData\Local\anaconda3\Lib\json\__init__.py, line 346: return _default_decoder.decode(s)
2025-06-27 19:35:02,205 | ERROR    | ImageApp1.views | log_exception        | Line 71   | Exception occurred in C:\Users\pooja.akolkar\AppData\Local\anaconda3\Lib\json\decoder.py, line 337: obj, end = self.raw_decode(s, idx=_w(s, 0).end())
2025-06-27 19:35:02,206 | ERROR    | ImageApp1.views | log_exception        | Line 71   | Exception occurred in C:\Users\pooja.akolkar\AppData\Local\anaconda3\Lib\json\decoder.py, line 355: raise JSONDecodeError("Expecting value", s, err.value) from None
2025-06-27 19:35:02,208 | ERROR    |  django.request | log_response         | Line 253  | Internal Server Error: /IDA/upload/
2025-06-27 19:47:30,211 | INFO     | django.utils.autoreload | run_with_reloader    | Line 667  | Watching for file changes with StatReloader
2025-06-27 19:47:53,292 | DEBUG    | google.cloud.storage._opentelemetry_tracing | <module>             | Line 42   | This service is instrumented using OpenTelemetry. OpenTelemetry or one of its components could not be imported; please add compatible versions of opentelemetry-api and opentelemetry-instrumentation packages in order to get Storage Tracing data.
2025-06-27 19:48:18,952 | INFO     | authentication.views | post                 | Line 96   | Login attempt received.
2025-06-27 19:48:20,116 | INFO     | authentication.views | post                 | Line 113  | Login successful for user: abc
2025-06-27 19:48:50,649 | INFO     | ImageApp1.views | post                 | Line 321  | Upload request received
2025-06-27 19:49:58,253 | ERROR    | ImageApp1.views | post                 | Line 429  | Invalid JSON received. Cannot parse JSON.
NoneType: None
2025-06-27 19:49:58,255 | WARNING  |  django.request | log_response         | Line 253  | Bad Request: /IDA/upload/
2025-06-27 19:53:34,833 | INFO     | django.utils.autoreload | trigger_reload       | Line 265  | D:\IDP_Project\ImageExtraction\ImageApp1\views.py changed, reloading.
2025-06-27 19:53:37,064 | INFO     | django.utils.autoreload | run_with_reloader    | Line 667  | Watching for file changes with StatReloader
2025-06-27 19:54:29,501 | INFO     | django.utils.autoreload | run_with_reloader    | Line 667  | Watching for file changes with StatReloader
2025-06-27 19:54:41,053 | DEBUG    | google.cloud.storage._opentelemetry_tracing | <module>             | Line 42   | This service is instrumented using OpenTelemetry. OpenTelemetry or one of its components could not be imported; please add compatible versions of opentelemetry-api and opentelemetry-instrumentation packages in order to get Storage Tracing data.
2025-06-27 19:54:50,140 | INFO     | ImageApp1.views | post                 | Line 306  | Upload request received
2025-06-27 19:56:23,595 | ERROR    | ImageApp1.views | post                 | Line 547  | 500
Traceback (most recent call last):
  File "D:\IDP_Project\ImageExtraction\ImageApp1\views.py", line 413, in post
    parsed_json = safe_json_load(result)
                  ^^^^^^^^^^^^^^
NameError: name 'safe_json_load' is not defined
2025-06-27 19:56:23,605 | ERROR    | ImageApp1.views | post                 | Line 548  | Error while processing document.
Traceback (most recent call last):
  File "D:\IDP_Project\ImageExtraction\ImageApp1\views.py", line 413, in post
    parsed_json = safe_json_load(result)
                  ^^^^^^^^^^^^^^
NameError: name 'safe_json_load' is not defined
2025-06-27 19:56:23,614 | ERROR    | ImageApp1.views | log_exception        | Line 71   | Exception occurred in D:\IDP_Project\ImageExtraction\ImageApp1\views.py, line 413: parsed_json = safe_json_load(result)
2025-06-27 19:56:23,615 | ERROR    |  django.request | log_response         | Line 253  | Internal Server Error: /IDA/upload/
2025-06-27 19:58:27,412 | INFO     | django.utils.autoreload | trigger_reload       | Line 265  | D:\IDP_Project\ImageExtraction\ImageApp1\views.py changed, reloading.
2025-06-27 19:58:33,185 | INFO     | django.utils.autoreload | run_with_reloader    | Line 667  | Watching for file changes with StatReloader
2025-06-27 19:58:49,479 | DEBUG    | google.cloud.storage._opentelemetry_tracing | <module>             | Line 42   | This service is instrumented using OpenTelemetry. OpenTelemetry or one of its components could not be imported; please add compatible versions of opentelemetry-api and opentelemetry-instrumentation packages in order to get Storage Tracing data.
2025-06-27 19:58:59,731 | INFO     | ImageApp1.views | post                 | Line 306  | Upload request received
