2025-06-24 05:15:41,233 | INFO     | django.utils.autoreload | run_with_reloader    | Line 667  | Watching for file changes with StatReloader
2025-06-24 05:15:46,147 | INFO     | django.utils.autoreload | trigger_reload       | Line 265  | D:\IDP_AI_App\Backend\Django Projects (2)\Django Projects\ImageExtraction\ImageApp1\views.py changed, reloading.
2025-06-24 05:15:47,794 | INFO     | django.utils.autoreload | run_with_reloader    | Line 667  | Watching for file changes with StatReloader
2025-06-24 05:19:57,802 | INFO     | django.utils.autoreload | trigger_reload       | Line 265  | D:\IDP_AI_App\Backend\Django Projects (2)\Django Projects\ImageExtraction\ImageApp1\views.py changed, reloading.
2025-06-24 05:19:59,439 | INFO     | django.utils.autoreload | run_with_reloader    | Line 667  | Watching for file changes with StatReloader
2025-06-24 05:20:17,629 | INFO     | django.utils.autoreload | run_with_reloader    | Line 667  | Watching for file changes with StatReloader
2025-06-24 05:21:09,034 | INFO     | authentication.views | post                 | Line 155  | Login attempt received.
2025-06-24 05:21:17,012 | INFO     | authentication.views | post                 | Line 155  | Login attempt received.
2025-06-24 05:21:17,648 | INFO     | authentication.views | post                 | Line 172  | Login successful for user: NikhilVDX
2025-06-24 05:21:17,658 | INFO     | authentication.views | post                 | Line 172  | Login successful for user: NikhilVDX
2025-06-24 05:21:24,975 | INFO     | ImageApp1.views | get                  | Line 131  | UserDocumentView accessed by user ID: 7
2025-06-24 05:21:24,976 | INFO     | ImageApp1.views | get                  | Line 138  | Fetching documents for user ID: 7
2025-06-24 05:21:25,018 | INFO     | ImageApp1.views | get                  | Line 147  | 102 documents retrieved successfully.
2025-06-24 05:26:56,374 | INFO     | authentication.views | post                 | Line 155  | Login attempt received.
2025-06-24 05:26:56,937 | INFO     | authentication.views | post                 | Line 172  | Login successful for user: abc
2025-06-24 05:27:39,564 | INFO     | ImageApp1.views | post                 | Line 294  | Upload request received
2025-06-24 05:27:42,202 | INFO     |            root | post                 | Line 459  | Input tokens: 1563, Output tokens: 79
2025-06-24 05:27:42,410 | ERROR    | ImageApp1.views | post                 | Line 508  | 500
2025-06-24 05:27:42,410 | ERROR    | ImageApp1.views | post                 | Line 509  | Error while processing document.
2025-06-24 05:27:42,542 | ERROR    | ImageApp1.views | log_exception        | Line 71   | Exception occurred in D:\IDP_AI_App\Backend\Django Projects (2)\Django Projects\ImageExtraction\ImageApp1\views.py, line 467: html_response = model.generate_content([html_prompt])
2025-06-24 05:27:42,543 | ERROR    | ImageApp1.views | log_exception        | Line 71   | Exception occurred in C:\Sujata\Python39\lib\site-packages\google\generativeai\generative_models.py, line 331: response = self._client.generate_content(
2025-06-24 05:27:42,545 | ERROR    | ImageApp1.views | log_exception        | Line 71   | Exception occurred in C:\Sujata\Python39\lib\site-packages\google\ai\generativelanguage_v1beta\services\generative_service\client.py, line 835: response = rpc(
2025-06-24 05:27:42,545 | ERROR    | ImageApp1.views | log_exception        | Line 71   | Exception occurred in C:\Sujata\Python39\lib\site-packages\google\api_core\gapic_v1\method.py, line 131: return wrapped_func(*args, **kwargs)
2025-06-24 05:27:42,546 | ERROR    | ImageApp1.views | log_exception        | Line 71   | Exception occurred in C:\Sujata\Python39\lib\site-packages\google\api_core\retry\retry_unary.py, line 294: return retry_target(
2025-06-24 05:27:42,546 | ERROR    | ImageApp1.views | log_exception        | Line 71   | Exception occurred in C:\Sujata\Python39\lib\site-packages\google\api_core\retry\retry_unary.py, line 156: next_sleep = _retry_error_helper(
2025-06-24 05:27:42,547 | ERROR    | ImageApp1.views | log_exception        | Line 71   | Exception occurred in C:\Sujata\Python39\lib\site-packages\google\api_core\retry\retry_base.py, line 214: raise final_exc from source_exc
2025-06-24 05:27:42,547 | ERROR    | ImageApp1.views | log_exception        | Line 71   | Exception occurred in C:\Sujata\Python39\lib\site-packages\google\api_core\retry\retry_unary.py, line 147: result = target()
2025-06-24 05:27:42,548 | ERROR    | ImageApp1.views | log_exception        | Line 71   | Exception occurred in C:\Sujata\Python39\lib\site-packages\google\api_core\timeout.py, line 130: return func(*args, **kwargs)
2025-06-24 05:27:42,548 | ERROR    | ImageApp1.views | log_exception        | Line 71   | Exception occurred in C:\Sujata\Python39\lib\site-packages\google\api_core\grpc_helpers.py, line 78: raise exceptions.from_grpc_error(exc) from exc
2025-06-24 05:27:42,550 | ERROR    |  django.request | log_response         | Line 241  | Internal Server Error: /IDA/upload/
2025-06-24 05:40:54,073 | INFO     | authentication.views | post                 | Line 155  | Login attempt received.
2025-06-24 05:40:54,677 | INFO     | authentication.views | post                 | Line 172  | Login successful for user: abc
2025-06-24 05:41:15,247 | INFO     | ImageApp1.views | post                 | Line 294  | Upload request received
2025-06-24 05:41:15,525 | ERROR    | ImageApp1.views | post                 | Line 508  | 500
2025-06-24 05:41:15,525 | ERROR    | ImageApp1.views | post                 | Line 509  | Error while processing document.
2025-06-24 05:41:15,529 | ERROR    | ImageApp1.views | log_exception        | Line 71   | Exception occurred in D:\IDP_AI_App\Backend\Django Projects (2)\Django Projects\ImageExtraction\ImageApp1\views.py, line 439: response = model.generate_content([data_part, REIMBURSEMENT_EXTRACTION_PROMPT])
2025-06-24 05:41:15,529 | ERROR    | ImageApp1.views | log_exception        | Line 71   | Exception occurred in C:\Sujata\Python39\lib\site-packages\google\generativeai\generative_models.py, line 331: response = self._client.generate_content(
2025-06-24 05:41:15,530 | ERROR    | ImageApp1.views | log_exception        | Line 71   | Exception occurred in C:\Sujata\Python39\lib\site-packages\google\ai\generativelanguage_v1beta\services\generative_service\client.py, line 835: response = rpc(
2025-06-24 05:41:15,531 | ERROR    | ImageApp1.views | log_exception        | Line 71   | Exception occurred in C:\Sujata\Python39\lib\site-packages\google\api_core\gapic_v1\method.py, line 131: return wrapped_func(*args, **kwargs)
2025-06-24 05:41:15,531 | ERROR    | ImageApp1.views | log_exception        | Line 71   | Exception occurred in C:\Sujata\Python39\lib\site-packages\google\api_core\retry\retry_unary.py, line 294: return retry_target(
2025-06-24 05:41:15,532 | ERROR    | ImageApp1.views | log_exception        | Line 71   | Exception occurred in C:\Sujata\Python39\lib\site-packages\google\api_core\retry\retry_unary.py, line 156: next_sleep = _retry_error_helper(
2025-06-24 05:41:15,532 | ERROR    | ImageApp1.views | log_exception        | Line 71   | Exception occurred in C:\Sujata\Python39\lib\site-packages\google\api_core\retry\retry_base.py, line 214: raise final_exc from source_exc
2025-06-24 05:41:15,533 | ERROR    | ImageApp1.views | log_exception        | Line 71   | Exception occurred in C:\Sujata\Python39\lib\site-packages\google\api_core\retry\retry_unary.py, line 147: result = target()
2025-06-24 05:41:15,533 | ERROR    | ImageApp1.views | log_exception        | Line 71   | Exception occurred in C:\Sujata\Python39\lib\site-packages\google\api_core\timeout.py, line 130: return func(*args, **kwargs)
2025-06-24 05:41:15,534 | ERROR    | ImageApp1.views | log_exception        | Line 71   | Exception occurred in C:\Sujata\Python39\lib\site-packages\google\api_core\grpc_helpers.py, line 78: raise exceptions.from_grpc_error(exc) from exc
2025-06-24 05:41:15,535 | ERROR    |  django.request | log_response         | Line 241  | Internal Server Error: /IDA/upload/
2025-06-24 05:41:17,811 | INFO     | ImageApp1.views | post                 | Line 294  | Upload request received
2025-06-24 05:41:18,074 | ERROR    | ImageApp1.views | post                 | Line 508  | 500
2025-06-24 05:41:18,074 | ERROR    | ImageApp1.views | post                 | Line 509  | Error while processing document.
2025-06-24 05:41:18,077 | ERROR    | ImageApp1.views | log_exception        | Line 71   | Exception occurred in D:\IDP_AI_App\Backend\Django Projects (2)\Django Projects\ImageExtraction\ImageApp1\views.py, line 439: response = model.generate_content([data_part, REIMBURSEMENT_EXTRACTION_PROMPT])
2025-06-24 05:41:18,078 | ERROR    | ImageApp1.views | log_exception        | Line 71   | Exception occurred in C:\Sujata\Python39\lib\site-packages\google\generativeai\generative_models.py, line 331: response = self._client.generate_content(
2025-06-24 05:41:18,079 | ERROR    | ImageApp1.views | log_exception        | Line 71   | Exception occurred in C:\Sujata\Python39\lib\site-packages\google\ai\generativelanguage_v1beta\services\generative_service\client.py, line 835: response = rpc(
2025-06-24 05:41:18,079 | ERROR    | ImageApp1.views | log_exception        | Line 71   | Exception occurred in C:\Sujata\Python39\lib\site-packages\google\api_core\gapic_v1\method.py, line 131: return wrapped_func(*args, **kwargs)
2025-06-24 05:41:18,080 | ERROR    | ImageApp1.views | log_exception        | Line 71   | Exception occurred in C:\Sujata\Python39\lib\site-packages\google\api_core\retry\retry_unary.py, line 294: return retry_target(
2025-06-24 05:41:18,080 | ERROR    | ImageApp1.views | log_exception        | Line 71   | Exception occurred in C:\Sujata\Python39\lib\site-packages\google\api_core\retry\retry_unary.py, line 156: next_sleep = _retry_error_helper(
2025-06-24 05:41:18,081 | ERROR    | ImageApp1.views | log_exception        | Line 71   | Exception occurred in C:\Sujata\Python39\lib\site-packages\google\api_core\retry\retry_base.py, line 214: raise final_exc from source_exc
2025-06-24 05:41:18,081 | ERROR    | ImageApp1.views | log_exception        | Line 71   | Exception occurred in C:\Sujata\Python39\lib\site-packages\google\api_core\retry\retry_unary.py, line 147: result = target()
2025-06-24 05:41:18,082 | ERROR    | ImageApp1.views | log_exception        | Line 71   | Exception occurred in C:\Sujata\Python39\lib\site-packages\google\api_core\timeout.py, line 130: return func(*args, **kwargs)
2025-06-24 05:41:18,083 | ERROR    | ImageApp1.views | log_exception        | Line 71   | Exception occurred in C:\Sujata\Python39\lib\site-packages\google\api_core\grpc_helpers.py, line 78: raise exceptions.from_grpc_error(exc) from exc
2025-06-24 05:41:18,083 | ERROR    |  django.request | log_response         | Line 241  | Internal Server Error: /IDA/upload/
2025-06-24 05:43:52,212 | INFO     | authentication.views | post                 | Line 155  | Login attempt received.
2025-06-24 05:43:52,831 | INFO     | authentication.views | post                 | Line 172  | Login successful for user: abc
2025-06-24 05:44:11,749 | INFO     | ImageApp1.views | post                 | Line 294  | Upload request received
2025-06-24 05:44:12,029 | ERROR    | ImageApp1.views | post                 | Line 508  | 500
2025-06-24 05:44:12,030 | ERROR    | ImageApp1.views | post                 | Line 509  | Error while processing document.
2025-06-24 05:44:12,031 | ERROR    | ImageApp1.views | log_exception        | Line 71   | Exception occurred in D:\IDP_AI_App\Backend\Django Projects (2)\Django Projects\ImageExtraction\ImageApp1\views.py, line 439: response = model.generate_content([data_part, REIMBURSEMENT_EXTRACTION_PROMPT])
2025-06-24 05:44:12,032 | ERROR    | ImageApp1.views | log_exception        | Line 71   | Exception occurred in C:\Sujata\Python39\lib\site-packages\google\generativeai\generative_models.py, line 331: response = self._client.generate_content(
2025-06-24 05:44:12,032 | ERROR    | ImageApp1.views | log_exception        | Line 71   | Exception occurred in C:\Sujata\Python39\lib\site-packages\google\ai\generativelanguage_v1beta\services\generative_service\client.py, line 835: response = rpc(
2025-06-24 05:44:12,032 | ERROR    | ImageApp1.views | log_exception        | Line 71   | Exception occurred in C:\Sujata\Python39\lib\site-packages\google\api_core\gapic_v1\method.py, line 131: return wrapped_func(*args, **kwargs)
2025-06-24 05:44:12,033 | ERROR    | ImageApp1.views | log_exception        | Line 71   | Exception occurred in C:\Sujata\Python39\lib\site-packages\google\api_core\retry\retry_unary.py, line 294: return retry_target(
2025-06-24 05:44:12,033 | ERROR    | ImageApp1.views | log_exception        | Line 71   | Exception occurred in C:\Sujata\Python39\lib\site-packages\google\api_core\retry\retry_unary.py, line 156: next_sleep = _retry_error_helper(
2025-06-24 05:44:12,034 | ERROR    | ImageApp1.views | log_exception        | Line 71   | Exception occurred in C:\Sujata\Python39\lib\site-packages\google\api_core\retry\retry_base.py, line 214: raise final_exc from source_exc
2025-06-24 05:44:12,034 | ERROR    | ImageApp1.views | log_exception        | Line 71   | Exception occurred in C:\Sujata\Python39\lib\site-packages\google\api_core\retry\retry_unary.py, line 147: result = target()
2025-06-24 05:44:12,034 | ERROR    | ImageApp1.views | log_exception        | Line 71   | Exception occurred in C:\Sujata\Python39\lib\site-packages\google\api_core\timeout.py, line 130: return func(*args, **kwargs)
2025-06-24 05:44:12,035 | ERROR    | ImageApp1.views | log_exception        | Line 71   | Exception occurred in C:\Sujata\Python39\lib\site-packages\google\api_core\grpc_helpers.py, line 78: raise exceptions.from_grpc_error(exc) from exc
2025-06-24 05:44:12,036 | ERROR    |  django.request | log_response         | Line 241  | Internal Server Error: /IDA/upload/
2025-06-24 05:44:14,187 | INFO     | ImageApp1.views | post                 | Line 294  | Upload request received
2025-06-24 05:44:14,450 | ERROR    | ImageApp1.views | post                 | Line 508  | 500
2025-06-24 05:44:14,451 | ERROR    | ImageApp1.views | post                 | Line 509  | Error while processing document.
2025-06-24 05:44:14,452 | ERROR    | ImageApp1.views | log_exception        | Line 71   | Exception occurred in D:\IDP_AI_App\Backend\Django Projects (2)\Django Projects\ImageExtraction\ImageApp1\views.py, line 439: response = model.generate_content([data_part, REIMBURSEMENT_EXTRACTION_PROMPT])
2025-06-24 05:44:14,452 | ERROR    | ImageApp1.views | log_exception        | Line 71   | Exception occurred in C:\Sujata\Python39\lib\site-packages\google\generativeai\generative_models.py, line 331: response = self._client.generate_content(
2025-06-24 05:44:14,453 | ERROR    | ImageApp1.views | log_exception        | Line 71   | Exception occurred in C:\Sujata\Python39\lib\site-packages\google\ai\generativelanguage_v1beta\services\generative_service\client.py, line 835: response = rpc(
2025-06-24 05:44:14,453 | ERROR    | ImageApp1.views | log_exception        | Line 71   | Exception occurred in C:\Sujata\Python39\lib\site-packages\google\api_core\gapic_v1\method.py, line 131: return wrapped_func(*args, **kwargs)
2025-06-24 05:44:14,453 | ERROR    | ImageApp1.views | log_exception        | Line 71   | Exception occurred in C:\Sujata\Python39\lib\site-packages\google\api_core\retry\retry_unary.py, line 294: return retry_target(
2025-06-24 05:44:14,454 | ERROR    | ImageApp1.views | log_exception        | Line 71   | Exception occurred in C:\Sujata\Python39\lib\site-packages\google\api_core\retry\retry_unary.py, line 156: next_sleep = _retry_error_helper(
2025-06-24 05:44:14,454 | ERROR    | ImageApp1.views | log_exception        | Line 71   | Exception occurred in C:\Sujata\Python39\lib\site-packages\google\api_core\retry\retry_base.py, line 214: raise final_exc from source_exc
2025-06-24 05:44:14,455 | ERROR    | ImageApp1.views | log_exception        | Line 71   | Exception occurred in C:\Sujata\Python39\lib\site-packages\google\api_core\retry\retry_unary.py, line 147: result = target()
2025-06-24 05:44:14,455 | ERROR    | ImageApp1.views | log_exception        | Line 71   | Exception occurred in C:\Sujata\Python39\lib\site-packages\google\api_core\timeout.py, line 130: return func(*args, **kwargs)
2025-06-24 05:44:14,455 | ERROR    | ImageApp1.views | log_exception        | Line 71   | Exception occurred in C:\Sujata\Python39\lib\site-packages\google\api_core\grpc_helpers.py, line 78: raise exceptions.from_grpc_error(exc) from exc
2025-06-24 05:44:14,456 | ERROR    |  django.request | log_response         | Line 241  | Internal Server Error: /IDA/upload/
2025-06-24 05:44:37,032 | INFO     | django.utils.autoreload | run_with_reloader    | Line 667  | Watching for file changes with StatReloader
2025-06-24 05:44:44,900 | INFO     | ImageApp1.views | post                 | Line 294  | Upload request received
2025-06-24 05:44:48,235 | INFO     |            root | post                 | Line 459  | Input tokens: 1563, Output tokens: 239
2025-06-24 05:44:53,735 | INFO     | ImageApp1.views | post                 | Line 500  | Document processed and saved successfully. Document ID: gAAAAABoWjtVmgX9D399LT5lQ7ZZB3GM5es1xyUl-7joa8il9Y3jJrp5IHJg00bGh0gtkdk0w23ays95-TCwyf2gLhmPQjGumA==
2025-06-24 05:45:43,306 | INFO     | ImageApp1.views | get                  | Line 95   | GetDocumentByIdView called with encrypted ID: gAAAAABoWjtVmgX9D399LT5lQ7ZZB3GM5es1xyUl-7joa8il9Y3jJrp5IHJg00bGh0gtkdk0w23ays95-TCwyf2gLhmPQjGumA==
2025-06-24 05:45:43,307 | DEBUG    | ImageApp1.views | get                  | Line 99   | Decrypted ID: 180
2025-06-24 05:45:43,325 | INFO     | ImageApp1.views | get                  | Line 103  | Document 180 retrieved successfully
2025-06-24 05:51:49,930 | INFO     | django.utils.autoreload | trigger_reload       | Line 265  | D:\IDP_AI_App\Backend\Django Projects (2)\Django Projects\ImageExtraction\ImageApp1\views.py changed, reloading.
2025-06-24 05:51:53,685 | INFO     | django.utils.autoreload | run_with_reloader    | Line 667  | Watching for file changes with StatReloader
2025-06-24 05:52:54,768 | INFO     | django.utils.autoreload | trigger_reload       | Line 265  | D:\IDP_AI_App\Backend\Django Projects (2)\Django Projects\ImageExtraction\ImageApp1\views.py changed, reloading.
2025-06-24 05:52:56,655 | INFO     | django.utils.autoreload | run_with_reloader    | Line 667  | Watching for file changes with StatReloader
2025-06-24 05:53:01,108 | INFO     | django.utils.autoreload | trigger_reload       | Line 265  | D:\IDP_AI_App\Backend\Django Projects (2)\Django Projects\ImageExtraction\ImageApp1\views.py changed, reloading.
2025-06-24 05:53:03,036 | INFO     | django.utils.autoreload | run_with_reloader    | Line 667  | Watching for file changes with StatReloader
2025-06-24 05:53:49,530 | INFO     | authentication.views | post                 | Line 155  | Login attempt received.
2025-06-24 05:53:50,115 | INFO     | authentication.views | post                 | Line 172  | Login successful for user: abc
2025-06-24 05:54:10,038 | INFO     | ImageApp1.views | get                  | Line 131  | UserDocumentView accessed by user ID: 3
2025-06-24 05:54:10,040 | INFO     | ImageApp1.views | get                  | Line 138  | Fetching documents for user ID: 3
2025-06-24 05:54:10,063 | ERROR    | ImageApp1.views | get                  | Line 159  | Exception occurred while fetching user documents.
2025-06-24 05:54:10,066 | ERROR    | ImageApp1.views | log_exception        | Line 71   | Exception occurred in D:\IDP_AI_App\Backend\Django Projects (2)\Django Projects\ImageExtraction\ImageApp1\views.py, line 146: total_input_tokens = sum(doc.input_token for doc in documents)
2025-06-24 05:54:10,067 | ERROR    |  django.request | log_response         | Line 241  | Internal Server Error: /IDA/documents/
2025-06-24 05:57:51,242 | INFO     | django.utils.autoreload | trigger_reload       | Line 265  | D:\IDP_AI_App\Backend\Django Projects (2)\Django Projects\ImageExtraction\ImageApp1\views.py changed, reloading.
2025-06-24 05:57:53,229 | INFO     | django.utils.autoreload | run_with_reloader    | Line 667  | Watching for file changes with StatReloader
2025-06-24 05:58:15,060 | INFO     | django.utils.autoreload | trigger_reload       | Line 265  | D:\IDP_AI_App\Backend\Django Projects (2)\Django Projects\ImageExtraction\ImageApp1\views.py changed, reloading.
2025-06-24 05:58:16,973 | INFO     | django.utils.autoreload | run_with_reloader    | Line 667  | Watching for file changes with StatReloader
2025-06-24 06:00:34,700 | INFO     | ImageApp1.views | get                  | Line 131  | UserDocumentView accessed by user ID: 3
2025-06-24 06:02:13,302 | INFO     | authentication.views | post                 | Line 155  | Login attempt received.
2025-06-24 06:00:30,529 | INFO     | django.utils.autoreload | trigger_reload       | Line 265  | D:\IDP_AI_App\Backend\Django Projects (2)\Django Projects\ImageExtraction\ImageApp1\views.py changed, reloading.
2025-06-24 06:02:32,846 | INFO     | ImageApp1.views | get                  | Line 138  | Fetching documents for user ID: 3
2025-06-24 06:02:34,568 | INFO     | django.utils.autoreload | run_with_reloader    | Line 667  | Watching for file changes with StatReloader
2025-06-24 06:02:44,979 | INFO     | authentication.views | post                 | Line 155  | Login attempt received.
2025-06-24 06:02:45,545 | INFO     | authentication.views | post                 | Line 172  | Login successful for user: abc
2025-06-24 06:03:05,811 | INFO     | ImageApp1.views | get                  | Line 131  | UserDocumentView accessed by user ID: 3
2025-06-24 06:03:05,812 | INFO     | ImageApp1.views | get                  | Line 138  | Fetching documents for user ID: 3
2025-06-24 06:03:05,838 | INFO     | ImageApp1.views | get                  | Line 154  | 33 documents retrieved successfully.
2025-06-24 06:14:50,275 | INFO     | django.utils.autoreload | trigger_reload       | Line 265  | D:\IDP_AI_App\Backend\Django Projects (2)\Django Projects\ImageExtraction\ImageApp1\views.py changed, reloading.
2025-06-24 06:21:28,165 | INFO     | django.utils.autoreload | run_with_reloader    | Line 667  | Watching for file changes with StatReloader
2025-06-24 06:34:44,713 | INFO     | django.utils.autoreload | run_with_reloader    | Line 667  | Watching for file changes with StatReloader
2025-06-24 06:36:10,099 | INFO     | django.utils.autoreload | trigger_reload       | Line 265  | D:\IDP_AI_App\Backend\Django Projects (2)\Django Projects\ImageExtraction\ImageApp1\views.py changed, reloading.
2025-06-24 06:36:11,935 | INFO     | django.utils.autoreload | run_with_reloader    | Line 667  | Watching for file changes with StatReloader
2025-06-24 06:41:05,292 | INFO     | django.utils.autoreload | trigger_reload       | Line 265  | D:\IDP_AI_App\Backend\Django Projects (2)\Django Projects\ImageExtraction\ImageApp1\views.py changed, reloading.
2025-06-24 06:41:07,054 | INFO     | django.utils.autoreload | run_with_reloader    | Line 667  | Watching for file changes with StatReloader
2025-06-24 06:50:29,375 | INFO     | django.utils.autoreload | run_with_reloader    | Line 667  | Watching for file changes with StatReloader
2025-06-24 06:52:37,963 | INFO     | django.utils.autoreload | run_with_reloader    | Line 667  | Watching for file changes with StatReloader
2025-06-24 06:55:33,587 | INFO     | django.utils.autoreload | trigger_reload       | Line 265  | D:\IDP_AI_App\Backend\Django Projects (2)\Django Projects\ImageExtraction\ImageApp1\views.py changed, reloading.
2025-06-24 06:55:35,427 | INFO     | django.utils.autoreload | run_with_reloader    | Line 667  | Watching for file changes with StatReloader
2025-06-24 06:57:01,538 | INFO     | django.utils.autoreload | trigger_reload       | Line 265  | D:\IDP_AI_App\Backend\Django Projects (2)\Django Projects\ImageExtraction\ImageApp1\views.py changed, reloading.
2025-06-24 06:57:03,246 | INFO     | django.utils.autoreload | run_with_reloader    | Line 667  | Watching for file changes with StatReloader
2025-06-24 06:58:45,164 | INFO     | django.utils.autoreload | trigger_reload       | Line 265  | D:\IDP_AI_App\Backend\Django Projects (2)\Django Projects\ImageExtraction\ImageExtraction\settings.py changed, reloading.
2025-06-24 06:58:47,046 | INFO     | django.utils.autoreload | run_with_reloader    | Line 667  | Watching for file changes with StatReloader
2025-06-24 06:59:05,837 | INFO     | authentication.views | post                 | Line 155  | Login attempt received.
2025-06-24 06:59:06,405 | INFO     | authentication.views | post                 | Line 172  | Login successful for user: abc
2025-06-24 06:59:35,209 | INFO     | django.utils.autoreload | trigger_reload       | Line 265  | D:\IDP_AI_App\Backend\Django Projects (2)\Django Projects\ImageExtraction\ImageExtraction\settings.py changed, reloading.
2025-06-24 06:59:37,023 | INFO     | django.utils.autoreload | run_with_reloader    | Line 667  | Watching for file changes with StatReloader
2025-06-24 06:59:44,136 | INFO     | authentication.views | post                 | Line 155  | Login attempt received.
2025-06-24 06:59:44,720 | INFO     | authentication.views | post                 | Line 172  | Login successful for user: NikhilVDX
2025-06-24 06:59:56,976 | INFO     | ImageApp1.views | post                 | Line 318  | Upload request received
2025-06-24 06:59:57,173 | ERROR    | ImageApp1.views | post                 | Line 531  | 500
2025-06-24 06:59:57,174 | ERROR    | ImageApp1.views | post                 | Line 532  | Error while processing document.
2025-06-24 06:59:57,188 | ERROR    | ImageApp1.views | log_exception        | Line 71   | Exception occurred in D:\IDP_AI_App\Backend\Django Projects (2)\Django Projects\ImageExtraction\ImageApp1\views.py, line 414: response = model.generate_content([data_part, prompt_text])
2025-06-24 06:59:57,189 | ERROR    | ImageApp1.views | log_exception        | Line 71   | Exception occurred in C:\Sujata\Python39\lib\site-packages\google\generativeai\generative_models.py, line 331: response = self._client.generate_content(
2025-06-24 06:59:57,190 | ERROR    | ImageApp1.views | log_exception        | Line 71   | Exception occurred in C:\Sujata\Python39\lib\site-packages\google\ai\generativelanguage_v1beta\services\generative_service\client.py, line 835: response = rpc(
2025-06-24 06:59:57,191 | ERROR    | ImageApp1.views | log_exception        | Line 71   | Exception occurred in C:\Sujata\Python39\lib\site-packages\google\api_core\gapic_v1\method.py, line 131: return wrapped_func(*args, **kwargs)
2025-06-24 06:59:57,191 | ERROR    | ImageApp1.views | log_exception        | Line 71   | Exception occurred in C:\Sujata\Python39\lib\site-packages\google\api_core\retry\retry_unary.py, line 294: return retry_target(
2025-06-24 06:59:57,192 | ERROR    | ImageApp1.views | log_exception        | Line 71   | Exception occurred in C:\Sujata\Python39\lib\site-packages\google\api_core\retry\retry_unary.py, line 156: next_sleep = _retry_error_helper(
2025-06-24 06:59:57,192 | ERROR    | ImageApp1.views | log_exception        | Line 71   | Exception occurred in C:\Sujata\Python39\lib\site-packages\google\api_core\retry\retry_base.py, line 214: raise final_exc from source_exc
2025-06-24 06:59:57,193 | ERROR    | ImageApp1.views | log_exception        | Line 71   | Exception occurred in C:\Sujata\Python39\lib\site-packages\google\api_core\retry\retry_unary.py, line 147: result = target()
2025-06-24 06:59:57,194 | ERROR    | ImageApp1.views | log_exception        | Line 71   | Exception occurred in C:\Sujata\Python39\lib\site-packages\google\api_core\timeout.py, line 130: return func(*args, **kwargs)
2025-06-24 06:59:57,194 | ERROR    | ImageApp1.views | log_exception        | Line 71   | Exception occurred in C:\Sujata\Python39\lib\site-packages\google\api_core\grpc_helpers.py, line 78: raise exceptions.from_grpc_error(exc) from exc
2025-06-24 06:59:57,195 | ERROR    |  django.request | log_response         | Line 241  | Internal Server Error: /IDA/upload/
2025-06-24 07:10:36,628 | INFO     | django.utils.autoreload | trigger_reload       | Line 265  | D:\IDP_AI_App\Backend\Django Projects (2)\Django Projects\ImageExtraction\ImageApp1\views.py changed, reloading.
2025-06-24 07:10:40,444 | INFO     | django.utils.autoreload | run_with_reloader    | Line 667  | Watching for file changes with StatReloader
2025-06-24 07:10:46,256 | INFO     | authentication.views | post                 | Line 155  | Login attempt received.
2025-06-24 07:10:46,814 | INFO     | authentication.views | post                 | Line 172  | Login successful for user: NikhilVDX
2025-06-24 07:10:57,275 | INFO     | ImageApp1.views | post                 | Line 318  | Upload request received
2025-06-24 07:10:57,471 | ERROR    | ImageApp1.views | post                 | Line 533  | 500
2025-06-24 07:10:57,471 | ERROR    | ImageApp1.views | post                 | Line 534  | Error while processing document.
2025-06-24 07:10:57,482 | ERROR    | ImageApp1.views | log_exception        | Line 71   | Exception occurred in D:\IDP_AI_App\Backend\Django Projects (2)\Django Projects\ImageExtraction\ImageApp1\views.py, line 415: response = model.generate_content([data_part, prompt_text])
2025-06-24 07:10:57,483 | ERROR    | ImageApp1.views | log_exception        | Line 71   | Exception occurred in C:\Sujata\Python39\lib\site-packages\google\generativeai\generative_models.py, line 331: response = self._client.generate_content(
2025-06-24 07:10:57,483 | ERROR    | ImageApp1.views | log_exception        | Line 71   | Exception occurred in C:\Sujata\Python39\lib\site-packages\google\ai\generativelanguage_v1beta\services\generative_service\client.py, line 835: response = rpc(
2025-06-24 07:10:57,484 | ERROR    | ImageApp1.views | log_exception        | Line 71   | Exception occurred in C:\Sujata\Python39\lib\site-packages\google\api_core\gapic_v1\method.py, line 131: return wrapped_func(*args, **kwargs)
2025-06-24 07:10:57,484 | ERROR    | ImageApp1.views | log_exception        | Line 71   | Exception occurred in C:\Sujata\Python39\lib\site-packages\google\api_core\retry\retry_unary.py, line 294: return retry_target(
2025-06-24 07:10:57,485 | ERROR    | ImageApp1.views | log_exception        | Line 71   | Exception occurred in C:\Sujata\Python39\lib\site-packages\google\api_core\retry\retry_unary.py, line 156: next_sleep = _retry_error_helper(
2025-06-24 07:10:57,485 | ERROR    | ImageApp1.views | log_exception        | Line 71   | Exception occurred in C:\Sujata\Python39\lib\site-packages\google\api_core\retry\retry_base.py, line 214: raise final_exc from source_exc
2025-06-24 07:10:57,486 | ERROR    | ImageApp1.views | log_exception        | Line 71   | Exception occurred in C:\Sujata\Python39\lib\site-packages\google\api_core\retry\retry_unary.py, line 147: result = target()
2025-06-24 07:10:57,487 | ERROR    | ImageApp1.views | log_exception        | Line 71   | Exception occurred in C:\Sujata\Python39\lib\site-packages\google\api_core\timeout.py, line 130: return func(*args, **kwargs)
2025-06-24 07:10:57,487 | ERROR    | ImageApp1.views | log_exception        | Line 71   | Exception occurred in C:\Sujata\Python39\lib\site-packages\google\api_core\grpc_helpers.py, line 78: raise exceptions.from_grpc_error(exc) from exc
2025-06-24 07:10:57,488 | ERROR    |  django.request | log_response         | Line 241  | Internal Server Error: /IDA/upload/
2025-06-24 07:11:28,917 | INFO     | django.utils.autoreload | trigger_reload       | Line 265  | D:\IDP_AI_App\Backend\Django Projects (2)\Django Projects\ImageExtraction\ImageApp1\views.py changed, reloading.
2025-06-24 07:13:36,329 | INFO     | django.utils.autoreload | run_with_reloader    | Line 667  | Watching for file changes with StatReloader
2025-06-24 07:17:59,245 | INFO     | django.utils.autoreload | run_with_reloader    | Line 667  | Watching for file changes with StatReloader
2025-06-24 07:18:17,553 | INFO     | authentication.views | post                 | Line 155  | Login attempt received.
2025-06-24 07:18:18,131 | INFO     | authentication.views | post                 | Line 172  | Login successful for user: abc
2025-06-24 07:18:42,304 | INFO     | ImageApp1.views | post                 | Line 318  | Upload request received
2025-06-24 07:18:42,583 | ERROR    | ImageApp1.views | post                 | Line 533  | 500
2025-06-24 07:18:42,583 | ERROR    | ImageApp1.views | post                 | Line 534  | Error while processing document.
2025-06-24 07:18:42,595 | ERROR    | ImageApp1.views | log_exception        | Line 71   | Exception occurred in D:\IDP_AI_App\Backend\Django Projects (2)\Django Projects\ImageExtraction\ImageApp1\views.py, line 464: response = model.generate_content([data_part, REIMBURSEMENT_EXTRACTION_PROMPT])
2025-06-24 07:18:42,596 | ERROR    | ImageApp1.views | log_exception        | Line 71   | Exception occurred in C:\Sujata\Python39\lib\site-packages\google\generativeai\generative_models.py, line 331: response = self._client.generate_content(
2025-06-24 07:18:42,597 | ERROR    | ImageApp1.views | log_exception        | Line 71   | Exception occurred in C:\Sujata\Python39\lib\site-packages\google\ai\generativelanguage_v1beta\services\generative_service\client.py, line 835: response = rpc(
2025-06-24 07:18:42,598 | ERROR    | ImageApp1.views | log_exception        | Line 71   | Exception occurred in C:\Sujata\Python39\lib\site-packages\google\api_core\gapic_v1\method.py, line 131: return wrapped_func(*args, **kwargs)
2025-06-24 07:18:42,598 | ERROR    | ImageApp1.views | log_exception        | Line 71   | Exception occurred in C:\Sujata\Python39\lib\site-packages\google\api_core\retry\retry_unary.py, line 294: return retry_target(
2025-06-24 07:18:42,599 | ERROR    | ImageApp1.views | log_exception        | Line 71   | Exception occurred in C:\Sujata\Python39\lib\site-packages\google\api_core\retry\retry_unary.py, line 156: next_sleep = _retry_error_helper(
2025-06-24 07:18:42,600 | ERROR    | ImageApp1.views | log_exception        | Line 71   | Exception occurred in C:\Sujata\Python39\lib\site-packages\google\api_core\retry\retry_base.py, line 214: raise final_exc from source_exc
2025-06-24 07:18:42,600 | ERROR    | ImageApp1.views | log_exception        | Line 71   | Exception occurred in C:\Sujata\Python39\lib\site-packages\google\api_core\retry\retry_unary.py, line 147: result = target()
2025-06-24 07:18:42,601 | ERROR    | ImageApp1.views | log_exception        | Line 71   | Exception occurred in C:\Sujata\Python39\lib\site-packages\google\api_core\timeout.py, line 130: return func(*args, **kwargs)
2025-06-24 07:18:42,601 | ERROR    | ImageApp1.views | log_exception        | Line 71   | Exception occurred in C:\Sujata\Python39\lib\site-packages\google\api_core\grpc_helpers.py, line 78: raise exceptions.from_grpc_error(exc) from exc
2025-06-24 07:18:42,602 | ERROR    |  django.request | log_response         | Line 241  | Internal Server Error: /IDA/upload/
2025-06-24 07:19:07,483 | INFO     | ImageApp1.views | post                 | Line 318  | Upload request received
2025-06-24 07:19:07,709 | ERROR    | ImageApp1.views | post                 | Line 533  | 500
2025-06-24 07:19:07,710 | ERROR    | ImageApp1.views | post                 | Line 534  | Error while processing document.
2025-06-24 07:19:07,713 | ERROR    | ImageApp1.views | log_exception        | Line 71   | Exception occurred in D:\IDP_AI_App\Backend\Django Projects (2)\Django Projects\ImageExtraction\ImageApp1\views.py, line 464: response = model.generate_content([data_part, REIMBURSEMENT_EXTRACTION_PROMPT])
2025-06-24 07:19:07,713 | ERROR    | ImageApp1.views | log_exception        | Line 71   | Exception occurred in C:\Sujata\Python39\lib\site-packages\google\generativeai\generative_models.py, line 331: response = self._client.generate_content(
2025-06-24 07:19:07,714 | ERROR    | ImageApp1.views | log_exception        | Line 71   | Exception occurred in C:\Sujata\Python39\lib\site-packages\google\ai\generativelanguage_v1beta\services\generative_service\client.py, line 835: response = rpc(
2025-06-24 07:19:07,714 | ERROR    | ImageApp1.views | log_exception        | Line 71   | Exception occurred in C:\Sujata\Python39\lib\site-packages\google\api_core\gapic_v1\method.py, line 131: return wrapped_func(*args, **kwargs)
2025-06-24 07:19:07,715 | ERROR    | ImageApp1.views | log_exception        | Line 71   | Exception occurred in C:\Sujata\Python39\lib\site-packages\google\api_core\retry\retry_unary.py, line 294: return retry_target(
2025-06-24 07:19:07,715 | ERROR    | ImageApp1.views | log_exception        | Line 71   | Exception occurred in C:\Sujata\Python39\lib\site-packages\google\api_core\retry\retry_unary.py, line 156: next_sleep = _retry_error_helper(
2025-06-24 07:19:07,716 | ERROR    | ImageApp1.views | log_exception        | Line 71   | Exception occurred in C:\Sujata\Python39\lib\site-packages\google\api_core\retry\retry_base.py, line 214: raise final_exc from source_exc
2025-06-24 07:19:07,716 | ERROR    | ImageApp1.views | log_exception        | Line 71   | Exception occurred in C:\Sujata\Python39\lib\site-packages\google\api_core\retry\retry_unary.py, line 147: result = target()
2025-06-24 07:19:07,717 | ERROR    | ImageApp1.views | log_exception        | Line 71   | Exception occurred in C:\Sujata\Python39\lib\site-packages\google\api_core\timeout.py, line 130: return func(*args, **kwargs)
2025-06-24 07:19:07,718 | ERROR    | ImageApp1.views | log_exception        | Line 71   | Exception occurred in C:\Sujata\Python39\lib\site-packages\google\api_core\grpc_helpers.py, line 78: raise exceptions.from_grpc_error(exc) from exc
2025-06-24 07:19:07,719 | ERROR    |  django.request | log_response         | Line 241  | Internal Server Error: /IDA/upload/
2025-06-24 07:26:15,516 | WARNING  |  django.request | log_response         | Line 241  | Unauthorized: /IDA/upload/
2025-06-24 07:31:15,839 | INFO     | django.utils.autoreload | run_with_reloader    | Line 667  | Watching for file changes with StatReloader
2025-06-24 07:31:27,021 | INFO     | authentication.views | post                 | Line 155  | Login attempt received.
2025-06-24 07:31:27,599 | INFO     | authentication.views | post                 | Line 172  | Login successful for user: NikhilVDX
2025-06-24 07:31:36,154 | INFO     | ImageApp1.views | post                 | Line 318  | Upload request received
2025-06-24 07:31:36,363 | ERROR    | ImageApp1.views | post                 | Line 533  | 500
2025-06-24 07:31:36,364 | ERROR    | ImageApp1.views | post                 | Line 534  | Error while processing document.
2025-06-24 07:31:36,375 | ERROR    | ImageApp1.views | log_exception        | Line 71   | Exception occurred in D:\IDP_AI_App\Backend\Django Projects (2)\Django Projects\ImageExtraction\ImageApp1\views.py, line 415: response = model.generate_content([data_part, prompt_text])
2025-06-24 07:31:36,376 | ERROR    | ImageApp1.views | log_exception        | Line 71   | Exception occurred in C:\Sujata\Python39\lib\site-packages\google\generativeai\generative_models.py, line 331: response = self._client.generate_content(
2025-06-24 07:31:36,377 | ERROR    | ImageApp1.views | log_exception        | Line 71   | Exception occurred in C:\Sujata\Python39\lib\site-packages\google\ai\generativelanguage_v1beta\services\generative_service\client.py, line 835: response = rpc(
2025-06-24 07:31:36,377 | ERROR    | ImageApp1.views | log_exception        | Line 71   | Exception occurred in C:\Sujata\Python39\lib\site-packages\google\api_core\gapic_v1\method.py, line 131: return wrapped_func(*args, **kwargs)
2025-06-24 07:31:36,378 | ERROR    | ImageApp1.views | log_exception        | Line 71   | Exception occurred in C:\Sujata\Python39\lib\site-packages\google\api_core\retry\retry_unary.py, line 294: return retry_target(
2025-06-24 07:31:36,379 | ERROR    | ImageApp1.views | log_exception        | Line 71   | Exception occurred in C:\Sujata\Python39\lib\site-packages\google\api_core\retry\retry_unary.py, line 156: next_sleep = _retry_error_helper(
2025-06-24 07:31:36,379 | ERROR    | ImageApp1.views | log_exception        | Line 71   | Exception occurred in C:\Sujata\Python39\lib\site-packages\google\api_core\retry\retry_base.py, line 214: raise final_exc from source_exc
2025-06-24 07:31:36,380 | ERROR    | ImageApp1.views | log_exception        | Line 71   | Exception occurred in C:\Sujata\Python39\lib\site-packages\google\api_core\retry\retry_unary.py, line 147: result = target()
2025-06-24 07:31:36,381 | ERROR    | ImageApp1.views | log_exception        | Line 71   | Exception occurred in C:\Sujata\Python39\lib\site-packages\google\api_core\timeout.py, line 130: return func(*args, **kwargs)
2025-06-24 07:31:36,381 | ERROR    | ImageApp1.views | log_exception        | Line 71   | Exception occurred in C:\Sujata\Python39\lib\site-packages\google\api_core\grpc_helpers.py, line 78: raise exceptions.from_grpc_error(exc) from exc
2025-06-24 07:31:36,382 | ERROR    |  django.request | log_response         | Line 241  | Internal Server Error: /IDA/upload/
2025-06-24 07:39:07,980 | INFO     | django.utils.autoreload | trigger_reload       | Line 265  | D:\IDP_AI_App\Backend\Django Projects (2)\Django Projects\ImageExtraction\ImageApp1\views.py changed, reloading.
2025-06-24 07:39:11,760 | INFO     | django.utils.autoreload | run_with_reloader    | Line 667  | Watching for file changes with StatReloader
2025-06-24 07:39:27,383 | INFO     | authentication.views | post                 | Line 155  | Login attempt received.
2025-06-24 07:39:27,947 | INFO     | authentication.views | post                 | Line 172  | Login successful for user: NikhilVDX
2025-06-24 07:39:34,291 | INFO     | ImageApp1.views | post                 | Line 318  | Upload request received
2025-06-24 07:39:34,483 | ERROR    | ImageApp1.views | post                 | Line 537  | 500
2025-06-24 07:39:34,484 | ERROR    | ImageApp1.views | post                 | Line 538  | Error while processing document.
2025-06-24 07:39:34,496 | ERROR    | ImageApp1.views | log_exception        | Line 71   | Exception occurred in D:\IDP_AI_App\Backend\Django Projects (2)\Django Projects\ImageExtraction\ImageApp1\views.py, line 419: response = model.generate_content([data_part, prompt_text])
2025-06-24 07:39:34,496 | ERROR    | ImageApp1.views | log_exception        | Line 71   | Exception occurred in C:\Sujata\Python39\lib\site-packages\google\generativeai\generative_models.py, line 331: response = self._client.generate_content(
2025-06-24 07:39:34,497 | ERROR    | ImageApp1.views | log_exception        | Line 71   | Exception occurred in C:\Sujata\Python39\lib\site-packages\google\ai\generativelanguage_v1beta\services\generative_service\client.py, line 835: response = rpc(
2025-06-24 07:39:34,498 | ERROR    | ImageApp1.views | log_exception        | Line 71   | Exception occurred in C:\Sujata\Python39\lib\site-packages\google\api_core\gapic_v1\method.py, line 131: return wrapped_func(*args, **kwargs)
2025-06-24 07:39:34,498 | ERROR    | ImageApp1.views | log_exception        | Line 71   | Exception occurred in C:\Sujata\Python39\lib\site-packages\google\api_core\retry\retry_unary.py, line 294: return retry_target(
2025-06-24 07:39:34,499 | ERROR    | ImageApp1.views | log_exception        | Line 71   | Exception occurred in C:\Sujata\Python39\lib\site-packages\google\api_core\retry\retry_unary.py, line 156: next_sleep = _retry_error_helper(
2025-06-24 07:39:34,499 | ERROR    | ImageApp1.views | log_exception        | Line 71   | Exception occurred in C:\Sujata\Python39\lib\site-packages\google\api_core\retry\retry_base.py, line 214: raise final_exc from source_exc
2025-06-24 07:39:34,500 | ERROR    | ImageApp1.views | log_exception        | Line 71   | Exception occurred in C:\Sujata\Python39\lib\site-packages\google\api_core\retry\retry_unary.py, line 147: result = target()
2025-06-24 07:39:34,501 | ERROR    | ImageApp1.views | log_exception        | Line 71   | Exception occurred in C:\Sujata\Python39\lib\site-packages\google\api_core\timeout.py, line 130: return func(*args, **kwargs)
2025-06-24 07:39:34,501 | ERROR    | ImageApp1.views | log_exception        | Line 71   | Exception occurred in C:\Sujata\Python39\lib\site-packages\google\api_core\grpc_helpers.py, line 78: raise exceptions.from_grpc_error(exc) from exc
2025-06-24 07:39:34,502 | ERROR    |  django.request | log_response         | Line 241  | Internal Server Error: /IDA/upload/
2025-06-24 07:40:49,471 | INFO     | ImageApp1.views | post                 | Line 318  | Upload request received
2025-06-24 07:40:49,553 | DEBUG    | PIL.PngImagePlugin | call                 | Line 201  | STREAM b'IHDR' 16 13
2025-06-24 07:40:49,554 | DEBUG    | PIL.PngImagePlugin | call                 | Line 201  | STREAM b'pHYs' 41 9
2025-06-24 07:40:49,556 | DEBUG    | PIL.PngImagePlugin | call                 | Line 201  | STREAM b'sRGB' 62 1
2025-06-24 07:40:49,557 | DEBUG    | PIL.PngImagePlugin | call                 | Line 201  | STREAM b'gAMA' 75 4
2025-06-24 07:40:49,557 | DEBUG    | PIL.PngImagePlugin | call                 | Line 201  | STREAM b'IDAT' 91 73342
2025-06-24 07:40:49,760 | ERROR    | ImageApp1.views | post                 | Line 537  | 500
2025-06-24 07:40:49,760 | ERROR    | ImageApp1.views | post                 | Line 538  | Error while processing document.
2025-06-24 07:40:49,764 | ERROR    | ImageApp1.views | log_exception        | Line 71   | Exception occurred in D:\IDP_AI_App\Backend\Django Projects (2)\Django Projects\ImageExtraction\ImageApp1\views.py, line 419: response = model.generate_content([data_part, prompt_text])
2025-06-24 07:40:49,764 | ERROR    | ImageApp1.views | log_exception        | Line 71   | Exception occurred in C:\Sujata\Python39\lib\site-packages\google\generativeai\generative_models.py, line 331: response = self._client.generate_content(
2025-06-24 07:40:49,765 | ERROR    | ImageApp1.views | log_exception        | Line 71   | Exception occurred in C:\Sujata\Python39\lib\site-packages\google\ai\generativelanguage_v1beta\services\generative_service\client.py, line 835: response = rpc(
2025-06-24 07:40:49,765 | ERROR    | ImageApp1.views | log_exception        | Line 71   | Exception occurred in C:\Sujata\Python39\lib\site-packages\google\api_core\gapic_v1\method.py, line 131: return wrapped_func(*args, **kwargs)
2025-06-24 07:40:49,766 | ERROR    | ImageApp1.views | log_exception        | Line 71   | Exception occurred in C:\Sujata\Python39\lib\site-packages\google\api_core\retry\retry_unary.py, line 294: return retry_target(
2025-06-24 07:40:49,767 | ERROR    | ImageApp1.views | log_exception        | Line 71   | Exception occurred in C:\Sujata\Python39\lib\site-packages\google\api_core\retry\retry_unary.py, line 156: next_sleep = _retry_error_helper(
2025-06-24 07:40:49,767 | ERROR    | ImageApp1.views | log_exception        | Line 71   | Exception occurred in C:\Sujata\Python39\lib\site-packages\google\api_core\retry\retry_base.py, line 214: raise final_exc from source_exc
2025-06-24 07:40:49,768 | ERROR    | ImageApp1.views | log_exception        | Line 71   | Exception occurred in C:\Sujata\Python39\lib\site-packages\google\api_core\retry\retry_unary.py, line 147: result = target()
2025-06-24 07:40:49,768 | ERROR    | ImageApp1.views | log_exception        | Line 71   | Exception occurred in C:\Sujata\Python39\lib\site-packages\google\api_core\timeout.py, line 130: return func(*args, **kwargs)
2025-06-24 07:40:49,769 | ERROR    | ImageApp1.views | log_exception        | Line 71   | Exception occurred in C:\Sujata\Python39\lib\site-packages\google\api_core\grpc_helpers.py, line 78: raise exceptions.from_grpc_error(exc) from exc
2025-06-24 07:40:49,770 | ERROR    |  django.request | log_response         | Line 241  | Internal Server Error: /IDA/upload/
2025-06-24 07:42:10,596 | INFO     | django.utils.autoreload | trigger_reload       | Line 265  | D:\IDP_AI_App\Backend\Django Projects (2)\Django Projects\ImageExtraction\ImageApp1\views.py changed, reloading.
2025-06-24 07:42:14,468 | INFO     | django.utils.autoreload | run_with_reloader    | Line 667  | Watching for file changes with StatReloader
2025-06-24 08:19:00,280 | INFO     | authentication.views | post                 | Line 155  | Login attempt received.
2025-06-24 08:19:00,864 | INFO     | authentication.views | post                 | Line 172  | Login successful for user: abc
2025-06-24 08:19:20,959 | INFO     | ImageApp1.views | post                 | Line 318  | Upload request received
2025-06-24 08:19:21,248 | ERROR    | ImageApp1.views | post                 | Line 537  | 500
2025-06-24 08:19:21,250 | ERROR    | ImageApp1.views | post                 | Line 538  | Error while processing document.
2025-06-24 08:19:21,262 | ERROR    | ImageApp1.views | log_exception        | Line 71   | Exception occurred in D:\IDP_AI_App\Backend\Django Projects (2)\Django Projects\ImageExtraction\ImageApp1\views.py, line 468: response = model.generate_content([data_part, REIMBURSEMENT_EXTRACTION_PROMPT])
2025-06-24 08:19:21,263 | ERROR    | ImageApp1.views | log_exception        | Line 71   | Exception occurred in C:\Sujata\Python39\lib\site-packages\google\generativeai\generative_models.py, line 331: response = self._client.generate_content(
2025-06-24 08:19:21,264 | ERROR    | ImageApp1.views | log_exception        | Line 71   | Exception occurred in C:\Sujata\Python39\lib\site-packages\google\ai\generativelanguage_v1beta\services\generative_service\client.py, line 835: response = rpc(
2025-06-24 08:19:21,264 | ERROR    | ImageApp1.views | log_exception        | Line 71   | Exception occurred in C:\Sujata\Python39\lib\site-packages\google\api_core\gapic_v1\method.py, line 131: return wrapped_func(*args, **kwargs)
2025-06-24 08:19:21,265 | ERROR    | ImageApp1.views | log_exception        | Line 71   | Exception occurred in C:\Sujata\Python39\lib\site-packages\google\api_core\retry\retry_unary.py, line 294: return retry_target(
2025-06-24 08:19:21,266 | ERROR    | ImageApp1.views | log_exception        | Line 71   | Exception occurred in C:\Sujata\Python39\lib\site-packages\google\api_core\retry\retry_unary.py, line 156: next_sleep = _retry_error_helper(
2025-06-24 08:19:21,266 | ERROR    | ImageApp1.views | log_exception        | Line 71   | Exception occurred in C:\Sujata\Python39\lib\site-packages\google\api_core\retry\retry_base.py, line 214: raise final_exc from source_exc
2025-06-24 08:19:21,267 | ERROR    | ImageApp1.views | log_exception        | Line 71   | Exception occurred in C:\Sujata\Python39\lib\site-packages\google\api_core\retry\retry_unary.py, line 147: result = target()
2025-06-24 08:19:21,268 | ERROR    | ImageApp1.views | log_exception        | Line 71   | Exception occurred in C:\Sujata\Python39\lib\site-packages\google\api_core\timeout.py, line 130: return func(*args, **kwargs)
2025-06-24 08:19:21,268 | ERROR    | ImageApp1.views | log_exception        | Line 71   | Exception occurred in C:\Sujata\Python39\lib\site-packages\google\api_core\grpc_helpers.py, line 78: raise exceptions.from_grpc_error(exc) from exc
2025-06-24 08:19:21,269 | ERROR    |  django.request | log_response         | Line 241  | Internal Server Error: /IDA/upload/
2025-06-24 08:23:15,925 | INFO     | django.utils.autoreload | run_with_reloader    | Line 667  | Watching for file changes with StatReloader
2025-06-24 08:23:35,297 | INFO     | authentication.views | post                 | Line 155  | Login attempt received.
2025-06-24 08:23:35,858 | INFO     | authentication.views | post                 | Line 172  | Login successful for user: abc
2025-06-24 08:23:52,894 | INFO     | ImageApp1.views | post                 | Line 318  | Upload request received
2025-06-24 08:23:53,147 | ERROR    | ImageApp1.views | post                 | Line 537  | 500
2025-06-24 08:23:53,147 | ERROR    | ImageApp1.views | post                 | Line 538  | Error while processing document.
2025-06-24 08:23:53,158 | ERROR    | ImageApp1.views | log_exception        | Line 71   | Exception occurred in D:\IDP_AI_App\Backend\Django Projects (2)\Django Projects\ImageExtraction\ImageApp1\views.py, line 468: response = model.generate_content([data_part, REIMBURSEMENT_EXTRACTION_PROMPT])
2025-06-24 08:23:53,159 | ERROR    | ImageApp1.views | log_exception        | Line 71   | Exception occurred in C:\Sujata\Python39\lib\site-packages\google\generativeai\generative_models.py, line 331: response = self._client.generate_content(
2025-06-24 08:23:53,159 | ERROR    | ImageApp1.views | log_exception        | Line 71   | Exception occurred in C:\Sujata\Python39\lib\site-packages\google\ai\generativelanguage_v1beta\services\generative_service\client.py, line 835: response = rpc(
2025-06-24 08:23:53,160 | ERROR    | ImageApp1.views | log_exception        | Line 71   | Exception occurred in C:\Sujata\Python39\lib\site-packages\google\api_core\gapic_v1\method.py, line 131: return wrapped_func(*args, **kwargs)
2025-06-24 08:23:53,161 | ERROR    | ImageApp1.views | log_exception        | Line 71   | Exception occurred in C:\Sujata\Python39\lib\site-packages\google\api_core\retry\retry_unary.py, line 294: return retry_target(
2025-06-24 08:23:53,161 | ERROR    | ImageApp1.views | log_exception        | Line 71   | Exception occurred in C:\Sujata\Python39\lib\site-packages\google\api_core\retry\retry_unary.py, line 156: next_sleep = _retry_error_helper(
2025-06-24 08:23:53,162 | ERROR    | ImageApp1.views | log_exception        | Line 71   | Exception occurred in C:\Sujata\Python39\lib\site-packages\google\api_core\retry\retry_base.py, line 214: raise final_exc from source_exc
2025-06-24 08:23:53,162 | ERROR    | ImageApp1.views | log_exception        | Line 71   | Exception occurred in C:\Sujata\Python39\lib\site-packages\google\api_core\retry\retry_unary.py, line 147: result = target()
2025-06-24 08:23:53,163 | ERROR    | ImageApp1.views | log_exception        | Line 71   | Exception occurred in C:\Sujata\Python39\lib\site-packages\google\api_core\timeout.py, line 130: return func(*args, **kwargs)
2025-06-24 08:23:53,164 | ERROR    | ImageApp1.views | log_exception        | Line 71   | Exception occurred in C:\Sujata\Python39\lib\site-packages\google\api_core\grpc_helpers.py, line 78: raise exceptions.from_grpc_error(exc) from exc
2025-06-24 08:23:53,165 | ERROR    |  django.request | log_response         | Line 241  | Internal Server Error: /IDA/upload/
2025-06-24 08:23:55,273 | INFO     | ImageApp1.views | post                 | Line 318  | Upload request received
2025-06-24 08:23:55,497 | ERROR    | ImageApp1.views | post                 | Line 537  | 500
2025-06-24 08:23:55,497 | ERROR    | ImageApp1.views | post                 | Line 538  | Error while processing document.
2025-06-24 08:23:55,500 | ERROR    | ImageApp1.views | log_exception        | Line 71   | Exception occurred in D:\IDP_AI_App\Backend\Django Projects (2)\Django Projects\ImageExtraction\ImageApp1\views.py, line 468: response = model.generate_content([data_part, REIMBURSEMENT_EXTRACTION_PROMPT])
2025-06-24 08:23:55,500 | ERROR    | ImageApp1.views | log_exception        | Line 71   | Exception occurred in C:\Sujata\Python39\lib\site-packages\google\generativeai\generative_models.py, line 331: response = self._client.generate_content(
2025-06-24 08:23:55,501 | ERROR    | ImageApp1.views | log_exception        | Line 71   | Exception occurred in C:\Sujata\Python39\lib\site-packages\google\ai\generativelanguage_v1beta\services\generative_service\client.py, line 835: response = rpc(
2025-06-24 08:23:55,502 | ERROR    | ImageApp1.views | log_exception        | Line 71   | Exception occurred in C:\Sujata\Python39\lib\site-packages\google\api_core\gapic_v1\method.py, line 131: return wrapped_func(*args, **kwargs)
2025-06-24 08:23:55,503 | ERROR    | ImageApp1.views | log_exception        | Line 71   | Exception occurred in C:\Sujata\Python39\lib\site-packages\google\api_core\retry\retry_unary.py, line 294: return retry_target(
2025-06-24 08:23:55,503 | ERROR    | ImageApp1.views | log_exception        | Line 71   | Exception occurred in C:\Sujata\Python39\lib\site-packages\google\api_core\retry\retry_unary.py, line 156: next_sleep = _retry_error_helper(
2025-06-24 08:23:55,504 | ERROR    | ImageApp1.views | log_exception        | Line 71   | Exception occurred in C:\Sujata\Python39\lib\site-packages\google\api_core\retry\retry_base.py, line 214: raise final_exc from source_exc
2025-06-24 08:23:55,504 | ERROR    | ImageApp1.views | log_exception        | Line 71   | Exception occurred in C:\Sujata\Python39\lib\site-packages\google\api_core\retry\retry_unary.py, line 147: result = target()
2025-06-24 08:23:55,505 | ERROR    | ImageApp1.views | log_exception        | Line 71   | Exception occurred in C:\Sujata\Python39\lib\site-packages\google\api_core\timeout.py, line 130: return func(*args, **kwargs)
2025-06-24 08:23:55,506 | ERROR    | ImageApp1.views | log_exception        | Line 71   | Exception occurred in C:\Sujata\Python39\lib\site-packages\google\api_core\grpc_helpers.py, line 78: raise exceptions.from_grpc_error(exc) from exc
2025-06-24 08:23:55,507 | ERROR    |  django.request | log_response         | Line 241  | Internal Server Error: /IDA/upload/
2025-06-24 08:28:22,890 | INFO     | authentication.views | post                 | Line 155  | Login attempt received.
2025-06-24 08:28:23,457 | INFO     | authentication.views | post                 | Line 172  | Login successful for user: abc
2025-06-24 08:29:19,219 | INFO     | ImageApp1.views | post                 | Line 318  | Upload request received
2025-06-24 08:29:19,458 | ERROR    | ImageApp1.views | post                 | Line 537  | 500
2025-06-24 08:29:19,459 | ERROR    | ImageApp1.views | post                 | Line 538  | Error while processing document.
2025-06-24 08:29:19,462 | ERROR    | ImageApp1.views | log_exception        | Line 71   | Exception occurred in D:\IDP_AI_App\Backend\Django Projects (2)\Django Projects\ImageExtraction\ImageApp1\views.py, line 468: response = model.generate_content([data_part, REIMBURSEMENT_EXTRACTION_PROMPT])
2025-06-24 08:29:19,462 | ERROR    | ImageApp1.views | log_exception        | Line 71   | Exception occurred in C:\Sujata\Python39\lib\site-packages\google\generativeai\generative_models.py, line 331: response = self._client.generate_content(
2025-06-24 08:29:19,463 | ERROR    | ImageApp1.views | log_exception        | Line 71   | Exception occurred in C:\Sujata\Python39\lib\site-packages\google\ai\generativelanguage_v1beta\services\generative_service\client.py, line 835: response = rpc(
2025-06-24 08:29:19,463 | ERROR    | ImageApp1.views | log_exception        | Line 71   | Exception occurred in C:\Sujata\Python39\lib\site-packages\google\api_core\gapic_v1\method.py, line 131: return wrapped_func(*args, **kwargs)
2025-06-24 08:29:19,464 | ERROR    | ImageApp1.views | log_exception        | Line 71   | Exception occurred in C:\Sujata\Python39\lib\site-packages\google\api_core\retry\retry_unary.py, line 294: return retry_target(
2025-06-24 08:29:19,465 | ERROR    | ImageApp1.views | log_exception        | Line 71   | Exception occurred in C:\Sujata\Python39\lib\site-packages\google\api_core\retry\retry_unary.py, line 156: next_sleep = _retry_error_helper(
2025-06-24 08:29:19,465 | ERROR    | ImageApp1.views | log_exception        | Line 71   | Exception occurred in C:\Sujata\Python39\lib\site-packages\google\api_core\retry\retry_base.py, line 214: raise final_exc from source_exc
2025-06-24 08:29:19,466 | ERROR    | ImageApp1.views | log_exception        | Line 71   | Exception occurred in C:\Sujata\Python39\lib\site-packages\google\api_core\retry\retry_unary.py, line 147: result = target()
2025-06-24 08:29:19,466 | ERROR    | ImageApp1.views | log_exception        | Line 71   | Exception occurred in C:\Sujata\Python39\lib\site-packages\google\api_core\timeout.py, line 130: return func(*args, **kwargs)
2025-06-24 08:29:19,467 | ERROR    | ImageApp1.views | log_exception        | Line 71   | Exception occurred in C:\Sujata\Python39\lib\site-packages\google\api_core\grpc_helpers.py, line 78: raise exceptions.from_grpc_error(exc) from exc
2025-06-24 08:29:19,468 | ERROR    |  django.request | log_response         | Line 241  | Internal Server Error: /IDA/upload/
2025-06-24 08:36:02,336 | INFO     | django.utils.autoreload | trigger_reload       | Line 265  | D:\IDP_AI_App\Backend\Django Projects (2)\Django Projects\ImageExtraction\ImageApp1\views.py changed, reloading.
2025-06-24 08:36:06,236 | INFO     | django.utils.autoreload | run_with_reloader    | Line 667  | Watching for file changes with StatReloader
2025-06-24 08:42:31,532 | INFO     | django.utils.autoreload | trigger_reload       | Line 265  | D:\IDP_AI_App\Backend\Django Projects (2)\Django Projects\ImageExtraction\ImageApp1\views.py changed, reloading.
2025-06-24 08:42:33,263 | INFO     | django.utils.autoreload | run_with_reloader    | Line 667  | Watching for file changes with StatReloader
2025-06-24 08:42:38,335 | DEBUG    | google.cloud.storage._opentelemetry_tracing | <module>             | Line 42   | This service is instrumented using OpenTelemetry. OpenTelemetry or one of its components could not be imported; please add compatible versions of opentelemetry-api and opentelemetry-instrumentation packages in order to get Storage Tracing data.
2025-06-24 08:43:06,642 | INFO     | django.utils.autoreload | trigger_reload       | Line 265  | D:\IDP_AI_App\Backend\Django Projects (2)\Django Projects\ImageExtraction\ImageApp1\views.py changed, reloading.
2025-06-24 08:43:09,003 | INFO     | django.utils.autoreload | run_with_reloader    | Line 667  | Watching for file changes with StatReloader
2025-06-24 08:43:14,431 | DEBUG    | google.cloud.storage._opentelemetry_tracing | <module>             | Line 42   | This service is instrumented using OpenTelemetry. OpenTelemetry or one of its components could not be imported; please add compatible versions of opentelemetry-api and opentelemetry-instrumentation packages in order to get Storage Tracing data.
2025-06-24 08:43:27,516 | INFO     | authentication.views | post                 | Line 155  | Login attempt received.
2025-06-24 08:43:28,074 | INFO     | authentication.views | post                 | Line 172  | Login successful for user: abc
2025-06-24 08:43:54,496 | INFO     | ImageApp1.views | post                 | Line 334  | Upload request received
2025-06-24 08:43:54,548 | ERROR    | ImageApp1.views | post                 | Line 549  | 500
2025-06-24 08:43:54,549 | ERROR    | ImageApp1.views | post                 | Line 550  | Error while processing document.
2025-06-24 08:43:54,554 | ERROR    | ImageApp1.views | log_exception        | Line 71   | Exception occurred in D:\IDP_AI_App\Backend\Django Projects (2)\Django Projects\ImageExtraction\ImageApp1\views.py, line 481: response = model.generate_content([data_part, REIMBURSEMENT_EXTRACTION_PROMPT])
2025-06-24 08:43:54,556 | ERROR    | ImageApp1.views | log_exception        | Line 71   | Exception occurred in C:\Sujata\Python39\lib\site-packages\vertexai\generative_models\_generative_models.py, line 710: return self._generate_content(
2025-06-24 08:43:54,556 | ERROR    | ImageApp1.views | log_exception        | Line 71   | Exception occurred in C:\Sujata\Python39\lib\site-packages\vertexai\generative_models\_generative_models.py, line 827: request = self._prepare_request(
2025-06-24 08:43:54,557 | ERROR    | ImageApp1.views | log_exception        | Line 71   | Exception occurred in C:\Sujata\Python39\lib\site-packages\vertexai\generative_models\_generative_models.py, line 3499: request_v1beta1 = super()._prepare_request(
2025-06-24 08:43:54,558 | ERROR    | ImageApp1.views | log_exception        | Line 71   | Exception occurred in C:\Sujata\Python39\lib\site-packages\vertexai\generative_models\_generative_models.py, line 562: _validate_generate_content_parameters(
2025-06-24 08:43:54,558 | ERROR    | ImageApp1.views | log_exception        | Line 71   | Exception occurred in C:\Sujata\Python39\lib\site-packages\vertexai\generative_models\_generative_models.py, line 246: _validate_contents_type_as_valid_sequence(contents)
2025-06-24 08:43:54,559 | ERROR    | ImageApp1.views | log_exception        | Line 71   | Exception occurred in C:\Sujata\Python39\lib\site-packages\vertexai\generative_models\_generative_models.py, line 297: raise TypeError(
2025-06-24 08:43:54,563 | ERROR    |  django.request | log_response         | Line 241  | Internal Server Error: /IDA/upload/
2025-06-24 08:49:56,528 | INFO     | ImageApp1.views | post                 | Line 334  | Upload request received
2025-06-24 08:49:48,767 | INFO     | django.utils.autoreload | trigger_reload       | Line 265  | D:\IDP_AI_App\Backend\Django Projects (2)\Django Projects\ImageExtraction\ImageApp1\views.py changed, reloading.
2025-06-24 08:50:59,120 | INFO     | django.utils.autoreload | run_with_reloader    | Line 667  | Watching for file changes with StatReloader
2025-06-24 08:51:04,002 | DEBUG    | google.cloud.storage._opentelemetry_tracing | <module>             | Line 42   | This service is instrumented using OpenTelemetry. OpenTelemetry or one of its components could not be imported; please add compatible versions of opentelemetry-api and opentelemetry-instrumentation packages in order to get Storage Tracing data.
2025-06-24 08:51:11,200 | INFO     | django.utils.autoreload | run_with_reloader    | Line 667  | Watching for file changes with StatReloader
2025-06-24 08:51:16,354 | DEBUG    | google.cloud.storage._opentelemetry_tracing | <module>             | Line 42   | This service is instrumented using OpenTelemetry. OpenTelemetry or one of its components could not be imported; please add compatible versions of opentelemetry-api and opentelemetry-instrumentation packages in order to get Storage Tracing data.
2025-06-24 08:51:24,399 | INFO     | authentication.views | post                 | Line 155  | Login attempt received.
2025-06-24 08:51:24,973 | INFO     | authentication.views | post                 | Line 172  | Login successful for user: abc
2025-06-24 08:51:48,872 | INFO     | ImageApp1.views | post                 | Line 334  | Upload request received
2025-06-24 08:51:48,919 | ERROR    | ImageApp1.views | post                 | Line 564  | Error while processing document: name 'Part' is not defined
Traceback (most recent call last):
  File "D:\IDP_AI_App\Backend\Django Projects (2)\Django Projects\ImageExtraction\ImageApp1\views.py", line 378, in post
    data_part = Part.from_data(data=f.read(), mime_type="application/pdf")
NameError: name 'Part' is not defined
2025-06-24 08:51:48,922 | ERROR    | ImageApp1.views | log_exception        | Line 71   | Exception occurred in D:\IDP_AI_App\Backend\Django Projects (2)\Django Projects\ImageExtraction\ImageApp1\views.py, line 378: data_part = Part.from_data(data=f.read(), mime_type="application/pdf")
2025-06-24 08:51:48,925 | ERROR    |  django.request | log_response         | Line 241  | Internal Server Error: /IDA/upload/
2025-06-24 08:52:58,518 | INFO     | django.utils.autoreload | trigger_reload       | Line 265  | D:\IDP_AI_App\Backend\Django Projects (2)\Django Projects\ImageExtraction\ImageApp1\views.py changed, reloading.
2025-06-24 08:53:01,042 | INFO     | django.utils.autoreload | run_with_reloader    | Line 667  | Watching for file changes with StatReloader
2025-06-24 08:53:06,252 | DEBUG    | google.cloud.storage._opentelemetry_tracing | <module>             | Line 42   | This service is instrumented using OpenTelemetry. OpenTelemetry or one of its components could not be imported; please add compatible versions of opentelemetry-api and opentelemetry-instrumentation packages in order to get Storage Tracing data.
2025-06-24 08:53:08,002 | INFO     | ImageApp1.views | post                 | Line 334  | Upload request received
2025-06-24 08:53:08,226 | ERROR    | ImageApp1.views | post                 | Line 564  | Error while processing document: 401 Request had invalid authentication credentials. Expected OAuth 2 access token, login cookie or other valid authentication credential. See https://developers.google.com/identity/sign-in/web/devconsole-project.
Traceback (most recent call last):
  File "C:\Sujata\Python39\lib\site-packages\google\api_core\grpc_helpers.py", line 76, in error_remapped_callable
    return callable_(*args, **kwargs)
  File "C:\Sujata\Python39\lib\site-packages\grpc\_interceptor.py", line 277, in __call__
    response, ignored_call = self._with_call(
  File "C:\Sujata\Python39\lib\site-packages\grpc\_interceptor.py", line 329, in _with_call
    call = self._interceptor.intercept_unary_unary(
  File "C:\Sujata\Python39\lib\site-packages\google\cloud\aiplatform_v1\services\prediction_service\transports\grpc.py", line 92, in intercept_unary_unary
    result = response.result()
  File "C:\Sujata\Python39\lib\site-packages\grpc\_channel.py", line 440, in result
    raise self
  File "C:\Sujata\Python39\lib\site-packages\grpc\_interceptor.py", line 315, in continuation
    response, call = self._thunk(new_method).with_call(
  File "C:\Sujata\Python39\lib\site-packages\grpc\_channel.py", line 1198, in with_call
    return _end_unary_response_blocking(state, call, True, None)
  File "C:\Sujata\Python39\lib\site-packages\grpc\_channel.py", line 1006, in _end_unary_response_blocking
    raise _InactiveRpcError(state)  # pytype: disable=not-instantiable
grpc._channel._InactiveRpcError: <_InactiveRpcError of RPC that terminated with:
	status = StatusCode.UNAUTHENTICATED
	details = "Request had invalid authentication credentials. Expected OAuth 2 access token, login cookie or other valid authentication credential. See https://developers.google.com/identity/sign-in/web/devconsole-project."
	debug_error_string = "UNKNOWN:Error received from peer ipv4:142.251.179.95:443 {grpc_message:"Request had invalid authentication credentials. Expected OAuth 2 access token, login cookie or other valid authentication credential. See https://developers.google.com/identity/sign-in/web/devconsole-project.", grpc_status:16, created_time:"2025-06-24T08:53:08.1858773+00:00"}"
>

The above exception was the direct cause of the following exception:

Traceback (most recent call last):
  File "D:\IDP_AI_App\Backend\Django Projects (2)\Django Projects\ImageExtraction\ImageApp1\views.py", line 494, in post
    response = model.generate_content([data_part, reimbursement_prompt_part]) # Corrected line
  File "C:\Sujata\Python39\lib\site-packages\vertexai\generative_models\_generative_models.py", line 710, in generate_content
    return self._generate_content(
  File "C:\Sujata\Python39\lib\site-packages\vertexai\generative_models\_generative_models.py", line 835, in _generate_content
    gapic_response = self._prediction_client.generate_content(request=request)
  File "C:\Sujata\Python39\lib\site-packages\google\cloud\aiplatform_v1\services\prediction_service\client.py", line 2276, in generate_content
    response = rpc(
  File "C:\Sujata\Python39\lib\site-packages\google\api_core\gapic_v1\method.py", line 131, in __call__
    return wrapped_func(*args, **kwargs)
  File "C:\Sujata\Python39\lib\site-packages\google\api_core\grpc_helpers.py", line 78, in error_remapped_callable
    raise exceptions.from_grpc_error(exc) from exc
google.api_core.exceptions.Unauthenticated: 401 Request had invalid authentication credentials. Expected OAuth 2 access token, login cookie or other valid authentication credential. See https://developers.google.com/identity/sign-in/web/devconsole-project.
2025-06-24 08:53:08,284 | ERROR    | ImageApp1.views | log_exception        | Line 71   | Exception occurred in D:\IDP_AI_App\Backend\Django Projects (2)\Django Projects\ImageExtraction\ImageApp1\views.py, line 494: response = model.generate_content([data_part, reimbursement_prompt_part]) # Corrected line
2025-06-24 08:53:08,289 | ERROR    | ImageApp1.views | log_exception        | Line 71   | Exception occurred in C:\Sujata\Python39\lib\site-packages\vertexai\generative_models\_generative_models.py, line 710: return self._generate_content(
2025-06-24 08:53:08,290 | ERROR    | ImageApp1.views | log_exception        | Line 71   | Exception occurred in C:\Sujata\Python39\lib\site-packages\vertexai\generative_models\_generative_models.py, line 835: gapic_response = self._prediction_client.generate_content(request=request)
2025-06-24 08:53:08,291 | ERROR    | ImageApp1.views | log_exception        | Line 71   | Exception occurred in C:\Sujata\Python39\lib\site-packages\google\cloud\aiplatform_v1\services\prediction_service\client.py, line 2276: response = rpc(
2025-06-24 08:53:08,291 | ERROR    | ImageApp1.views | log_exception        | Line 71   | Exception occurred in C:\Sujata\Python39\lib\site-packages\google\api_core\gapic_v1\method.py, line 131: return wrapped_func(*args, **kwargs)
2025-06-24 08:53:08,292 | ERROR    | ImageApp1.views | log_exception        | Line 71   | Exception occurred in C:\Sujata\Python39\lib\site-packages\google\api_core\grpc_helpers.py, line 78: raise exceptions.from_grpc_error(exc) from exc
2025-06-24 08:53:08,293 | ERROR    |  django.request | log_response         | Line 241  | Internal Server Error: /IDA/upload/
2025-06-24 09:50:01,969 | INFO     | django.utils.autoreload | trigger_reload       | Line 265  | D:\IDP_AI_App\Backend\Django Projects (2)\Django Projects\ImageExtraction\authentication\views.py changed, reloading.
2025-06-24 09:50:04,403 | INFO     | django.utils.autoreload | run_with_reloader    | Line 667  | Watching for file changes with StatReloader
2025-06-24 09:50:09,553 | DEBUG    | google.cloud.storage._opentelemetry_tracing | <module>             | Line 42   | This service is instrumented using OpenTelemetry. OpenTelemetry or one of its components could not be imported; please add compatible versions of opentelemetry-api and opentelemetry-instrumentation packages in order to get Storage Tracing data.
2025-06-24 09:50:26,269 | INFO     | authentication.views | post                 | Line 155  | Login attempt received.
2025-06-24 09:50:26,843 | INFO     | authentication.views | post                 | Line 172  | Login successful for user: abc
2025-06-24 09:51:14,498 | INFO     | django.utils.autoreload | trigger_reload       | Line 265  | D:\IDP_AI_App\Backend\Django Projects (2)\Django Projects\ImageExtraction\authentication\views.py changed, reloading.
2025-06-24 09:51:16,949 | INFO     | django.utils.autoreload | run_with_reloader    | Line 667  | Watching for file changes with StatReloader
2025-06-24 09:51:22,604 | DEBUG    | google.cloud.storage._opentelemetry_tracing | <module>             | Line 42   | This service is instrumented using OpenTelemetry. OpenTelemetry or one of its components could not be imported; please add compatible versions of opentelemetry-api and opentelemetry-instrumentation packages in order to get Storage Tracing data.
2025-06-24 09:52:27,626 | INFO     | ImageApp1.views | post                 | Line 334  | Upload request received
2025-06-24 09:52:27,851 | ERROR    | ImageApp1.views | post                 | Line 564  | Error while processing document: 401 Request had invalid authentication credentials. Expected OAuth 2 access token, login cookie or other valid authentication credential. See https://developers.google.com/identity/sign-in/web/devconsole-project.
Traceback (most recent call last):
  File "C:\Sujata\Python39\lib\site-packages\google\api_core\grpc_helpers.py", line 76, in error_remapped_callable
    return callable_(*args, **kwargs)
  File "C:\Sujata\Python39\lib\site-packages\grpc\_interceptor.py", line 277, in __call__
    response, ignored_call = self._with_call(
  File "C:\Sujata\Python39\lib\site-packages\grpc\_interceptor.py", line 329, in _with_call
    call = self._interceptor.intercept_unary_unary(
  File "C:\Sujata\Python39\lib\site-packages\google\cloud\aiplatform_v1\services\prediction_service\transports\grpc.py", line 92, in intercept_unary_unary
    result = response.result()
  File "C:\Sujata\Python39\lib\site-packages\grpc\_channel.py", line 440, in result
    raise self
  File "C:\Sujata\Python39\lib\site-packages\grpc\_interceptor.py", line 315, in continuation
    response, call = self._thunk(new_method).with_call(
  File "C:\Sujata\Python39\lib\site-packages\grpc\_channel.py", line 1198, in with_call
    return _end_unary_response_blocking(state, call, True, None)
  File "C:\Sujata\Python39\lib\site-packages\grpc\_channel.py", line 1006, in _end_unary_response_blocking
    raise _InactiveRpcError(state)  # pytype: disable=not-instantiable
grpc._channel._InactiveRpcError: <_InactiveRpcError of RPC that terminated with:
	status = StatusCode.UNAUTHENTICATED
	details = "Request had invalid authentication credentials. Expected OAuth 2 access token, login cookie or other valid authentication credential. See https://developers.google.com/identity/sign-in/web/devconsole-project."
	debug_error_string = "UNKNOWN:Error received from peer ipv4:64.233.180.95:443 {grpc_message:"Request had invalid authentication credentials. Expected OAuth 2 access token, login cookie or other valid authentication credential. See https://developers.google.com/identity/sign-in/web/devconsole-project.", grpc_status:16, created_time:"2025-06-24T09:52:27.8114763+00:00"}"
>

The above exception was the direct cause of the following exception:

Traceback (most recent call last):
  File "D:\IDP_AI_App\Backend\Django Projects (2)\Django Projects\ImageExtraction\ImageApp1\views.py", line 494, in post
    response = model.generate_content([data_part, reimbursement_prompt_part]) # Corrected line
  File "C:\Sujata\Python39\lib\site-packages\vertexai\generative_models\_generative_models.py", line 710, in generate_content
    return self._generate_content(
  File "C:\Sujata\Python39\lib\site-packages\vertexai\generative_models\_generative_models.py", line 835, in _generate_content
    gapic_response = self._prediction_client.generate_content(request=request)
  File "C:\Sujata\Python39\lib\site-packages\google\cloud\aiplatform_v1\services\prediction_service\client.py", line 2276, in generate_content
    response = rpc(
  File "C:\Sujata\Python39\lib\site-packages\google\api_core\gapic_v1\method.py", line 131, in __call__
    return wrapped_func(*args, **kwargs)
  File "C:\Sujata\Python39\lib\site-packages\google\api_core\grpc_helpers.py", line 78, in error_remapped_callable
    raise exceptions.from_grpc_error(exc) from exc
google.api_core.exceptions.Unauthenticated: 401 Request had invalid authentication credentials. Expected OAuth 2 access token, login cookie or other valid authentication credential. See https://developers.google.com/identity/sign-in/web/devconsole-project.
2025-06-24 09:52:27,866 | ERROR    | ImageApp1.views | log_exception        | Line 71   | Exception occurred in D:\IDP_AI_App\Backend\Django Projects (2)\Django Projects\ImageExtraction\ImageApp1\views.py, line 494: response = model.generate_content([data_part, reimbursement_prompt_part]) # Corrected line
2025-06-24 09:52:27,871 | ERROR    | ImageApp1.views | log_exception        | Line 71   | Exception occurred in C:\Sujata\Python39\lib\site-packages\vertexai\generative_models\_generative_models.py, line 710: return self._generate_content(
2025-06-24 09:52:27,871 | ERROR    | ImageApp1.views | log_exception        | Line 71   | Exception occurred in C:\Sujata\Python39\lib\site-packages\vertexai\generative_models\_generative_models.py, line 835: gapic_response = self._prediction_client.generate_content(request=request)
2025-06-24 09:52:27,872 | ERROR    | ImageApp1.views | log_exception        | Line 71   | Exception occurred in C:\Sujata\Python39\lib\site-packages\google\cloud\aiplatform_v1\services\prediction_service\client.py, line 2276: response = rpc(
2025-06-24 09:52:27,872 | ERROR    | ImageApp1.views | log_exception        | Line 71   | Exception occurred in C:\Sujata\Python39\lib\site-packages\google\api_core\gapic_v1\method.py, line 131: return wrapped_func(*args, **kwargs)
2025-06-24 09:52:27,873 | ERROR    | ImageApp1.views | log_exception        | Line 71   | Exception occurred in C:\Sujata\Python39\lib\site-packages\google\api_core\grpc_helpers.py, line 78: raise exceptions.from_grpc_error(exc) from exc
2025-06-24 09:52:27,874 | ERROR    |  django.request | log_response         | Line 241  | Internal Server Error: /IDA/upload/
2025-06-24 09:53:34,231 | INFO     | django.utils.autoreload | run_with_reloader    | Line 667  | Watching for file changes with StatReloader
2025-06-24 09:53:39,220 | DEBUG    | google.cloud.storage._opentelemetry_tracing | <module>             | Line 42   | This service is instrumented using OpenTelemetry. OpenTelemetry or one of its components could not be imported; please add compatible versions of opentelemetry-api and opentelemetry-instrumentation packages in order to get Storage Tracing data.
2025-06-24 09:54:15,152 | INFO     | django.utils.autoreload | trigger_reload       | Line 265  | D:\IDP_AI_App\Backend\Django Projects (2)\Django Projects\ImageExtraction\authentication\views.py changed, reloading.
2025-06-24 09:54:17,466 | INFO     | django.utils.autoreload | run_with_reloader    | Line 667  | Watching for file changes with StatReloader
2025-06-24 09:54:22,721 | DEBUG    | google.cloud.storage._opentelemetry_tracing | <module>             | Line 42   | This service is instrumented using OpenTelemetry. OpenTelemetry or one of its components could not be imported; please add compatible versions of opentelemetry-api and opentelemetry-instrumentation packages in order to get Storage Tracing data.
2025-06-24 09:54:34,851 | INFO     | authentication.views | post                 | Line 99   | Login attempt received.
2025-06-24 09:54:35,428 | INFO     | authentication.views | post                 | Line 116  | Login successful for user: NikhilVDX
2025-06-24 09:55:01,764 | INFO     | ImageApp1.views | post                 | Line 334  | Upload request received
2025-06-24 09:55:01,957 | ERROR    | ImageApp1.views | post                 | Line 564  | Error while processing document: 401 Request had invalid authentication credentials. Expected OAuth 2 access token, login cookie or other valid authentication credential. See https://developers.google.com/identity/sign-in/web/devconsole-project.
Traceback (most recent call last):
  File "C:\Sujata\Python39\lib\site-packages\google\api_core\grpc_helpers.py", line 76, in error_remapped_callable
    return callable_(*args, **kwargs)
  File "C:\Sujata\Python39\lib\site-packages\grpc\_interceptor.py", line 277, in __call__
    response, ignored_call = self._with_call(
  File "C:\Sujata\Python39\lib\site-packages\grpc\_interceptor.py", line 329, in _with_call
    call = self._interceptor.intercept_unary_unary(
  File "C:\Sujata\Python39\lib\site-packages\google\cloud\aiplatform_v1\services\prediction_service\transports\grpc.py", line 92, in intercept_unary_unary
    result = response.result()
  File "C:\Sujata\Python39\lib\site-packages\grpc\_channel.py", line 440, in result
    raise self
  File "C:\Sujata\Python39\lib\site-packages\grpc\_interceptor.py", line 315, in continuation
    response, call = self._thunk(new_method).with_call(
  File "C:\Sujata\Python39\lib\site-packages\grpc\_channel.py", line 1198, in with_call
    return _end_unary_response_blocking(state, call, True, None)
  File "C:\Sujata\Python39\lib\site-packages\grpc\_channel.py", line 1006, in _end_unary_response_blocking
    raise _InactiveRpcError(state)  # pytype: disable=not-instantiable
grpc._channel._InactiveRpcError: <_InactiveRpcError of RPC that terminated with:
	status = StatusCode.UNAUTHENTICATED
	details = "Request had invalid authentication credentials. Expected OAuth 2 access token, login cookie or other valid authentication credential. See https://developers.google.com/identity/sign-in/web/devconsole-project."
	debug_error_string = "UNKNOWN:Error received from peer ipv4:192.178.218.95:443 {grpc_message:"Request had invalid authentication credentials. Expected OAuth 2 access token, login cookie or other valid authentication credential. See https://developers.google.com/identity/sign-in/web/devconsole-project.", grpc_status:16, created_time:"2025-06-24T09:55:01.9156796+00:00"}"
>

The above exception was the direct cause of the following exception:

Traceback (most recent call last):
  File "D:\IDP_AI_App\Backend\Django Projects (2)\Django Projects\ImageExtraction\ImageApp1\views.py", line 448, in post
    response = model.generate_content([data_part, prompt_text_part])
  File "C:\Sujata\Python39\lib\site-packages\vertexai\generative_models\_generative_models.py", line 710, in generate_content
    return self._generate_content(
  File "C:\Sujata\Python39\lib\site-packages\vertexai\generative_models\_generative_models.py", line 835, in _generate_content
    gapic_response = self._prediction_client.generate_content(request=request)
  File "C:\Sujata\Python39\lib\site-packages\google\cloud\aiplatform_v1\services\prediction_service\client.py", line 2276, in generate_content
    response = rpc(
  File "C:\Sujata\Python39\lib\site-packages\google\api_core\gapic_v1\method.py", line 131, in __call__
    return wrapped_func(*args, **kwargs)
  File "C:\Sujata\Python39\lib\site-packages\google\api_core\grpc_helpers.py", line 78, in error_remapped_callable
    raise exceptions.from_grpc_error(exc) from exc
google.api_core.exceptions.Unauthenticated: 401 Request had invalid authentication credentials. Expected OAuth 2 access token, login cookie or other valid authentication credential. See https://developers.google.com/identity/sign-in/web/devconsole-project.
2025-06-24 09:55:01,971 | ERROR    | ImageApp1.views | log_exception        | Line 71   | Exception occurred in D:\IDP_AI_App\Backend\Django Projects (2)\Django Projects\ImageExtraction\ImageApp1\views.py, line 448: response = model.generate_content([data_part, prompt_text_part])
2025-06-24 09:55:01,976 | ERROR    | ImageApp1.views | log_exception        | Line 71   | Exception occurred in C:\Sujata\Python39\lib\site-packages\vertexai\generative_models\_generative_models.py, line 710: return self._generate_content(
2025-06-24 09:55:01,976 | ERROR    | ImageApp1.views | log_exception        | Line 71   | Exception occurred in C:\Sujata\Python39\lib\site-packages\vertexai\generative_models\_generative_models.py, line 835: gapic_response = self._prediction_client.generate_content(request=request)
2025-06-24 09:55:01,977 | ERROR    | ImageApp1.views | log_exception        | Line 71   | Exception occurred in C:\Sujata\Python39\lib\site-packages\google\cloud\aiplatform_v1\services\prediction_service\client.py, line 2276: response = rpc(
2025-06-24 09:55:01,977 | ERROR    | ImageApp1.views | log_exception        | Line 71   | Exception occurred in C:\Sujata\Python39\lib\site-packages\google\api_core\gapic_v1\method.py, line 131: return wrapped_func(*args, **kwargs)
2025-06-24 09:55:01,978 | ERROR    | ImageApp1.views | log_exception        | Line 71   | Exception occurred in C:\Sujata\Python39\lib\site-packages\google\api_core\grpc_helpers.py, line 78: raise exceptions.from_grpc_error(exc) from exc
2025-06-24 09:55:01,979 | ERROR    |  django.request | log_response         | Line 241  | Internal Server Error: /IDA/upload/
2025-06-24 09:57:27,787 | INFO     | django.utils.autoreload | trigger_reload       | Line 265  | D:\IDP_AI_App\Backend\Django Projects (2)\Django Projects\ImageExtraction\ImageExtraction\settings.py changed, reloading.
2025-06-24 10:00:01,615 | INFO     | django.utils.autoreload | run_with_reloader    | Line 667  | Watching for file changes with StatReloader
2025-06-24 10:00:06,680 | DEBUG    | google.cloud.storage._opentelemetry_tracing | <module>             | Line 42   | This service is instrumented using OpenTelemetry. OpenTelemetry or one of its components could not be imported; please add compatible versions of opentelemetry-api and opentelemetry-instrumentation packages in order to get Storage Tracing data.
2025-06-24 11:11:33,663 | INFO     | django.utils.autoreload | run_with_reloader    | Line 667  | Watching for file changes with StatReloader
2025-06-24 11:11:38,732 | DEBUG    | google.cloud.storage._opentelemetry_tracing | <module>             | Line 42   | This service is instrumented using OpenTelemetry. OpenTelemetry or one of its components could not be imported; please add compatible versions of opentelemetry-api and opentelemetry-instrumentation packages in order to get Storage Tracing data.
2025-06-24 11:13:00,356 | INFO     | authentication.views | post                 | Line 99   | Login attempt received.
2025-06-24 11:13:00,918 | INFO     | authentication.views | post                 | Line 116  | Login successful for user: abc
2025-06-24 11:13:16,276 | INFO     | ImageApp1.views | post                 | Line 334  | Upload request received
2025-06-24 11:13:18,950 | INFO     |            root | post                 | Line 500  | Input tokens: 1563, Output tokens: 79
2025-06-24 11:13:22,651 | INFO     | ImageApp1.views | post                 | Line 541  | Document processed and saved successfully. Document ID: gAAAAABoWohST4LxzBjXxBu7CvhDMW1HXrlvDzpjCavEH7F00VVVJRO4ZtBdvXlwYdrMocy61YMhuUzvXxuhq3NmB6boZN6FLA==
2025-06-24 11:13:29,753 | INFO     | authentication.views | post                 | Line 99   | Login attempt received.
2025-06-24 11:13:30,318 | INFO     | authentication.views | post                 | Line 116  | Login successful for user: NikhilVDX
2025-06-24 11:14:14,708 | INFO     | ImageApp1.views | post                 | Line 334  | Upload request received
2025-06-24 11:14:25,956 | INFO     | ImageApp1.views | post                 | Line 541  | Document processed and saved successfully. Document ID: gAAAAABoWoiRwXdHaINC_zKOQ_2ogRNlzZ5z5reZiJFvxchSH50_Y1zUBCPEbRq9SeD3Uq8OzlTUIU1JcZLQAvu-G4pLU5sDfQ==
2025-06-24 11:14:26,128 | INFO     | ImageApp1.views | get                  | Line 126  | GetDocumentByIdView called with encrypted ID: gAAAAABoWoiRwXdHaINC_zKOQ_2ogRNlzZ5z5reZiJFvxchSH50_Y1zUBCPEbRq9SeD3Uq8OzlTUIU1JcZLQAvu-G4pLU5sDfQ==
2025-06-24 11:14:26,129 | DEBUG    | ImageApp1.views | get                  | Line 130  | Decrypted ID: 182
2025-06-24 11:14:26,141 | INFO     | ImageApp1.views | get                  | Line 134  | Document 182 retrieved successfully
2025-06-24 11:15:00,367 | INFO     | ImageApp1.views | post                 | Line 334  | Upload request received
2025-06-24 11:15:04,671 | INFO     |            root | post                 | Line 500  | Input tokens: 1305, Output tokens: 279
2025-06-24 11:15:08,881 | INFO     | ImageApp1.views | post                 | Line 541  | Document processed and saved successfully. Document ID: gAAAAABoWoi8tOa4aO4yNj800pZTyoui1zv4w7DGAUniGp0vronVe5zASSRUhKMNOKqgQlm5HXWwGJY1FCHdrnphQf1h99BZHA==
2025-06-24 11:15:09,058 | INFO     | ImageApp1.views | get                  | Line 126  | GetDocumentByIdView called with encrypted ID: gAAAAABoWoi8tOa4aO4yNj800pZTyoui1zv4w7DGAUniGp0vronVe5zASSRUhKMNOKqgQlm5HXWwGJY1FCHdrnphQf1h99BZHA==
2025-06-24 11:15:09,059 | DEBUG    | ImageApp1.views | get                  | Line 130  | Decrypted ID: 183
2025-06-24 11:15:09,072 | INFO     | ImageApp1.views | get                  | Line 134  | Document 183 retrieved successfully
2025-06-24 11:18:27,477 | INFO     | ImageApp1.views | get                  | Line 162  | UserDocumentView accessed by user ID: 7
2025-06-24 11:18:27,478 | INFO     | ImageApp1.views | get                  | Line 169  | Fetching documents for user ID: 7
2025-06-24 11:18:27,508 | INFO     | ImageApp1.views | get                  | Line 173  | 104 documents retrieved successfully.
2025-06-24 11:18:27,516 | INFO     | ImageApp1.views | get                  | Line 183  | 104 documents retrieved. Total input: 82843, output: 32388
2025-06-24 11:24:13,858 | INFO     | ImageApp1.views | get                  | Line 162  | UserDocumentView accessed by user ID: 7
2025-06-24 11:24:13,861 | INFO     | ImageApp1.views | get                  | Line 169  | Fetching documents for user ID: 7
2025-06-24 11:24:13,890 | INFO     | ImageApp1.views | get                  | Line 173  | 104 documents retrieved successfully.
2025-06-24 11:24:13,899 | INFO     | ImageApp1.views | get                  | Line 183  | 104 documents retrieved. Total input: 82843, output: 32388
2025-06-24 11:24:48,842 | INFO     | ImageApp1.views | get                  | Line 162  | UserDocumentView accessed by user ID: 7
2025-06-24 11:24:48,843 | INFO     | ImageApp1.views | get                  | Line 169  | Fetching documents for user ID: 7
2025-06-24 11:24:48,876 | INFO     | ImageApp1.views | get                  | Line 173  | 104 documents retrieved successfully.
2025-06-24 11:24:48,884 | INFO     | ImageApp1.views | get                  | Line 183  | 104 documents retrieved. Total input: 82843, output: 32388
2025-06-24 11:25:38,811 | INFO     | ImageApp1.views | get                  | Line 162  | UserDocumentView accessed by user ID: 7
2025-06-24 11:25:38,812 | INFO     | ImageApp1.views | get                  | Line 169  | Fetching documents for user ID: 7
2025-06-24 11:25:38,842 | INFO     | ImageApp1.views | get                  | Line 173  | 104 documents retrieved successfully.
2025-06-24 11:25:38,850 | INFO     | ImageApp1.views | get                  | Line 183  | 104 documents retrieved. Total input: 82843, output: 32388
2025-06-24 11:26:11,833 | INFO     | ImageApp1.views | get                  | Line 162  | UserDocumentView accessed by user ID: 7
2025-06-24 11:26:11,834 | INFO     | ImageApp1.views | get                  | Line 169  | Fetching documents for user ID: 7
2025-06-24 11:26:11,865 | INFO     | ImageApp1.views | get                  | Line 173  | 104 documents retrieved successfully.
2025-06-24 11:26:11,874 | INFO     | ImageApp1.views | get                  | Line 183  | 104 documents retrieved. Total input: 82843, output: 32388
2025-06-24 11:27:13,823 | INFO     | ImageApp1.views | get                  | Line 162  | UserDocumentView accessed by user ID: 7
2025-06-24 11:27:13,824 | INFO     | ImageApp1.views | get                  | Line 169  | Fetching documents for user ID: 7
2025-06-24 11:27:13,855 | INFO     | ImageApp1.views | get                  | Line 173  | 104 documents retrieved successfully.
2025-06-24 11:27:13,864 | INFO     | ImageApp1.views | get                  | Line 183  | 104 documents retrieved. Total input: 82843, output: 32388
2025-06-24 11:27:29,819 | INFO     | ImageApp1.views | get                  | Line 162  | UserDocumentView accessed by user ID: 7
2025-06-24 11:27:29,821 | INFO     | ImageApp1.views | get                  | Line 169  | Fetching documents for user ID: 7
2025-06-24 11:27:29,852 | INFO     | ImageApp1.views | get                  | Line 173  | 104 documents retrieved successfully.
2025-06-24 11:27:29,860 | INFO     | ImageApp1.views | get                  | Line 183  | 104 documents retrieved. Total input: 82843, output: 32388
2025-06-24 11:27:50,834 | INFO     | ImageApp1.views | get                  | Line 162  | UserDocumentView accessed by user ID: 7
2025-06-24 11:27:50,835 | INFO     | ImageApp1.views | get                  | Line 169  | Fetching documents for user ID: 7
2025-06-24 11:27:50,868 | INFO     | ImageApp1.views | get                  | Line 173  | 104 documents retrieved successfully.
2025-06-24 11:27:50,877 | INFO     | ImageApp1.views | get                  | Line 183  | 104 documents retrieved. Total input: 82843, output: 32388
2025-06-24 11:28:09,818 | INFO     | ImageApp1.views | get                  | Line 162  | UserDocumentView accessed by user ID: 7
2025-06-24 11:28:09,819 | INFO     | ImageApp1.views | get                  | Line 169  | Fetching documents for user ID: 7
2025-06-24 11:28:09,852 | INFO     | ImageApp1.views | get                  | Line 173  | 104 documents retrieved successfully.
2025-06-24 11:28:09,862 | INFO     | ImageApp1.views | get                  | Line 183  | 104 documents retrieved. Total input: 82843, output: 32388
2025-06-24 11:29:04,008 | WARNING  |  django.request | log_response         | Line 241  | Unauthorized: /IDA/get-document/gAAAAABoWovJpOPwafb2tLPgfOpUDCoTyHW778zk5dsYMm2UNgiOMnZDRHkDlaLQY6PW1Dqm1rd3RJrCDDsbeyQUJmooJvOc_w==/
2025-06-24 11:29:09,315 | WARNING  |  django.request | log_response         | Line 241  | Unauthorized: /IDA/documents/
2025-06-24 11:29:18,174 | INFO     | authentication.views | post                 | Line 99   | Login attempt received.
2025-06-24 11:29:18,740 | INFO     | authentication.views | post                 | Line 116  | Login successful for user: NikhilVDX
2025-06-24 11:29:25,665 | INFO     | ImageApp1.views | get                  | Line 162  | UserDocumentView accessed by user ID: 7
2025-06-24 11:29:25,665 | INFO     | ImageApp1.views | get                  | Line 169  | Fetching documents for user ID: 7
2025-06-24 11:29:25,694 | INFO     | ImageApp1.views | get                  | Line 173  | 104 documents retrieved successfully.
2025-06-24 11:29:25,703 | INFO     | ImageApp1.views | get                  | Line 183  | 104 documents retrieved. Total input: 82843, output: 32388
2025-06-24 11:29:48,184 | INFO     | ImageApp1.views | get                  | Line 126  | GetDocumentByIdView called with encrypted ID: gAAAAABoWowVz5L696MQW3euiCXEXmfXrn9UtELMZ5FaP__mSGyQDwLFydX9uYn7_beUlIfDV6eUPpQ6WNTbyaRliWZ1NfpsAA==
2025-06-24 11:29:48,185 | DEBUG    | ImageApp1.views | get                  | Line 130  | Decrypted ID: 183
2025-06-24 11:29:48,202 | INFO     | ImageApp1.views | get                  | Line 134  | Document 183 retrieved successfully
2025-06-24 11:39:48,894 | INFO     | ImageApp1.views | get                  | Line 126  | GetDocumentByIdView called with encrypted ID: gAAAAABoWowVz5L696MQW3euiCXEXmfXrn9UtELMZ5FaP__mSGyQDwLFydX9uYn7_beUlIfDV6eUPpQ6WNTbyaRliWZ1NfpsAA==
2025-06-24 11:39:48,895 | DEBUG    | ImageApp1.views | get                  | Line 130  | Decrypted ID: 183
2025-06-24 11:39:48,917 | INFO     | ImageApp1.views | get                  | Line 134  | Document 183 retrieved successfully
2025-06-24 11:40:09,110 | INFO     | ImageApp1.views | get                  | Line 162  | UserDocumentView accessed by user ID: 7
2025-06-24 11:40:09,111 | INFO     | ImageApp1.views | get                  | Line 169  | Fetching documents for user ID: 7
2025-06-24 11:40:09,143 | INFO     | ImageApp1.views | get                  | Line 173  | 104 documents retrieved successfully.
2025-06-24 11:40:09,154 | INFO     | ImageApp1.views | get                  | Line 183  | 104 documents retrieved. Total input: 82843, output: 32388
2025-06-24 11:40:16,742 | INFO     | ImageApp1.views | get                  | Line 126  | GetDocumentByIdView called with encrypted ID: gAAAAABoWo6ZNa5c4oJqCQr3f1NfJlmUUFgCvqqQZO-nOeHKzsCiVmm08_Y3KWnQ46wpqO2tTTo9kSuOUAiXSHYEMO-VvT3oGQ==
2025-06-24 11:40:16,744 | DEBUG    | ImageApp1.views | get                  | Line 130  | Decrypted ID: 56
2025-06-24 11:40:16,765 | INFO     | ImageApp1.views | get                  | Line 134  | Document 56 retrieved successfully
2025-06-24 11:40:17,050 | WARNING  |  django.request | log_response         | Line 241  | Not Found: /media/uploads/pdf_files/GST-Invoice-Template-In-Hindi_rlFsS2U.jpg
2025-06-24 11:40:23,407 | INFO     | ImageApp1.views | get                  | Line 162  | UserDocumentView accessed by user ID: 7
2025-06-24 11:40:23,408 | INFO     | ImageApp1.views | get                  | Line 169  | Fetching documents for user ID: 7
2025-06-24 11:40:23,445 | INFO     | ImageApp1.views | get                  | Line 173  | 104 documents retrieved successfully.
2025-06-24 11:40:23,463 | INFO     | ImageApp1.views | get                  | Line 183  | 104 documents retrieved. Total input: 82843, output: 32388
2025-06-24 11:40:29,683 | INFO     | ImageApp1.views | get                  | Line 126  | GetDocumentByIdView called with encrypted ID: gAAAAABoWo6nIlaR7g0JFJrS8JnQaiM5cIgwFR1QgYHWJSg1uGjrTwVVrE-F41QBCZoa3xWtEAKnDfp8EiIv8YFGHUtZS9GIRg==
2025-06-24 11:40:29,684 | DEBUG    | ImageApp1.views | get                  | Line 130  | Decrypted ID: 182
2025-06-24 11:40:29,700 | INFO     | ImageApp1.views | get                  | Line 134  | Document 182 retrieved successfully
2025-06-24 11:42:36,818 | INFO     | ImageApp1.views | get                  | Line 126  | GetDocumentByIdView called with encrypted ID: gAAAAABoWo6nIlaR7g0JFJrS8JnQaiM5cIgwFR1QgYHWJSg1uGjrTwVVrE-F41QBCZoa3xWtEAKnDfp8EiIv8YFGHUtZS9GIRg==
2025-06-24 11:42:36,820 | DEBUG    | ImageApp1.views | get                  | Line 130  | Decrypted ID: 182
2025-06-24 11:42:36,834 | INFO     | ImageApp1.views | get                  | Line 134  | Document 182 retrieved successfully
2025-06-24 11:43:05,786 | INFO     | ImageApp1.views | get                  | Line 162  | UserDocumentView accessed by user ID: 7
2025-06-24 11:43:05,787 | INFO     | ImageApp1.views | get                  | Line 169  | Fetching documents for user ID: 7
2025-06-24 11:43:05,816 | INFO     | ImageApp1.views | get                  | Line 173  | 104 documents retrieved successfully.
2025-06-24 11:43:05,824 | INFO     | ImageApp1.views | get                  | Line 183  | 104 documents retrieved. Total input: 82843, output: 32388
2025-06-24 11:46:53,465 | INFO     | django.utils.autoreload | trigger_reload       | Line 265  | D:\IDP_AI_App\Backend\Django Projects (2)\Django Projects\ImageExtraction\ImageApp1\views.py changed, reloading.
2025-06-24 11:46:59,878 | INFO     | django.utils.autoreload | run_with_reloader    | Line 667  | Watching for file changes with StatReloader
2025-06-24 11:48:00,444 | INFO     | django.utils.autoreload | trigger_reload       | Line 265  | D:\IDP_AI_App\Backend\Django Projects (2)\Django Projects\ImageExtraction\ImageApp1\views.py changed, reloading.
2025-06-24 11:48:02,228 | INFO     | django.utils.autoreload | run_with_reloader    | Line 667  | Watching for file changes with StatReloader
2025-06-24 11:49:31,470 | INFO     | django.utils.autoreload | run_with_reloader    | Line 667  | Watching for file changes with StatReloader
2025-06-24 11:49:39,682 | DEBUG    | google.cloud.storage._opentelemetry_tracing | <module>             | Line 42   | This service is instrumented using OpenTelemetry. OpenTelemetry or one of its components could not be imported; please add compatible versions of opentelemetry-api and opentelemetry-instrumentation packages in order to get Storage Tracing data.
2025-06-24 11:51:08,049 | INFO     | django.utils.autoreload | run_with_reloader    | Line 667  | Watching for file changes with StatReloader
2025-06-24 11:51:13,135 | DEBUG    | google.cloud.storage._opentelemetry_tracing | <module>             | Line 42   | This service is instrumented using OpenTelemetry. OpenTelemetry or one of its components could not be imported; please add compatible versions of opentelemetry-api and opentelemetry-instrumentation packages in order to get Storage Tracing data.
2025-06-24 11:52:29,515 | INFO     | django.utils.autoreload | run_with_reloader    | Line 667  | Watching for file changes with StatReloader
2025-06-24 11:52:34,712 | DEBUG    | google.cloud.storage._opentelemetry_tracing | <module>             | Line 42   | This service is instrumented using OpenTelemetry. OpenTelemetry or one of its components could not be imported; please add compatible versions of opentelemetry-api and opentelemetry-instrumentation packages in order to get Storage Tracing data.
2025-06-24 11:55:37,437 | INFO     | django.utils.autoreload | trigger_reload       | Line 265  | D:\IDP_AI_App\Backend\Django Projects (2)\Django Projects\ImageExtraction\ImageApp1\views.py changed, reloading.
2025-06-24 11:55:40,110 | INFO     | django.utils.autoreload | run_with_reloader    | Line 667  | Watching for file changes with StatReloader
2025-06-24 11:55:45,395 | DEBUG    | google.cloud.storage._opentelemetry_tracing | <module>             | Line 42   | This service is instrumented using OpenTelemetry. OpenTelemetry or one of its components could not be imported; please add compatible versions of opentelemetry-api and opentelemetry-instrumentation packages in order to get Storage Tracing data.
2025-06-24 11:56:11,053 | INFO     | authentication.views | post                 | Line 99   | Login attempt received.
2025-06-24 11:56:11,630 | INFO     | authentication.views | post                 | Line 116  | Login successful for user: abc
2025-06-24 11:56:18,783 | INFO     | authentication.views | post                 | Line 99   | Login attempt received.
2025-06-24 11:56:19,367 | INFO     | authentication.views | post                 | Line 116  | Login successful for user: NikhilVDX
2025-06-24 11:56:31,262 | INFO     | ImageApp1.views | post                 | Line 346  | Upload request received
2025-06-24 11:56:31,505 | ERROR    | ImageApp1.views | post                 | Line 561  | 500
2025-06-24 11:56:31,506 | ERROR    | ImageApp1.views | post                 | Line 562  | Error while processing document.
2025-06-24 11:56:31,539 | ERROR    | ImageApp1.views | log_exception        | Line 71   | Exception occurred in D:\IDP_AI_App\Backend\Django Projects (2)\Django Projects\ImageExtraction\ImageApp1\views.py, line 444: response = model.generate_content([data_part, prompt_text])
2025-06-24 11:56:31,540 | ERROR    | ImageApp1.views | log_exception        | Line 71   | Exception occurred in C:\Sujata\Python39\lib\site-packages\google\generativeai\generative_models.py, line 331: response = self._client.generate_content(
2025-06-24 11:56:31,542 | ERROR    | ImageApp1.views | log_exception        | Line 71   | Exception occurred in C:\Sujata\Python39\lib\site-packages\google\ai\generativelanguage_v1beta\services\generative_service\client.py, line 835: response = rpc(
2025-06-24 11:56:31,543 | ERROR    | ImageApp1.views | log_exception        | Line 71   | Exception occurred in C:\Sujata\Python39\lib\site-packages\google\api_core\gapic_v1\method.py, line 131: return wrapped_func(*args, **kwargs)
2025-06-24 11:56:31,543 | ERROR    | ImageApp1.views | log_exception        | Line 71   | Exception occurred in C:\Sujata\Python39\lib\site-packages\google\api_core\retry\retry_unary.py, line 294: return retry_target(
2025-06-24 11:56:31,544 | ERROR    | ImageApp1.views | log_exception        | Line 71   | Exception occurred in C:\Sujata\Python39\lib\site-packages\google\api_core\retry\retry_unary.py, line 156: next_sleep = _retry_error_helper(
2025-06-24 11:56:31,544 | ERROR    | ImageApp1.views | log_exception        | Line 71   | Exception occurred in C:\Sujata\Python39\lib\site-packages\google\api_core\retry\retry_base.py, line 214: raise final_exc from source_exc
2025-06-24 11:56:31,545 | ERROR    | ImageApp1.views | log_exception        | Line 71   | Exception occurred in C:\Sujata\Python39\lib\site-packages\google\api_core\retry\retry_unary.py, line 147: result = target()
2025-06-24 11:56:31,545 | ERROR    | ImageApp1.views | log_exception        | Line 71   | Exception occurred in C:\Sujata\Python39\lib\site-packages\google\api_core\timeout.py, line 130: return func(*args, **kwargs)
2025-06-24 11:56:31,546 | ERROR    | ImageApp1.views | log_exception        | Line 71   | Exception occurred in C:\Sujata\Python39\lib\site-packages\google\api_core\grpc_helpers.py, line 78: raise exceptions.from_grpc_error(exc) from exc
2025-06-24 11:56:31,547 | ERROR    |  django.request | log_response         | Line 241  | Internal Server Error: /IDA/upload/
2025-06-24 12:02:45,629 | INFO     | django.utils.autoreload | trigger_reload       | Line 265  | D:\IDP_AI_App\Backend\Django Projects (2)\Django Projects\ImageExtraction\ImageApp1\views.py changed, reloading.
2025-06-24 12:05:57,629 | INFO     | django.utils.autoreload | run_with_reloader    | Line 667  | Watching for file changes with StatReloader
2025-06-24 12:06:02,905 | DEBUG    | google.cloud.storage._opentelemetry_tracing | <module>             | Line 42   | This service is instrumented using OpenTelemetry. OpenTelemetry or one of its components could not be imported; please add compatible versions of opentelemetry-api and opentelemetry-instrumentation packages in order to get Storage Tracing data.
2025-06-24 12:06:19,689 | INFO     | authentication.views | post                 | Line 99   | Login attempt received.
2025-06-24 12:06:20,270 | INFO     | authentication.views | post                 | Line 116  | Login successful for user: NikhilVDX
2025-06-24 12:06:30,945 | INFO     | ImageApp1.views | post                 | Line 346  | Upload request received
2025-06-24 12:06:31,268 | ERROR    | ImageApp1.views | post                 | Line 561  | 500
2025-06-24 12:06:31,270 | ERROR    | ImageApp1.views | post                 | Line 562  | Error while processing document.
2025-06-24 12:06:31,281 | ERROR    | ImageApp1.views | log_exception        | Line 71   | Exception occurred in D:\IDP_AI_App\Backend\Django Projects (2)\Django Projects\ImageExtraction\ImageApp1\views.py, line 444: response = model.generate_content([data_part, prompt_text])
2025-06-24 12:06:31,285 | ERROR    | ImageApp1.views | log_exception        | Line 71   | Exception occurred in C:\Sujata\Python39\lib\site-packages\google\generativeai\generative_models.py, line 331: response = self._client.generate_content(
2025-06-24 12:06:31,285 | ERROR    | ImageApp1.views | log_exception        | Line 71   | Exception occurred in C:\Sujata\Python39\lib\site-packages\google\ai\generativelanguage_v1beta\services\generative_service\client.py, line 835: response = rpc(
2025-06-24 12:06:31,286 | ERROR    | ImageApp1.views | log_exception        | Line 71   | Exception occurred in C:\Sujata\Python39\lib\site-packages\google\api_core\gapic_v1\method.py, line 131: return wrapped_func(*args, **kwargs)
2025-06-24 12:06:31,287 | ERROR    | ImageApp1.views | log_exception        | Line 71   | Exception occurred in C:\Sujata\Python39\lib\site-packages\google\api_core\retry\retry_unary.py, line 294: return retry_target(
2025-06-24 12:06:31,287 | ERROR    | ImageApp1.views | log_exception        | Line 71   | Exception occurred in C:\Sujata\Python39\lib\site-packages\google\api_core\retry\retry_unary.py, line 156: next_sleep = _retry_error_helper(
2025-06-24 12:06:31,288 | ERROR    | ImageApp1.views | log_exception        | Line 71   | Exception occurred in C:\Sujata\Python39\lib\site-packages\google\api_core\retry\retry_base.py, line 214: raise final_exc from source_exc
2025-06-24 12:06:31,288 | ERROR    | ImageApp1.views | log_exception        | Line 71   | Exception occurred in C:\Sujata\Python39\lib\site-packages\google\api_core\retry\retry_unary.py, line 147: result = target()
2025-06-24 12:06:31,292 | ERROR    | ImageApp1.views | log_exception        | Line 71   | Exception occurred in C:\Sujata\Python39\lib\site-packages\google\api_core\timeout.py, line 130: return func(*args, **kwargs)
2025-06-24 12:06:31,292 | ERROR    | ImageApp1.views | log_exception        | Line 71   | Exception occurred in C:\Sujata\Python39\lib\site-packages\google\api_core\grpc_helpers.py, line 78: raise exceptions.from_grpc_error(exc) from exc
2025-06-24 12:06:31,293 | ERROR    |  django.request | log_response         | Line 241  | Internal Server Error: /IDA/upload/
2025-06-24 12:40:33,853 | INFO     | authentication.views | post                 | Line 99   | Login attempt received.
2025-06-24 12:40:45,585 | INFO     | authentication.views | post                 | Line 116  | Login successful for user: NikhilVDX
2025-06-24 12:41:10,701 | INFO     | django.utils.autoreload | run_with_reloader    | Line 667  | Watching for file changes with StatReloader
2025-06-24 12:41:15,793 | DEBUG    | google.cloud.storage._opentelemetry_tracing | <module>             | Line 42   | This service is instrumented using OpenTelemetry. OpenTelemetry or one of its components could not be imported; please add compatible versions of opentelemetry-api and opentelemetry-instrumentation packages in order to get Storage Tracing data.
2025-06-24 12:41:27,378 | INFO     | authentication.views | post                 | Line 99   | Login attempt received.
2025-06-24 12:41:27,935 | INFO     | authentication.views | post                 | Line 116  | Login successful for user: NikhilVDX
2025-06-24 12:41:43,022 | INFO     | ImageApp1.views | post                 | Line 346  | Upload request received
2025-06-24 12:41:43,480 | ERROR    | ImageApp1.views | post                 | Line 561  | 500
2025-06-24 12:41:43,481 | ERROR    | ImageApp1.views | post                 | Line 562  | Error while processing document.
2025-06-24 12:41:43,497 | ERROR    | ImageApp1.views | log_exception        | Line 71   | Exception occurred in D:\IDP_AI_App\Backend\Django Projects (2)\Django Projects\ImageExtraction\ImageApp1\views.py, line 444: response = model.generate_content([data_part, prompt_text])
2025-06-24 12:41:43,497 | ERROR    | ImageApp1.views | log_exception        | Line 71   | Exception occurred in C:\Sujata\Python39\lib\site-packages\google\generativeai\generative_models.py, line 331: response = self._client.generate_content(
2025-06-24 12:41:43,498 | ERROR    | ImageApp1.views | log_exception        | Line 71   | Exception occurred in C:\Sujata\Python39\lib\site-packages\google\ai\generativelanguage_v1beta\services\generative_service\client.py, line 835: response = rpc(
2025-06-24 12:41:43,499 | ERROR    | ImageApp1.views | log_exception        | Line 71   | Exception occurred in C:\Sujata\Python39\lib\site-packages\google\api_core\gapic_v1\method.py, line 131: return wrapped_func(*args, **kwargs)
2025-06-24 12:41:43,499 | ERROR    | ImageApp1.views | log_exception        | Line 71   | Exception occurred in C:\Sujata\Python39\lib\site-packages\google\api_core\retry\retry_unary.py, line 294: return retry_target(
2025-06-24 12:41:43,500 | ERROR    | ImageApp1.views | log_exception        | Line 71   | Exception occurred in C:\Sujata\Python39\lib\site-packages\google\api_core\retry\retry_unary.py, line 156: next_sleep = _retry_error_helper(
2025-06-24 12:41:43,501 | ERROR    | ImageApp1.views | log_exception        | Line 71   | Exception occurred in C:\Sujata\Python39\lib\site-packages\google\api_core\retry\retry_base.py, line 214: raise final_exc from source_exc
2025-06-24 12:41:43,507 | ERROR    | ImageApp1.views | log_exception        | Line 71   | Exception occurred in C:\Sujata\Python39\lib\site-packages\google\api_core\retry\retry_unary.py, line 147: result = target()
2025-06-24 12:41:43,507 | ERROR    | ImageApp1.views | log_exception        | Line 71   | Exception occurred in C:\Sujata\Python39\lib\site-packages\google\api_core\timeout.py, line 130: return func(*args, **kwargs)
2025-06-24 12:41:43,508 | ERROR    | ImageApp1.views | log_exception        | Line 71   | Exception occurred in C:\Sujata\Python39\lib\site-packages\google\api_core\grpc_helpers.py, line 78: raise exceptions.from_grpc_error(exc) from exc
2025-06-24 12:41:43,509 | ERROR    |  django.request | log_response         | Line 241  | Internal Server Error: /IDA/upload/
2025-06-24 12:54:11,132 | INFO     | authentication.views | post                 | Line 99   | Login attempt received.
2025-06-24 12:54:20,943 | INFO     | authentication.views | post                 | Line 116  | Login successful for user: NikhilVDX
2025-06-24 12:54:41,018 | INFO     | ImageApp1.views | post                 | Line 346  | Upload request received
2025-06-24 12:54:41,816 | ERROR    | ImageApp1.views | post                 | Line 561  | 500
2025-06-24 12:54:41,816 | ERROR    | ImageApp1.views | post                 | Line 562  | Error while processing document.
2025-06-24 12:54:41,820 | ERROR    | ImageApp1.views | log_exception        | Line 71   | Exception occurred in D:\IDP_AI_App\Backend\Django Projects (2)\Django Projects\ImageExtraction\ImageApp1\views.py, line 444: else:
2025-06-24 12:54:41,820 | ERROR    | ImageApp1.views | log_exception        | Line 71   | Exception occurred in C:\Sujata\Python39\lib\site-packages\google\generativeai\generative_models.py, line 331: response = self._client.generate_content(
2025-06-24 12:54:41,820 | ERROR    | ImageApp1.views | log_exception        | Line 71   | Exception occurred in C:\Sujata\Python39\lib\site-packages\google\ai\generativelanguage_v1beta\services\generative_service\client.py, line 835: response = rpc(
2025-06-24 12:54:41,820 | ERROR    | ImageApp1.views | log_exception        | Line 71   | Exception occurred in C:\Sujata\Python39\lib\site-packages\google\api_core\gapic_v1\method.py, line 131: return wrapped_func(*args, **kwargs)
2025-06-24 12:54:41,820 | ERROR    | ImageApp1.views | log_exception        | Line 71   | Exception occurred in C:\Sujata\Python39\lib\site-packages\google\api_core\retry\retry_unary.py, line 294: return retry_target(
2025-06-24 12:54:41,820 | ERROR    | ImageApp1.views | log_exception        | Line 71   | Exception occurred in C:\Sujata\Python39\lib\site-packages\google\api_core\retry\retry_unary.py, line 156: next_sleep = _retry_error_helper(
2025-06-24 12:54:41,820 | ERROR    | ImageApp1.views | log_exception        | Line 71   | Exception occurred in C:\Sujata\Python39\lib\site-packages\google\api_core\retry\retry_base.py, line 214: raise final_exc from source_exc
2025-06-24 12:54:41,820 | ERROR    | ImageApp1.views | log_exception        | Line 71   | Exception occurred in C:\Sujata\Python39\lib\site-packages\google\api_core\retry\retry_unary.py, line 147: result = target()
2025-06-24 12:54:41,820 | ERROR    | ImageApp1.views | log_exception        | Line 71   | Exception occurred in C:\Sujata\Python39\lib\site-packages\google\api_core\timeout.py, line 130: return func(*args, **kwargs)
2025-06-24 12:54:41,824 | ERROR    | ImageApp1.views | log_exception        | Line 71   | Exception occurred in C:\Sujata\Python39\lib\site-packages\google\api_core\grpc_helpers.py, line 78: raise exceptions.from_grpc_error(exc) from exc
2025-06-24 12:54:41,825 | ERROR    |  django.request | log_response         | Line 241  | Internal Server Error: /IDA/upload/
2025-06-24 12:54:50,120 | INFO     | ImageApp1.views | post                 | Line 346  | Upload request received
2025-06-24 12:54:50,264 | ERROR    | ImageApp1.views | post                 | Line 561  | 500
2025-06-24 12:54:50,265 | ERROR    | ImageApp1.views | post                 | Line 562  | Error while processing document.
2025-06-24 12:54:50,268 | ERROR    | ImageApp1.views | log_exception        | Line 71   | Exception occurred in D:\IDP_AI_App\Backend\Django Projects (2)\Django Projects\ImageExtraction\ImageApp1\views.py, line 444: else:
2025-06-24 12:54:50,269 | ERROR    | ImageApp1.views | log_exception        | Line 71   | Exception occurred in C:\Sujata\Python39\lib\site-packages\google\generativeai\generative_models.py, line 331: response = self._client.generate_content(
2025-06-24 12:54:50,269 | ERROR    | ImageApp1.views | log_exception        | Line 71   | Exception occurred in C:\Sujata\Python39\lib\site-packages\google\ai\generativelanguage_v1beta\services\generative_service\client.py, line 835: response = rpc(
2025-06-24 12:54:50,270 | ERROR    | ImageApp1.views | log_exception        | Line 71   | Exception occurred in C:\Sujata\Python39\lib\site-packages\google\api_core\gapic_v1\method.py, line 131: return wrapped_func(*args, **kwargs)
2025-06-24 12:54:50,271 | ERROR    | ImageApp1.views | log_exception        | Line 71   | Exception occurred in C:\Sujata\Python39\lib\site-packages\google\api_core\retry\retry_unary.py, line 294: return retry_target(
2025-06-24 12:54:50,271 | ERROR    | ImageApp1.views | log_exception        | Line 71   | Exception occurred in C:\Sujata\Python39\lib\site-packages\google\api_core\retry\retry_unary.py, line 156: next_sleep = _retry_error_helper(
2025-06-24 12:54:50,272 | ERROR    | ImageApp1.views | log_exception        | Line 71   | Exception occurred in C:\Sujata\Python39\lib\site-packages\google\api_core\retry\retry_base.py, line 214: raise final_exc from source_exc
2025-06-24 12:54:50,275 | ERROR    | ImageApp1.views | log_exception        | Line 71   | Exception occurred in C:\Sujata\Python39\lib\site-packages\google\api_core\retry\retry_unary.py, line 147: result = target()
2025-06-24 12:54:50,278 | ERROR    | ImageApp1.views | log_exception        | Line 71   | Exception occurred in C:\Sujata\Python39\lib\site-packages\google\api_core\timeout.py, line 130: return func(*args, **kwargs)
2025-06-24 12:54:50,278 | ERROR    | ImageApp1.views | log_exception        | Line 71   | Exception occurred in C:\Sujata\Python39\lib\site-packages\google\api_core\grpc_helpers.py, line 78: raise exceptions.from_grpc_error(exc) from exc
2025-06-24 12:54:50,280 | ERROR    |  django.request | log_response         | Line 241  | Internal Server Error: /IDA/upload/
2025-06-24 12:55:23,381 | INFO     | django.utils.autoreload | trigger_reload       | Line 265  | D:\IDP_AI_App\Backend\Django Projects (2)\Django Projects\ImageExtraction\ImageApp1\views.py changed, reloading.
2025-06-24 12:55:27,678 | INFO     | django.utils.autoreload | run_with_reloader    | Line 667  | Watching for file changes with StatReloader
2025-06-24 12:55:33,082 | DEBUG    | google.cloud.storage._opentelemetry_tracing | <module>             | Line 42   | This service is instrumented using OpenTelemetry. OpenTelemetry or one of its components could not be imported; please add compatible versions of opentelemetry-api and opentelemetry-instrumentation packages in order to get Storage Tracing data.
